Workbook

Sheet DETALLE_TRAZABILIDAD
A1: ESTADO_CARGA_PES | B1: NUM_DOCUMENTO | C1: DV | D1: NOMBRE_COMPLETO | E1: MOTIVO_NO_CARGA_LEGIBLE | F1: COLUMNAS_OBSERVADAS | G1: VALORES_OBSERVADOS | H1: ACCION_REQUERIDA_LEGIBLE | I1: SIES_TIPO_DOCUMENTO | J1: ORIGINAL_TIPO_DOCUMENTO | K1: SIES_NUM_DOCUMENTO | L1: ORIGINAL_NUM_DOCUMENTO | M1: SIES_DV | N1: ORIGINAL_DV | O1: SIES_PRIMER_APELLIDO | P1: ORIGINAL_PRIMER_APELLIDO | Q1: SIES_SEGUNDO_APELLIDO | R1: ORIGINAL_SEGUNDO_APELLIDO | S1: SIES_NOMBRES | T1: ORIGINAL_NOMBRES | U1: SIES_SEXO | V1: ORIGINAL_SEXO | W1: SIES_FECHA_NACIMIENTO | X1: ORIGINAL_FECHA_NACIMIENTO | Y1: SIES_NACIONALIDAD | Z1: ORIGINAL_NACIONALIDAD | AA1: SIES_NIVEL_FORMACION_ACADEMICO | AB1: ORIGINAL_NIVEL_FORMACION_ACADEMICO | AC1: SIES_NOMBRE_TITULO_O_GRADO | AD1: ORIGINAL_NOMBRE_TITULO_O_GRADO | AE1: SIES_NOMBRE_INSTITUCION_OBT_TITULO | AF1: ORIGINAL_NOMBRE_INSTITUCION_OBT_TITULO | AG1: SIES_PAIS_OBTENCION_TIT_O_GRADO | AH1: ORIGINAL_PAIS_OBTENCION_TIT_O_GRADO | AI1: SIES_FECHA_OBT_TIT_O_GRADO | AJ1: ORIGINAL_FECHA_OBT_TIT_O_GRADO | AK1: SIES_NIVEL_FORMACION_ESPECIALIDAD | AL1: ORIGINAL_NIVEL_FORMACION_ESPECIALIDAD | AM1: SIES_TIPO_ESPECIALIDAD | AN1: ORIGINAL_TIPO_ESPECIALIDAD | AO1: SIES_NOMBRE_ESPECIALIDAD | AP1: ORIGINAL_NOMBRE_ESPECIALIDAD | AQ1: SIES_NOMBRE_INST_OBT_ESPECIALIDAD | AR1: ORIGINAL_NOMBRE_INST_OBT_ESPECIALIDAD | AS1: SIES_PAIS_OBTENCION_ESPECIALIDAD | AT1: ORIGINAL_PAIS_OBTENCION_ESPECIALIDAD | AU1: SIES_FECHA_OBTENCION_ESPECIALIDAD | AV1: ORIGINAL_FECHA_OBTENCION_ESPECIALIDAD | AW1: SIES_PRINCIPAL_CARGO_ACADEMICO | AX1: ORIGINAL_PRINCIPAL_CARGO_ACADEMICO | AY1: SIES_CARGO_NORMALIZADO | AZ1: ORIGINAL_CARGO_NORMALIZADO | BA1: SIES_NIVEL_SUPERIOR_ADSCRIPCION | BB1: ORIGINAL_NIVEL_SUPERIOR_ADSCRIPCION | BC1: SIES_NIVEL_SECUNDARIO_ADSCRIPCION | BD1: ORIGINAL_NIVEL_SECUNDARIO_ADSCRIPCION | BE1: SIES_COMUNA_MAYOR_FUNCION | BF1: ORIGINAL_COMUNA_MAYOR_FUNCION | BG1: SIES_NOMBRE_PRINCIPAL_PROGRAMA | BH1: ORIGINAL_NOMBRE_PRINCIPAL_PROGRAMA | BI1: SIES_TOTAL_HORAS_PRINCIPAL_PROGRAMA | BJ1: ORIGINAL_TOTAL_HORAS_PRINCIPAL_PROGRAMA | BK1: SIES_COMUNA_PRINCIPAL_PROGRAMA | BL1: ORIGINAL_COMUNA_PRINCIPAL_PROGRAMA | BM1: SIES_NUM_HORAS_PLANTA | BN1: ORIGINAL_NUM_HORAS_PLANTA | BO1: SIES_NUM_HORAS_CONTRATA | BP1: ORIGINAL_NUM_HORAS_CONTRATA | BQ1: SIES_NUM_HORAS_HONORARIOS | BR1: ORIGINAL_NUM_HORAS_HONORARIOS | BS1: SIES_JERARQUIA_ACADEMICA | BT1: ORIGINAL_JERARQUIA_ACADEMICA | BU1: SIES_JERARQUIA_ACADEMICA_OCDE | BV1: ORIGINAL_JERARQUIA_ACADEMICA_OCDE | BW1: SIES_VIGENCIA | BX1: ORIGINAL_VIGENCIA
A2: CARGADO_PES | B2: 10063280 | C2: 2 | D2: ESPINOZA CHAPARRO FLORENCIO | H2: Sin accion requerida. | I2: R | J2: R | K2: 10063280 | L2: 10063280 | M2: 2 | N2: 2 | O2: ESPINOZA | P2: ESPINOZA | Q2: CHAPARRO | R2: CHAPARRO | S2: FLORENCIO | T2: FLORENCIO | U2: H | V2: H | W2: 12-10-1964 | X2: 1964-10-12 | Y2: 38 | Z2: 38 | AA2: 5 | AB2: 5 | AC2: PROGRAMADOR DE APLICACIONES | AD2: PROGRAMADOR DE APLICACIONES | AE2: CFT ITESA | AF2: CFT ITESA | AG2: 38 | AH2: 38 | AI2: 20-10-1990 | AJ2: 1990-10-20 | AP2: NO APLICA | AR2: NO APLICA | AV2: NO APLICA | AW2: DOCENTE | AX2: DOCENTE | AY2: 9 | AZ2: 9 | BA2: VICERRECTORIA ACADEMICA | BB2: VICERRECTORIA ACADEMICA | BC2: DIRECCION DE CARRERA | BD2: DIRECCION DE CARRERA | BE2: SANTIAGO | BG2: INGENIERIA EN CIBERSEGURIDAD | BH2: INGENIERIA EN CIBERSEGURIDAD | BI2: 12 | BJ2: 12 | BK2: SANTIAGO | BL2: SANTIAGO | BM2: 0 | BO2: 0 | BQ2: 18 | BR2: 18 | BS2: NO APLICA | BT2: NO APLICA | BU2: 5 | BV2: 5 | BW2: 1 | BX2: 1
A3: CARGADO_PES | B3: 10393519 | C3: 9 | D3: LOPEZ PARRA JOSÉ JOEL | H3: Sin accion requerida. | I3: R | J3: R | K3: 10393519 | L3: 10393519 | M3: 9 | N3: 9 | O3: LOPEZ | P3: LOPEZ | Q3: PARRA | R3: PARRA | S3: JOSE JOEL | T3: JOSÉ JOEL | U3: H | V3: H | W3: 18-12-1966 | X3: 1966-12-18 | Y3: 38 | Z3: 38 | AA3: 3 | AB3: 3 | AC3: INGENIERO DE EJECUCION EN ADMINISTRACION Y FINANZAS | AD3: INGENIERO DE EJECUCIÓN EN ADMINISTRACIÓN Y FINANZAS | AE3: UNIVERSIDAD RAUL SILVA HENRIQUEZ | AF3: UNIVERSIDAD RAUL SILVA HENRIQUEZ | AG3: 38 | AH3: 38 | AI3: 19-07-2012 | AJ3: 2012-07-19 | AP3: NO APLICA | AR3: NO APLICA | AV3: NO APLICA | AW3: DOCENTE | AX3: DOCENTE | AY3: 9 | AZ3: 9 | BA3: VICERRECTORIA ACADEMICA | BB3: VICERRECTORIA ACADEMICA | BC3: DIRECCION DE CARRERA | BD3: DIRECCION DE CARRERA | BE3: SANTIAGO | BG3: INGENIERIA EN ADMINISTRACION DE EMPRESAS | BH3: INGENIERIA EN ADMINISTRACION DE EMPRESAS | BI3: 15 | BJ3: 15 | BK3: SANTIAGO | BL3: SANTIAGO | BM3: 0 | BO3: 0 | BQ3: 25 | BR3: 25 | BS3: NO APLICA | BT3: NO APLICA | BU3: 5 | BV3: 5 | BW3: 1 | BX3: 1
A4: CARGADO_PES | B4: 10536500 | C4: 4 | D4: GARCIA ROMERO MARIO | H4: Sin accion requerida. | I4: R | J4: R | K4: 10536500 | L4: 10536500 | M4: 4 | N4: 4 | O4: GARCIA | P4: GARCIA | Q4: ROMERO | R4: ROMERO | S4: MARIO | T4: MARIO | U4: H | V4: H | W4: 14-04-1967 | X4: 1967-04-14 | Y4: 38 | Z4: 38 | AA4: 2 | AB4: 2 | AC4: MMAGISTER EN DOCENCIA PARA LA EDUCACION SUPERIOR | AD4: MMAGISTER EN DOCENCIA PARA LA EDUCACIÓN SUPERIOR | AE4: UNIVERSIDAD ANDRES BELLO | AF4: UNIVERSIDAD ANDRES BELLO | AG4: 38 | AH4: 38 | AI4: 08-11-2011 | AJ4: 2011-11-08 | AP4: NO APLICA | AR4: NO APLICA | AV4: NO APLICA | AW4: DOCENTE | AX4: DOCENTE | AY4: 9 | AZ4: 9 | BA4: VICERRECTORIA ACADEMICA | BB4: VICERRECTORIA ACADEMICA | BC4: DIRECCION DE CARRERA | BD4: DIRECCION DE CARRERA | BE4: SANTIAGO | BG4: FORMACION GENERAL | BH4: FORMACIÓN GENERAL | BI4: 5 | BJ4: 5 | BK4: SANTIAGO | BL4: SANTIAGO | BM4: 0 | BO4: 0 | BQ4: 24.5 | BR4: 24.5 | BS4: NO APLICA | BT4: NO APLICA | BU4: 5 | BV4: 5 | BW4: 1 | BX4: 1
A5: CARGADO_PES | B5: 10727793 | C5: 5 | D5: BRAVO FIGUEROA PATRICIO ANDRÉS | H5: Sin accion requerida. | I5: R | J5: R | K5: 10727793 | L5: 10727793 | M5: 5 | N5: 5 | O5: BRAVO | P5: BRAVO | Q5: FIGUEROA | R5: FIGUEROA | S5: PATRICIO ANDRES | T5: PATRICIO ANDRÉS | U5: H | V5: H | W5: 02-06-1969 | X5: 1969-06-02 | Y5: 38 | Z5: 38 | AA5: 2 | AB5: 2 | AC5: MAGISTER EN GESTION PEDAGOGICA CURRICULAR Y PROYECTOS EDUCATIVOS | AD5: MAGÍSTER EN GESTIÓN PEDAGÓGICA - CURRICULAR Y PROYECTOS EDUCATIVOS | AE5: UNIVERSIDAD ANDRES BELLO | AF5: UNIVERSIDAD ANDRES BELLO | AG5: 38 | AH5: 38 | AI5: 06-10-2023 | AJ5: 2023-10-06 | AP5: NO APLICA | AR5: NO APLICA | AV5: NO APLICA | AW5: DOCENTE | AX5: DOCENTE | AY5: 9 | AZ5: 9 | BA5: VICERRECTORIA ACADEMICA | BB5: VICERRECTORIA ACADEMICA | BC5: DIRECCION DE CARRERA | BD5: DIRECCION DE CARRERA | BE5: SANTIAGO | BG5: FORMACION GENERAL | BH5: FORMACIÓN GENERAL | BI5: 15 | BJ5: 15 | BK5: SANTIAGO | BL5: SANTIAGO | BM5: 0 | BO5: 0 | BQ5: 24.5 | BR5: 24.5 | BS5: NO APLICA | BT5: NO APLICA | BU5: 5 | BV5: 5 | BW5: 1 | BX5: 1
A6: CARGADO_PES | B6: 11250569 | C6: 5 | D6: CASAS KRAM DINA MAGDALENA | H6: Sin accion requerida. | I6: R | J6: R | K6: 11250569 | L6: 11250569 | M6: 5 | N6: 5 | O6: CASAS | P6: CASAS | Q6: KRAM | R6: KRAM | S6: DINA MAGDALENA | T6: DINA MAGDALENA | U6: M | V6: M | W6: 06-07-1968 | X6: 1968-07-06 | Y6: 38 | Z6: 38 | AA6: 2 | AB6: 2 | AC6: MAGISTER EN DOCENCIA PARA LA EDUCACION SUPERIOR | AD6: MAGÍSTER EN DOCENCIA PARA LA EDUCACIÓN SUPERIOR | AE6: UNIVERSIDAD CENTRAL DE CHILE | AF6: UNIVERSIDAD CENTRAL DE CHILE | AG6: 38 | AH6: 38 | AI6: 13-07-2023 | AJ6: 2023-07-13 | AP6: NO APLICA | AR6: NO APLICA | AV6: NO APLICA | AW6: DOCENTE | AX6: DOCENTE | AY6: 9 | AZ6: 9 | BA6: VICERRECTORIA ACADEMICA | BB6: VICERRECTORIA ACADEMICA | BC6: DIRECCION DE CARRERA | BD6: DIRECCION DE CARRERA | BE6: SANTIAGO | BG6: TECNICO EN ENFERMERIA | BH6: TECNICO EN ENFERMERIA | BI6: 20 | BJ6: 20 | BK6: SANTIAGO | BL6: SANTIAGO | BM6: 0 | BO6: 0 | BQ6: 20 | BR6: 20 | BS6: NO APLICA | BT6: NO APLICA | BU6: 5 | BV6: 5 | BW6: 1 | BX6: 1
A7: CARGADO_PES | B7: 11481000 | C7: 2 | D7: AGUILAR SANTANA CARLOS ALFREDO | H7: Sin accion requerida. | I7: R | J7: R | K7: 11481000 | L7: 11481000 | M7: 2 | N7: 2 | O7: AGUILAR | P7: AGUILAR | Q7: SANTANA | R7: SANTANA | S7: CARLOS ALFREDO | T7: CARLOS ALFREDO | U7: H | V7: H | W7: 21-08-1968 | X7: 1968-08-21 | Y7: 38 | Z7: 38 | AA7: 3 | AB7: 3 | AC7: PROFESOR DE MATEMATICAS | AD7: PROFESOR DE MATEMÁTICAS | AE7: UNIVERSIDAD CATOLICA DE VALPARAISO | AF7: UNIVERSIDAD CATOLICA DE VALPARAISO | AG7: 38 | AH7: 38 | AI7: 08-08-1996 | AJ7: 1996-08-08 | AP7: NO APLICA | AR7: NO APLICA | AV7: NO APLICA | AW7: DOCENTE | AX7: DOCENTE | AY7: 9 | AZ7: 9 | BA7: VICERRECTORIA ACADEMICA | BB7: VICERRECTORIA ACADEMICA | BC7: DIRECCION DE CARRERA | BD7: DIRECCION DE CARRERA | BE7: SANTIAGO | BG7: FORMACION GENERAL | BH7: FORMACIÓN GENERAL | BI7: 10 | BJ7: 10 | BK7: SANTIAGO | BL7: SANTIAGO | BM7: 0 | BO7: 0 | BQ7: 10 | BR7: 10 | BS7: NO APLICA | BT7: NO APLICA | BU7: 5 | BV7: 5 | BW7: 1 | BX7: 1
A8: CARGADO_PES | B8: 11613889 | C8: 1 | D8: MENA ZUMARÁN NINROD | H8: Sin accion requerida. | I8: R | J8: R | K8: 11613889 | L8: 11613889 | M8: 1 | N8: 1 | O8: MENA | P8: MENA | Q8: ZUMARAN | R8: ZUMARÁN | S8: NINROD | T8: NINROD | U8: M | V8: M | W8: 24-02-1970 | X8: 1970-02-24 | Y8: 38 | Z8: 38 | AA8: 3 | AB8: 3 | AC8: INGENIERO EN EJECUCION ELECTRONICA | AD8: INGENIERO EN EJECUCIÓN ELECTRÓNICA | AE8: UNIVERSIDAD TECNOLOGICA DE CHILE INACAP | AF8: UNIVERSIDAD TECNOLOGICA DE CHILE INACAP | AG8: 38 | AH8: 38 | AI8: 18-02-2020 | AJ8: 2020-02-18 | AP8: NO APLICA | AR8: NO APLICA | AV8: NO APLICA | AW8: DOCENTE | AX8: DOCENTE | AY8: 9 | AZ8: 9 | BA8: VICERRECTORIA ACADEMICA | BB8: VICERRECTORIA ACADEMICA | BC8: DIRECCION DE CARRERA | BD8: DIRECCION DE CARRERA | BE8: SANTIAGO | BG8: INGENIERIA EN CIBERSEGURIDAD | BH8: INGENIERIA EN CIBERSEGURIDAD | BI8: 6 | BJ8: 6 | BK8: SANTIAGO | BL8: SANTIAGO | BM8: 0 | BO8: 0 | BQ8: 3 | BR8: 3 | BS8: NO APLICA | BT8: NO APLICA | BU8: 5 | BV8: 5 | BW8: 1 | BX8: 1
A9: CARGADO_PES | B9: 11640980 | C9: 1 | D9: LARA ORELLANA PATRICIO ANDRÉS | H9: Sin accion requerida. | I9: R | J9: R | K9: 11640980 | L9: 11640980 | M9: 1 | N9: 1 | O9: LARA | P9: LARA | Q9: ORELLANA | R9: ORELLANA | S9: PATRICIO ANDRES | T9: PATRICIO ANDRÉS | U9: H | V9: H | W9: 15-12-1970 | X9: 1970-12-15 | Y9: 38 | Z9: 38 | AA9: 3 | AB9: 3 | AC9: INGENIERO EN EJECUCION EN ADMINISTRACION PUBLICA | AD9: INGENIERO EN EJECUCIÓN EN ADMINISTRACIÓN PÚBLICA | AE9: UNIVERSIDAD ACADEMIA DE HUMANISMO CRISTIANO | AF9: UNIVERSIDAD ACADEMIA DE HUMANISMO CRISTIANO | AG9: 38 | AH9: 38 | AI9: 25-10-2005 | AJ9: 2005-10-25 | AP9: NO APLICA | AR9: NO APLICA | AV9: NO APLICA | AW9: DOCENTE | AX9: DOCENTE | AY9: 9 | AZ9: 9 | BA9: VICERRECTORIA ACADEMICA | BB9: VICERRECTORIA ACADEMICA | BC9: DIRECCION DE CARRERA | BD9: DIRECCION DE CARRERA | BE9: SANTIAGO | BG9: ADMINISTRACION PUBLICA | BH9: ADMINISTRACION PUBLICA | BI9: 15 | BJ9: 15 | BK9: SANTIAGO | BL9: SANTIAGO | BM9: 0 | BO9: 0 | BQ9: 15 | BR9: 15 | BS9: NO APLICA | BT9: NO APLICA | BU9: 5 | BV9: 5 | BW9: 1 | BX9: 1
A10: CARGADO_PES | B10: 11944423 | C10: 3 | D10: SUMA DE VILLA NELSON CARVALLO | H10: Sin accion requerida. | I10: R | J10: R | K10: 11944423 | L10: 11944423 | M10: 3 | N10: 3 | O10: SUMA | P10: SUMA | Q10: DE VILLA | R10: DE VILLA | S10: NELSON CARVALLO | T10: NELSON CARVALLO | U10: H | V10: H | W10: 06-05-1972 | X10: 1972-05-06 | Y10: 38 | Z10: 38 | AA10: 4 | AB10: 4 | AC10: LICENCIADO EN MATEMATICA Y COMPUTACION | AD10: LICENCIADO EN MATEMÁTICA Y COMPUTACIÓN | AE10: UNIVERSIDAD DE SANTIAGO DE CHILE | AF10: UNIVERSIDAD DE SANTIAGO DE CHILE | AG10: 38 | AH10: 38 | AI10: 19-05-1998 | AJ10: 1998-05-19 | AP10: NO APLICA | AR10: NO APLICA | AV10: NO APLICA | AW10: DOCENTE | AX10: DOCENTE | AY10: 9 | AZ10: 9 | BA10: VICERRECTORIA ACADEMICA | BB10: VICERRECTORIA ACADEMICA | BC10: DIRECCION DE CARRERA | BD10: DIRECCION DE CARRERA | BE10: SANTIAGO | BG10: INGENIERIA EN INFORMATICA | BH10: INGENIERIA EN INFORMATICA | BI10: 21 | BJ10: 21 | BK10: SANTIAGO | BL10: SANTIAGO | BM10: 0 | BO10: 0 | BQ10: 15 | BR10: 15 | BS10: NO APLICA | BT10: NO APLICA | BU10: 5 | BV10: 5 | BW10: 1 | BX10: 1
A11: CARGADO_PES | B11: 12141132 | C11: 6 | D11: SANDOVAL TRONCOSO SEBASTIÁN | H11: Sin accion requerida. | I11: R | J11: R | K11: 12141132 | L11: 12141132 | M11: 6 | N11: 6 | O11: SANDOVAL | P11: SANDOVAL | Q11: TRONCOSO | R11: TRONCOSO | S11: SEBASTIAN | T11: SEBASTIÁN | U11: H | V11: H | W11: 21-11-1970 | X11: 1970-11-21 | Y11: 38 | Z11: 38 | AA11: 3 | AB11: 3 | AC11: INGENIERO EN CONECTIVIDAD Y REDES | AD11: INGENIERO EN CONECTIVIDAD Y REDES | AE11: INSTITUTO PROFESIONAL SAN SEBASTIAN | AF11: INSTITUTO PROFESIONAL SAN SEBASTIÁN | AG11: 38 | AH11: 38 | AI11: 28-04-2025 | AJ11: 2025-04-28 | AP11: NO APLICA | AR11: NO APLICA | AV11: NO APLICA | AW11: DOCENTE | AX11: DOCENTE | AY11: 9 | AZ11: 9 | BA11: VICERRECTORIA ACADEMICA | BB11: VICERRECTORIA ACADEMICA | BC11: DIRECCION DE CARRERA | BD11: DIRECCION DE CARRERA | BE11: SANTIAGO | BG11: INGENIERIA EN INFORMATICA | BH11: INGENIERIA EN INFORMATICA | BI11: 3 | BJ11: 3 | BK11: SANTIAGO | BL11: SANTIAGO | BM11: 0 | BO11: 0 | BQ11: 3 | BR11: 3 | BS11: NO APLICA | BT11: NO APLICA | BU11: 5 | BV11: 5 | BW11: 1 | BX11: 1
A12: CARGADO_PES | B12: 12240733 | C12: 0 | D12: ÁLVAREZ MAULÉN MILTON | H12: Sin accion requerida. | I12: R | J12: R | K12: 12240733 | L12: 12240733 | M12: 0 | N12: 0 | O12: ALVAREZ | P12: ÁLVAREZ | Q12: MAULEN | R12: MAULÉN | S12: MILTON | T12: MILTON | U12: H | V12: H | W12: 31-07-1972 | X12: 1972-07-31 | Y12: 38 | Z12: 38 | AA12: 3 | AB12: 3 | AC12: PROFESOR DE ESTADO EN FISICA Y MATEMATICA | AD12: PROFESOR DE ESTADO EN FÍSICA Y MATEMÁTICA | AE12: UNIVERSIDAD DE SANTIAGO | AF12: UNIVERSIDAD DE SANTIAGO | AG12: 38 | AH12: 38 | AI12: 16-06-2009 | AJ12: 2009-06-16 | AP12: NO APLICA | AR12: NO APLICA | AV12: NO APLICA | AW12: DOCENTE | AX12: DOCENTE | AY12: 9 | AZ12: 9 | BA12: VICERRECTORIA ACADEMICA | BB12: VICERRECTORIA ACADEMICA | BC12: DIRECCION DE CARRERA | BD12: DIRECCION DE CARRERA | BE12: SANTIAGO | BG12: FORMACION GENERAL | BH12: FORMACIÓN GENERAL | BI12: 15 | BJ12: 15 | BK12: SANTIAGO | BL12: SANTIAGO | BM12: 0 | BO12: 0 | BQ12: 25 | BR12: 25 | BS12: NO APLICA | BT12: NO APLICA | BU12: 5 | BV12: 5 | BW12: 1 | BX12: 1
A13: CARGADO_PES | B13: 12534768 | C13: 1 | D13: MATUS PEZO RODRIGO | H13: Sin accion requerida. | I13: R | J13: R | K13: 12534768 | L13: 12534768 | M13: 1 | N13: 1 | O13: MATUS | P13: MATUS | Q13: PEZO | R13: PEZO | S13: RODRIGO | T13: RODRIGO | U13: H | V13: H | W13: 08-11-1973 | X13: 1973-11-08 | Y13: 38 | Z13: 38 | AA13: 3 | AB13: 3 | AC13: INGENIERO DE EJECUCION EN INFORMATICA | AD13: INGENIERO DE EJECUCIÓN EN INFORMÁTICA | AE13: UNIVERSIDAD DE LA FRONTERA | AF13: UNIVERSIDAD DE LA FRONTERA | AG13: 38 | AH13: 38 | AI13: 28-04-2004 | AJ13: 2004-04-28 | AP13: NO APLICA | AR13: NO APLICA | AV13: NO APLICA | AW13: DOCENTE | AX13: DOCENTE | AY13: 9 | AZ13: 9 | BA13: VICERRECTORIA ACADEMICA | BB13: VICERRECTORIA ACADEMICA | BC13: DIRECCION DE CARRERA | BD13: DIRECCION DE CARRERA | BE13: SANTIAGO | BG13: INGENIERIA EN CIBERSEGURIDAD | BH13: INGENIERIA EN CIBERSEGURIDAD | BI13: 6 | BJ13: 6 | BK13: SANTIAGO | BL13: SANTIAGO | BM13: 0 | BO13: 0 | BQ13: 6 | BR13: 6 | BS13: NO APLICA | BT13: NO APLICA | BU13: 5 | BV13: 5 | BW13: 1 | BX13: 1
... A19: CARGADO_PES | B19: 13191365 | C19: 6 | D19: ERICES GARCIA CAROLINA MARCELA | H19: Sin accion requerida. | I19: R | J19: R | K19: 13191365 | L19: 13191365 | M19: 6 | N19: 6 | O19: ERICES | P19: ERICES | Q19: GARCIA | R19: GARCIA | S19: CAROLINA MARCELA | T19: CAROLINA MARCELA | U19: M | V19: M | W19: 11-10-1977 | X19: 1977-10-11 | Y19: 38 | Z19: 38 | AA19: 2 | AB19: 2 | AC19: MAGISTER EN GESTIOIN EMPRESARIAL | AD19: MAGISTER EN GESTIÓIN EMPRESARIAL | AE19: UNOIVERSIDAD TECNICA FEDERICO SANTA MARIA | AF19: UNOIVERSIDAD TÉCNICA FEDERICO SANTA MARÍA | AG19: 38 | AH19: 38 | AI19: 21-12-2024 | AJ19: 2024-12-21 | AP19: NO APLICA | AR19: NO APLICA | AV19: NO APLICA | AW19: DOCENTE | AX19: DOCENTE | AY19: 9 | AZ19: 9 | BA19: VICERRECTORIA ACADEMICA | BB19: VICERRECTORIA ACADEMICA | BC19: DIRECCION DE CARRERA | BD19: DIRECCION DE CARRERA | BE19: SANTIAGO | BG19: INGENIERIA EN MARKETING DIGITAL | BH19: INGENIERIA EN MARKETING DIGITAL | BI19: 6 | BJ19: 6 | BK19: SANTIAGO | BL19: SANTIAGO | BM19: 0 | BO19: 0 | BQ19: 18 | BR19: 18 | BS19: NO APLICA | BT19: NO APLICA | BU19: 5 | BV19: 5 | BW19: 1 | BX19: 1
A20: NO_CARGADO_PENDIENTE | B20: 13255405 | C20: 6 | D20: SEVERINO DIAZ SINDY ARACELY | E20: La fecha de obtencion del titulo/grado es posterior al corte permitido y requiere confirmacion. | F20: FECHA_OBT_TIT_O_GRADO | G20: FECHA_OBT_TIT_O_GRADO=2027-11-29 | H20: Validar respaldo de la fecha y autorizar correccion controlada antes de carga complementaria. | J20: R | L20: 13255405 | N20: 6 | P20: SEVERINO | R20: DIAZ | T20: SINDY ARACELY | V20: M | X20: 1977-04-14 | Z20: 38 | AB20: 3 | AD20: PROFESORA DE FÍSICA Y MATEMÁTICAS | AF20: UNIVERSIDAD MAYOR | AH20: 38 | AJ20: 2027-11-29 | AP20: NO APLICA | AR20: NO APLICA | AV20: NO APLICA | AX20: DOCENTE | AZ20: 9 | BB20: VICERRECTORIA ACADEMICA | BD20: DIRECCION DE CARRERA | BH20: INGENIERIA INDUSTRIAL | BJ20: 12 | BL20: SANTIAGO | BR20: 12 | BT20: NO APLICA | BV20: 5 | BX20: 1
A21: CARGADO_PES | B21: 13297154 | C21: 4 | D21: MONTENEGRO FERNÁNDEZ YASNA SOLEDAD | H21: Sin accion requerida. | I21: R | J21: R | K21: 13297154 | L21: 13297154 | M21: 4 | N21: 4 | O21: MONTENEGRO | P21: MONTENEGRO | Q21: FERNANDEZ | R21: FERNÁNDEZ | S21: YASNA SOLEDAD | T21: YASNA SOLEDAD | U21: M | V21: M | W21: 08-09-1977 | X21: 1977-09-08 | Y21: 38 | Z21: 38 | AA21: 4 | AB21: 4 | AC21: LICENCIADO EN EDUCACION | AD21: LICENCIADO EN EDUCACIÓN | AE21: UNIVERSIDAD MAYOR | AF21: UNIVERSIDAD MAYOR | AG21: 38 | AH21: 38 | AI21: 19-06-2024 | AJ21: 2024-06-19 | AP21: NO APLICA | AR21: NO APLICA | AV21: NO APLICA | AW21: DOCENTE | AX21: DOCENTE | AY21: 9 | AZ21: 9 | BA21: VICERRECTORIA ACADEMICA | BB21: VICERRECTORIA ACADEMICA | BC21: DIRECCION DE CARRERA | BD21: DIRECCION DE CARRERA | BE21: SANTIAGO | BG21: INGENIERIA EN ADMINISTRACION | BH21: INGENIERIA EN ADMINISTRACION | BI21: 12 | BJ21: 12 | BK21: SANTIAGO | BL21: SANTIAGO | BM21: 0 | BO21: 0 | BQ21: 15 | BR21: 15 | BS21: NO APLICA | BT21: NO APLICA | BU21: 5 | BV21: 5 | BW21: 1 | BX21: 1
A22: CARGADO_PES | B22: 13367508 | C22: 6 | D22: ARAVENA CASTILLO VLADIMIR | H22: Sin accion requerida. | I22: R | J22: R | K22: 13367508 | L22: 13367508 | M22: 6 | N22: 6 | O22: ARAVENA | P22: ARAVENA | Q22: CASTILLO | R22: CASTILLO | S22: VLADIMIR | T22: VLADIMIR | U22: H | V22: H | W22: 21-09-1978 | X22: 1978-09-21 | Y22: 38 | Z22: 38 | AA22: 3 | AB22: 3 | AC22: INGENIERO DE EJECUCION EN ADMINISTRACION DE EMPRESAS | AD22: INGENIERO DE EJECUCIÓN EN ADMINISTRACIÓN DE EMPRESAS | AE22: UNIVERSIDAD DE LOS LAGOS | AF22: UNIVERSIDAD DE LOS LAGOS | AG22: 38 | AH22: 38 | AI22: 10-01-2012 | AJ22: 2012-01-10 | AP22: NO APLICA | AR22: NO APLICA | AV22: NO APLICA | AW22: DOCENTE | AX22: DOCENTE | AY22: 9 | AZ22: 9 | BA22: VICERRECTORIA ACADEMICA | BB22: VICERRECTORIA ACADEMICA | BC22: DIRECCION DE CARRERA | BD22: DIRECCION DE CARRERA | BE22: SANTIAGO | BG22: INGENIERIA EN INFORMATICA | BH22: INGENIERIA EN INFORMATICA | BI22: 19 | BJ22: 19 | BK22: SANTIAGO | BL22: SANTIAGO | BM22: 0 | BO22: 0 | BQ22: 24 | BR22: 24 | BS22: NO APLICA | BT22: NO APLICA | BU22: 5 | BV22: 5 | BW22: 1 | BX22: 1
A23: CARGADO_PES | B23: 13469992 | C23: 2 | D23: PALMA HENRIQUEZ JUAN CARLOS | H23: Sin accion requerida. | I23: R | J23: R | K23: 13469992 | L23: 13469992 | M23: 2 | N23: 2 | O23: PALMA | P23: PALMA | Q23: HENRIQUEZ | R23: HENRIQUEZ | S23: JUAN CARLOS | T23: JUAN CARLOS | U23: H | V23: H | W23: 10-11-1988 | X23: 1988-11-10 | Y23: 38 | Z23: 38 | AA23: 3 | AB23: 3 | AC23: INGENIERO FINANCIERO | AD23: INGENIERO FINANCIERO | AE23: UNIVERSIDAD DE GRANADA | AF23: UNIVERSIDAD DE GRANADA | AG23: 59 | AH23: 59 | AI23: 04-12-2023 | AJ23: 2023-12-04 | AP23: NO APLICA | AR23: NO APLICA | AV23: NO APLICA | AW23: DOCENTE | AX23: DOCENTE | AY23: 9 | AZ23: 9 | BA23: VICERRECTORIA ACADEMICA | BB23: VICERRECTORIA ACADEMICA | BC23: DIRECCION DE CARRERA | BD23: DIRECCION DE CARRERA | BE23: SANTIAGO | BG23: FORMACION GENERAL | BH23: FORMACIÓN GENERAL | BI23: 26 | BJ23: 26 | BK23: SANTIAGO | BL23: SANTIAGO | BM23: 0 | BO23: 0 | BQ23: 24 | BR23: 24 | BS23: NO APLICA | BT23: NO APLICA | BU23: 5 | BV23: 5 | BW23: 1 | BX23: 1
A24: CARGADO_PES | B24: 13527605 | C24: 7 | D24: CONTRERAS SAAVEDRA PAOLA RUTH | H24: Sin accion requerida. | I24: R | J24: R | K24: 13527605 | L24: 13527605 | M24: 7 | N24: 7 | O24: CONTRERAS | P24: CONTRERAS | Q24: SAAVEDRA | R24: SAAVEDRA | S24: PAOLA RUTH | T24: PAOLA RUTH | U24: M | V24: M | W24: 08-06-1978 | X24: 1978-06-08 | Y24: 38 | Z24: 38 | AA24: 2 | AB24: 2 | AC24: MAGISTER EN DOCENCIA PARA LA EDUCACION SUPERIOR | AD24: MAGISTER EN DOCENCIA PARA LA EDUCACIÓN SUPERIOR | AE24: UNIVERSIDAD ANDRES BELLO | AF24: UNIVERSIDAD ANDRÉS BELLO | AG24: 38 | AH24: 38 | AI24: 25-01-2023 | AJ24: 2023-01-25 | AP24: NO APLICA | AR24: NO APLICA | AV24: NO APLICA | AW24: DOCENTE | AX24: DOCENTE | AY24: 9 | AZ24: 9 | BA24: VICERRECTORIA ACADEMICA | BB24: VICERRECTORIA ACADEMICA | BC24: DIRECCION DE CARRERA | BD24: DIRECCION DE CARRERA | BE24: CONCEPCION | BG24: TECNICO EN ENFERMERIA E INSTRUMENTACION QUIRURGICA | BH24: TECNICO EN ENFERMERIA E INSTRUMENTACION QUIRURGICA | BI24: 7 | BJ24: 7 | BK24: CONCEPCION | BL24: CONCEPCIÓN | BM24: 0 | BO24: 0 | BQ24: 7 | BR24: 7 | BS24: NO APLICA | BT24: NO APLICA | BU24: 5 | BV24: 5 | BW24: 1 | BX24: 1
A25: CARGADO_PES | B25: 13666963 | C25: K | D25: SILVA DÍAZ CLAUDIA | H25: Sin accion requerida. | I25: R | J25: R | K25: 13666963 | L25: 13666963 | M25: K | N25: K | O25: SILVA | P25: SILVA | Q25: DIAZ | R25: DÍAZ | S25: CLAUDIA | T25: CLAUDIA | U25: M | V25: M | W25: 02-10-1979 | X25: 1979-10-02 | Y25: 38 | Z25: 38 | AA25: 2 | AB25: 2 | AC25: MAGISTER EN DIRECCION Y LIDERAZGO PARA LA GESTION EDUCACIONAL | AD25: MAGISTER EN DIRECCION Y LIDERAZGO PARA LA GESTION EDUCACIONAL | AE25: UNIVERSIDAD ANDRES BELLO | AF25: UNIVERSIDAD ANDRES BELLO | AG25: 38 | AH25: 38 | AI25: 16-01-2023 | AJ25: 2023-01-16 | AP25: NO APLICA | AR25: NO APLICA | AV25: NO APLICA | AW25: DOCENTE | AX25: DOCENTE | AY25: 9 | AZ25: 9 | BA25: VICERRECTORIA ACADEMICA | BB25: VICERRECTORIA ACADEMICA | BC25: DIRECCION DE CARRERA | BD25: DIRECCION DE CARRERA | BE25: SANTIAGO | BG25: FORMACION GENERAL | BH25: FORMACIÓN GENERAL | BI25: 10 | BJ25: 10 | BK25: SANTIAGO | BL25: SANTIAGO | BM25: 0 | BO25: 0 | BQ25: 8 | BR25: 8 | BS25: NO APLICA | BT25: NO APLICA | BU25: 5 | BV25: 5 | BW25: 1 | BX25: 1
A26: CARGADO_PES | B26: 13668202 | C26: 4 | D26: POZO BAEZA EDUARDO ANDRÉS | H26: Sin accion requerida. | I26: R | J26: R | K26: 13668202 | L26: 13668202 | M26: 4 | N26: 4 | O26: POZO | P26: POZO | Q26: BAEZA | R26: BAEZA | S26: EDUARDO ANDRES | T26: EDUARDO ANDRÉS | U26: H | V26: H | W26: 04-11-1978 | X26: 1978-11-04 | Y26: 38 | Z26: 38 | AA26: 2 | AB26: 2 | AC26: MAGISTER EN ADMINISTRACION Y DIRECCION DE EMPRESAS | AD26: MAGISTER EN ADMINISTRACION Y DIRECCION DE EMPRESAS | AE26: UNIVERSIDAD DE SANTIAGO DE CHILE | AF26: UNIVERSIDAD DE SANTIAGO DE CHILE | AG26: 38 | AH26: 38 | AI26: 26-10-2018 | AJ26: 2018-10-26 | AP26: NO APLICA | AR26: NO APLICA | AV26: NO APLICA | AW26: DOCENTE | AX26: DOCENTE | AY26: 9 | AZ26: 9 | BA26: VICERRECTORIA ACADEMICA | BB26: VICERRECTORIA ACADEMICA | BC26: DIRECCION DE CARRERA | BD26: DIRECCION DE CARRERA | BE26: SANTIAGO | BG26: AUDITORIA | BH26: AUDITORIA | BI26: 6 | BJ26: 6 | BK26: SANTIAGO | BL26: SANTIAGO | BM26: 0 | BO26: 0 | BQ26: 11 | BR26: 11 | BS26: NO APLICA | BT26: NO APLICA | BU26: 5 | BV26: 5 | BW26: 1 | BX26: 1
A27: CARGADO_PES | B27: 13684591 | C27: 8 | D27: RUBIO ZÚÑIGA GUILLERMO | H27: Sin accion requerida. | I27: R | J27: R | K27: 13684591 | L27: 13684591 | M27: 8 | N27: 8 | O27: RUBIO | P27: RUBIO | Q27: ZUNIGA | R27: ZÚÑIGA | S27: GUILLERMO | T27: GUILLERMO | U27: H | V27: H | W27: 29-10-1979 | X27: 1979-10-29 | Y27: 38 | Z27: 38 | AA27: 3 | AB27: 3 | AC27: INGENIERO EN CONECTIVIDAD Y REDES | AD27: INGENIERO EN CONECTIVIDAD Y REDES | AE27: INSTITUTO PROFESIONAL SAN SEBASTIAN | AF27: INSTITUTO PROFESIONAL SAN SEBASTIÁN | AG27: 38 | AH27: 38 | AI27: 29-01-2009 | AJ27: 2009-01-29 | AP27: NO APLICA | AR27: NO APLICA | AV27: NO APLICA | AW27: DOCENTE | AX27: DOCENTE | AY27: 9 | AZ27: 9 | BA27: VICERRECTORIA ACADEMICA | BB27: VICERRECTORIA ACADEMICA | BC27: DIRECCION DE CARRERA | BD27: DIRECCION DE CARRERA | BE27: SANTIAGO | BG27: INGENIERIA EN CIBERSEGURIDAD | BH27: INGENIERIA EN CIBERSEGURIDAD | BI27: 6 | BJ27: 6 | BK27: SANTIAGO | BL27: SANTIAGO | BM27: 0 | BO27: 0 | BQ27: 6 | BR27: 6 | BS27: NO APLICA | BT27: NO APLICA | BU27: 5 | BV27: 5 | BW27: 1 | BX27: 1
A28: CARGADO_PES | B28: 13772126 | C28: 0 | D28: FERNANDEZ SOTO CESAR | H28: Sin accion requerida. | I28: R | J28: R | K28: 13772126 | L28: 13772126 | M28: 0 | N28: 0 | O28: FERNANDEZ | P28: FERNANDEZ | Q28: SOTO | R28: SOTO | S28: CESAR | T28: CESAR | U28: H | V28: H | W28: 04-01-1980 | X28: 1980-01-04 | Y28: 38 | Z28: 38 | AA28: 3 | AB28: 3 | AC28: INGENIERO CIVIL EN COMPUTACION E INFORMATICA | AD28: INGENIERO CIVIL EN COMPUTACION E INFORMATICA | AE28: UNIVERSIDAD ANDRES BELLO | AF28: UNIVERSIDAD ANDRES BELLO | AG28: 38 | AH28: 38 | AI28: 21-08-2009 | AJ28: 2009-08-21 | AP28: NO APLICA | AR28: NO APLICA | AV28: NO APLICA | AW28: DOCENTE | AX28: DOCENTE | AY28: 9 | AZ28: 9 | BA28: VICERRECTORIA ACADEMICA | BB28: VICERRECTORIA ACADEMICA | BC28: DIRECCION DE CARRERA | BD28: DIRECCION DE CARRERA | BE28: SANTIAGO | BG28: FORMACION GENERAL | BH28: FORMACIÓN GENERAL | BI28: 10 | BJ28: 10 | BK28: SANTIAGO | BL28: SANTIAGO | BM28: 0 | BO28: 0 | BQ28: 13 | BR28: 13 | BS28: NO APLICA | BT28: NO APLICA | BU28: 5 | BV28: 5 | BW28: 1 | BX28: 1
A29: CARGADO_PES | B29: 13840494 | C29: 3 | D29: SALDÍVAR FARÍAS AURORA ANDREA | H29: Sin accion requerida. | I29: R | J29: R | K29: 13840494 | L29: 13840494 | M29: 3 | N29: 3 | O29: SALDIVAR | P29: SALDÍVAR | Q29: FARIAS | R29: FARÍAS | S29: AURORA ANDREA | T29: AURORA ANDREA | U29: M | V29: M | W29: 03-10-1984 | X29: 1984-10-03 | Y29: 38 | Z29: 38 | AA29: 3 | AB29: 3 | AC29: INGENIERA EN RECURSOS HUMANOS | AD29: INGENIERA EN RECURSOS HUMANOS | AE29: IPLACEX | AF29: IPLACEX | AG29: 38 | AH29: 38 | AI29: 19-04-2024 | AJ29: 2024-04-19 | AP29: NO APLICA | AR29: NO APLICA | AV29: NO APLICA | AW29: DOCENTE | AX29: DOCENTE | AY29: 9 | AZ29: 9 | BA29: VICERRECTORIA ACADEMICA | BB29: VICERRECTORIA ACADEMICA | BC29: DIRECCION DE CARRERA | BD29: DIRECCION DE CARRERA | BE29: SANTIAGO | BG29: INGENIERIA EN SEGURIDAD PRIVADA | BH29: INGENIERIA EN SEGURIDAD PRIVADA | BI29: 6 | BJ29: 6 | BK29: SANTIAGO | BL29: SANTIAGO | BM29: 0 | BO29: 0 | BQ29: 11 | BR29: 11 | BS29: NO APLICA | BT29: NO APLICA | BU29: 5 | BV29: 5 | BW29: 1 | BX29: 1
A30: CARGADO_PES | B30: 13888857 | C30: 6 | D30: RODRIGUEZ GUTIERREZ LUIS FERNANDO | H30: Sin accion requerida. | I30: R | J30: R | K30: 13888857 | L30: 13888857 | M30: 6 | N30: 6 | O30: RODRIGUEZ | P30: RODRIGUEZ | Q30: GUTIERREZ | R30: GUTIERREZ | S30: LUIS FERNANDO | T30: LUIS FERNANDO | U30: H | V30: H | W30: 13-11-1980 | X30: 1980-11-13 | Y30: 38 | Z30: 38 | AA30: 2 | AB30: 2 | AC30: MAGISTER EN EDUCACION MENCION CALIDAD | AD30: MAGISTER EN EDUCACIÓN MENCIÓN CALIDAD | AE30: UNIVERSIDAD MIGUEL DE CERVANTES | AF30: UNIVERSIDAD MIGUEL DE CERVANTES | AG30: 38 | AH30: 38 | AI30: 10-12-2018 | AJ30: 2018-12-10 | AP30: NO APLICA | AR30: NO APLICA | AV30: NO APLICA | AW30: DOCENTE | AX30: DOCENTE | AY30: 9 | AZ30: 9 | BA30: VICERRECTORIA ACADEMICA | BB30: VICERRECTORIA ACADEMICA | BC30: DIRECCION DE CARRERA | BD30: DIRECCION DE CARRERA | BE30: SANTIAGO | BG30: TECNICO EN ENFERMERIA | BH30: TECNICO EN ENFERMERIA | BI30: 12 | BJ30: 12 | BK30: SANTIAGO | BL30: SANTIAGO | BM30: 0 | BO30: 0 | BQ30: 12 | BR30: 12 | BS30: NO APLICA | BT30: NO APLICA | BU30: 5 | BV30: 5 | BW30: 1 | BX30: 1
A31: CARGADO_PES | B31: 13916058 | C31: 4 | D31: RUBÍ RUBÍ FERNANDO MANUEL | H31: Sin accion requerida. | I31: R | J31: R | K31: 13916058 | L31: 13916058 | M31: 4 | N31: 4 | O31: RUBI | P31: RUBÍ | Q31: RUBI | R31: RUBÍ | S31: FERNANDO MANUEL | T31: FERNANDO MANUEL | U31: H | V31: H | W31: 30-06-1980 | X31: 1980-06-30 | Y31: 38 | Z31: 38 | AA31: 3 | AB31: 3 | AC31: INGENIERO EN GESTION LOGISTICA | AD31: INGENIERO EN GESTIÓN LOGÍSTICA | AE31: IP ESUCOMEX | AF31: IP ESUCOMEX | AG31: 38 | AH31: 38 | AI31: 05-06-2021 | AJ31: 2021-06-05 | AP31: NO APLICA | AR31: NO APLICA | AV31: NO APLICA | AW31: DOCENTE | AX31: DOCENTE | AY31: 9 | AZ31: 9 | BA31: VICERRECTORIA ACADEMICA | BB31: VICERRECTORIA ACADEMICA | BC31: DIRECCION DE CARRERA | BD31: DIRECCION DE CARRERA | BE31: SANTIAGO | BG31: INGENIERIA EN LOGISTICA | BH31: INGENIERIA EN LOGISTICA | BI31: 19 | BJ31: 19 | BK31: SANTIAGO | BL31: SANTIAGO | BM31: 0 | BO31: 0 | BQ31: 25 | BR31: 25 | BS31: NO APLICA | BT31: NO APLICA | BU31: 5 | BV31: 5 | BW31: 1 | BX31: 1
A32: CARGADO_PES | B32: 13931726 | C32: 2 | D32: VILLARROEL CATALAN JORGE | H32: Sin accion requerida. | I32: R | J32: R | K32: 13931726 | L32: 13931726 | M32: 2 | N32: 2 | O32: VILLARROEL | P32: VILLARROEL | Q32: CATALAN | R32: CATALAN | S32: JORGE | T32: JORGE | U32: H | V32: H | W32: 30-09-1980 | X32: 1980-09-30 | Y32: 38 | Z32: 38 | AA32: 2 | AB32: 2 | AC32: MAGISTER EN DATA SCIENCE | AD32: MAGÍSTER EN DATA SCIENCE | AE32: UNIVERSIDADADOLFO IBANEZ | AF32: UNIVERSIDADADOLFO IBÁÑEZ | AG32: 38 | AH32: 38 | AI32: 22-08-2023 | AJ32: 2023-08-22 | AP32: NO APLICA | AR32: NO APLICA | AV32: NO APLICA | AW32: DOCENTE | AX32: DOCENTE | AY32: 9 | AZ32: 9 | BA32: VICERRECTORIA ACADEMICA | BB32: VICERRECTORIA ACADEMICA | BC32: DIRECCION DE CARRERA | BD32: DIRECCION DE CARRERA | BE32: SANTIAGO | BG32: INGENIERIA EN INFORMATICA | BH32: INGENIERIA EN INFORMATICA | BI32: 18 | BJ32: 18 | BK32: SANTIAGO | BL32: SANTIAGO | BM32: 0 | BO32: 0 | BQ32: 18 | BR32: 18 | BS32: NO APLICA | BT32: NO APLICA | BU32: 5 | BV32: 5 | BW32: 1 | BX32: 1
... A39: CARGADO_PES | B39: 14691289 | C39: 3 | D39: PACHECO TINEO JUANA GUADALUPE | H39: Sin accion requerida. | I39: R | J39: R | K39: 14691289 | L39: 14691289 | M39: 3 | N39: 3 | O39: PACHECO | P39: PACHECO | Q39: TINEO | R39: TINEO | S39: JUANA GUADALUPE | T39: JUANA GUADALUPE | U39: M | V39: M | W39: 10-08-1995 | X39: 1995-08-10 | Y39: 142 | Z39: 142 | AA39: 3 | AB39: 3 | AC39: MATRONA | AD39: MATRONA | AE39: UNIVERSIDAD DE CHILE | AF39: UNIVERSIDAD DE CHILE | AG39: 38 | AH39: 38 | AI39: 27-07-2023 | AJ39: 2023-07-27 | AP39: NO APLICA | AR39: NO APLICA | AV39: NO APLICA | AW39: DOCENTE | AX39: DOCENTE | AY39: 9 | AZ39: 9 | BA39: VICERRECTORIA ACADEMICA | BB39: VICERRECTORIA ACADEMICA | BC39: DIRECCION DE CARRERA | BD39: DIRECCION DE CARRERA | BE39: SANTIAGO | BG39: TECNICO EN ENFERMERIA | BH39: TECNICO EN ENFERMERIA | BI39: 16 | BJ39: 16 | BK39: SANTIAGO | BL39: SANTIAGO | BM39: 0 | BO39: 0 | BQ39: 16 | BR39: 16 | BS39: NO APLICA | BT39: NO APLICA | BU39: 5 | BV39: 5 | BW39: 1 | BX39: 1
A40: NO_CARGADO_PENDIENTE | B40: 14713937 | C40: 3 | D40: DIAZ FORONDA CARLOS ALBERTO | E40: Falta completar un codigo valido del pais donde se obtuvo el titulo o grado. | F40: PAIS_OBTENCION_TIT_O_GRADO | G40: PAIS_OBTENCION_TIT_O_GRADO=#N/A | H40: Completar dato fuente con respaldo y regenerar candidato PES/SIES. | J40: R | L40: 14713937 | N40: 3 | P40: DIAZ | R40: FORONDA | T40: CARLOS ALBERTO | V40: H | X40: 1972-08-22 | Z40: 38 | AB40: 3 | AD40: INGENIERO COMERCIAL | AF40: UNIVERSIDAD CATÓLOCA BOLIVARIANA | AH40: #N/A | AJ40: 2000-01-21 | AP40: NO APLICA | AR40: NO APLICA | AV40: NO APLICA | AX40: DOCENTE | AZ40: 9 | BB40: VICERRECTORIA ACADEMICA | BD40: DIRECCION DE CARRERA | BH40: INGENIERIA EN FINANZAS | BJ40: 6 | BL40: SANTIAGO | BR40: 14 | BT40: NO APLICA | BV40: 5 | BX40: 1
A41: CARGADO_PES | B41: 14741813 | C41: 2 | D41: NAVARRO NAVARRO DAVID | H41: Sin accion requerida. | I41: R | J41: R | K41: 14741813 | L41: 14741813 | M41: 2 | N41: 2 | O41: NAVARRO | P41: NAVARRO | Q41: NAVARRO | R41: NAVARRO | S41: DAVID | T41: DAVID | U41: H | V41: H | W41: 08-12-1982 | X41: 1982-12-08 | Y41: 38 | Z41: 38 | AA41: 3 | AB41: 3 | AC41: INGENIERO EN MARKETING | AD41: INGENIERO EN MARKETING | AE41: DUOC UC | AF41: DUOC UC | AG41: 38 | AH41: 38 | AI41: 17-01-2019 | AJ41: 2019-01-17 | AP41: NO APLICA | AR41: NO APLICA | AV41: NO APLICA | AW41: DOCENTE | AX41: DOCENTE | AY41: 9 | AZ41: 9 | BA41: VICERRECTORIA ACADEMICA | BB41: VICERRECTORIA ACADEMICA | BC41: DIRECCION DE CARRERA | BD41: DIRECCION DE CARRERA | BE41: SANTIAGO | BG41: INGENIERIA EN INFORMATICA | BH41: INGENIERIA EN INFORMATICA | BI41: 12 | BJ41: 12 | BK41: SANTIAGO | BL41: SANTIAGO | BM41: 0 | BO41: 0 | BQ41: 12 | BR41: 12 | BS41: NO APLICA | BT41: NO APLICA | BU41: 5 | BV41: 5 | BW41: 1 | BX41: 1
A42: CARGADO_PES | B42: 15062190 | C42: 9 | D42: MARTÍNEZ LÓPEZ LUIS ALEJANDRO | H42: Sin accion requerida. | I42: R | J42: R | K42: 15062190 | L42: 15062190 | M42: 9 | N42: 9 | O42: MARTINEZ | P42: MARTÍNEZ | Q42: LOPEZ | R42: LÓPEZ | S42: LUIS ALEJANDRO | T42: LUIS ALEJANDRO | U42: H | V42: H | W42: 17-12-1981 | X42: 1981-12-17 | Y42: 38 | Z42: 38 | AA42: 3 | AB42: 3 | AC42: INGENIERO COMERCIAL | AD42: INGENIERO COMERCIAL | AE42: PONTIFICIA UNIVERSIDAD CATOLICA DE VALPARAISO | AF42: PONTIFICIA UNIVERSIDAD CATOLICA DE VALPARAISO | AG42: 38 | AH42: 38 | AI42: 01-08-2008 | AJ42: 2008-08-01 | AP42: NO APLICA | AR42: NO APLICA | AV42: NO APLICA | AW42: DOCENTE | AX42: DOCENTE | AY42: 9 | AZ42: 9 | BA42: VICERRECTORIA ACADEMICA | BB42: VICERRECTORIA ACADEMICA | BC42: DIRECCION DE CARRERA | BD42: DIRECCION DE CARRERA | BE42: SANTIAGO | BG42: INGENIERIA EN ADMINISTRACION | BH42: INGENIERIA EN ADMINISTRACION | BI42: 6 | BJ42: 6 | BK42: SANTIAGO | BL42: SANTIAGO | BM42: 0 | BO42: 0 | BQ42: 12 | BR42: 12 | BS42: NO APLICA | BT42: NO APLICA | BU42: 5 | BV42: 5 | BW42: 1 | BX42: 1
A43: CARGADO_PES | B43: 15100870 | C43: 4 | D43: ZUMAETA ORTIZ ALONSO | H43: Sin accion requerida. | I43: R | J43: R | K43: 15100870 | L43: 15100870 | M43: 4 | N43: 4 | O43: ZUMAETA | P43: ZUMAETA | Q43: ORTIZ | R43: ORTIZ | S43: ALONSO | T43: ALONSO | U43: H | V43: H | W43: 05-09-1982 | X43: 1982-09-05 | Y43: 38 | Z43: 38 | AA43: 3 | AB43: 3 | AC43: CONTADOR AUDITOR | AD43: CONTADOR AUDITOR | AE43: DUOC UC | AF43: DUOC UC | AG43: 38 | AH43: 38 | AI43: 11-02-2013 | AJ43: 2013-02-11 | AP43: NO APLICA | AR43: NO APLICA | AV43: NO APLICA | AW43: DOCENTE | AX43: DOCENTE | AY43: 9 | AZ43: 9 | BA43: VICERRECTORIA ACADEMICA | BB43: VICERRECTORIA ACADEMICA | BC43: DIRECCION DE CARRERA | BD43: DIRECCION DE CARRERA | BE43: SANTIAGO | BG43: ADMINISTRACION PUBLICA | BH43: ADMINISTRACION PUBLICA | BI43: 5 | BJ43: 5 | BK43: SANTIAGO | BL43: SANTIAGO | BM43: 0 | BO43: 0 | BQ43: 17 | BR43: 17 | BS43: NO APLICA | BT43: NO APLICA | BU43: 5 | BV43: 5 | BW43: 1 | BX43: 1
A44: CARGADO_PES | B44: 15173859 | C44: 1 | D44: OJEDA MORA ANDRÉS EDUARDO | H44: Sin accion requerida. | I44: R | J44: R | K44: 15173859 | L44: 15173859 | M44: 1 | N44: 1 | O44: OJEDA | P44: OJEDA | Q44: MORA | R44: MORA | S44: ANDRES EDUARDO | T44: ANDRÉS EDUARDO | U44: H | V44: H | W44: 03-01-1983 | X44: 1983-01-03 | Y44: 38 | Z44: 38 | AA44: 2 | AB44: 2 | AC44: MAGISTER EN INGENIERIA INFORMATICA | AD44: MAGISTER EN INGENIERÍA INFORMÁTICA | AE44: UNIVERSIDAD ANDRES BELLO | AF44: UNIVERSIDAD ANDRES BELLO | AG44: 38 | AH44: 38 | AI44: 19-12-2024 | AJ44: 2024-12-19 | AP44: NO APLICA | AR44: NO APLICA | AV44: NO APLICA | AW44: DOCENTE | AX44: DOCENTE | AY44: 9 | AZ44: 9 | BA44: VICERRECTORIA ACADEMICA | BB44: VICERRECTORIA ACADEMICA | BC44: DIRECCION DE CARRERA | BD44: DIRECCION DE CARRERA | BE44: SANTIAGO | BG44: INGENIERIA EN LOGISTICA | BH44: INGENIERIA EN LOGISTICA | BI44: 23 | BJ44: 23 | BK44: SANTIAGO | BL44: SANTIAGO | BM44: 0 | BO44: 0 | BQ44: 23 | BR44: 23 | BS44: NO APLICA | BT44: NO APLICA | BU44: 5 | BV44: 5 | BW44: 1 | BX44: 1
A45: CARGADO_PES | B45: 15283505 | C45: 1 | D45: SILVA CARTES PATRICIO EDUARDO | H45: Sin accion requerida. | I45: R | J45: R | K45: 15283505 | L45: 15283505 | M45: 1 | N45: 1 | O45: SILVA | P45: SILVA | Q45: CARTES | R45: CARTES | S45: PATRICIO EDUARDO | T45: PATRICIO EDUARDO | U45: H | V45: H | W45: 12-12-1983 | X45: 1983-12-12 | Y45: 38 | Z45: 38 | AA45: 3 | AB45: 3 | AC45: INGENIERIA EN INFORMATICA | AD45: INGENIERÍA EN INFORMÁTICA | AE45: INSTITUTO PROFESIONAL CIISA | AF45: INSTITUTO PROFESIONAL CIISA | AG45: 38 | AH45: 38 | AI45: 28-06-2023 | AJ45: 2023-06-28 | AP45: NO APLICA | AR45: NO APLICA | AV45: NO APLICA | AW45: DOCENTE | AX45: DOCENTE | AY45: 9 | AZ45: 9 | BA45: VICERRECTORIA ACADEMICA | BB45: VICERRECTORIA ACADEMICA | BC45: DIRECCION DE CARRERA | BD45: DIRECCION DE CARRERA | BE45: SANTIAGO | BG45: INGENIERIA EN INFORMATICA | BH45: INGENIERIA EN INFORMATICA | BI45: 18 | BJ45: 18 | BK45: SANTIAGO | BL45: SANTIAGO | BM45: 0 | BO45: 0 | BQ45: 18 | BR45: 18 | BS45: NO APLICA | BT45: NO APLICA | BU45: 5 | BV45: 5 | BW45: 1 | BX45: 1
A46: CARGADO_PES | B46: 15373842 | C46: 4 | D46: VILLARROEL PALMA DANIEL ANGEL | H46: Sin accion requerida. | I46: R | J46: R | K46: 15373842 | L46: 15373842 | M46: 4 | N46: 4 | O46: VILLARROEL | P46: VILLARROEL | Q46: PALMA | R46: PALMA | S46: DANIEL ANGEL | T46: DANIEL ANGEL | U46: H | V46: H | W46: 10-08-1982 | X46: 1982-08-10 | Y46: 38 | Z46: 38 | AA46: 2 | AB46: 2 | AC46: MAGISTER EN DOCENCIA PARA LA EDUCACION SUPERIOR | AD46: MAGISTER EN DOCENCIA PARA LA EDUCACIÓN SUPERIOR | AE46: UNIVERDIDAD ANDRES BELLO | AF46: UNIVERDIDAD ANDRES BELLO | AG46: 38 | AH46: 38 | AI46: 14-04-2021 | AJ46: 2021-04-14 | AP46: NO APLICA | AR46: NO APLICA | AV46: NO APLICA | AW46: DOCENTE | AX46: DOCENTE | AY46: 9 | AZ46: 9 | BA46: VICERRECTORIA ACADEMICA | BB46: VICERRECTORIA ACADEMICA | BC46: DIRECCION DE CARRERA | BD46: DIRECCION DE CARRERA | BE46: SANTIAGO | BG46: INGENIERIA EN SEGURIDAD PRIVADA | BH46: INGENIERIA EN SEGURIDAD PRIVADA | BI46: 6 | BJ46: 6 | BK46: SANTIAGO | BL46: SANTIAGO | BM46: 0 | BO46: 0 | BQ46: 6 | BR46: 6 | BS46: NO APLICA | BT46: NO APLICA | BU46: 5 | BV46: 5 | BW46: 1 | BX46: 1
A47: CARGADO_PES | B47: 15386876 | C47: K | D47: CORTÉS GARRIDO CAROLINA | H47: Sin accion requerida. | I47: R | J47: R | K47: 15386876 | L47: 15386876 | M47: K | N47: K | O47: CORTES | P47: CORTÉS | Q47: GARRIDO | R47: GARRIDO | S47: CAROLINA | T47: CAROLINA | U47: M | V47: M | W47: 13-05-1980 | X47: 1980-05-13 | Y47: 38 | Z47: 38 | AA47: 3 | AB47: 3 | AC47: INGENIERA COMERCIAL | AD47: INGENIERA COMERCIAL | AE47: UNIVERSIDAD TECNOLOGICA METROPOLITANA | AF47: UNIVERSIDAD TECNOLOGICA METROPOLITANA | AG47: 38 | AH47: 38 | AI47: 21-07-2006 | AJ47: 2006-07-21 | AP47: NO APLICA | AR47: NO APLICA | AV47: NO APLICA | AW47: DOCENTE | AX47: DOCENTE | AY47: 9 | AZ47: 9 | BA47: VICERRECTORIA ACADEMICA | BB47: VICERRECTORIA ACADEMICA | BC47: DIRECCION DE CARRERA | BD47: DIRECCION DE CARRERA | BE47: CONCEPCION | BG47: FORMACION GENERAL | BH47: FORMACIÓN GENERAL | BI47: 27.5 | BJ47: 27.5 | BK47: CONCEPCION | BL47: CONCEPCIÓN | BM47: 0 | BO47: 0 | BQ47: 25 | BR47: 25 | BS47: NO APLICA | BT47: NO APLICA | BU47: 5 | BV47: 5 | BW47: 1 | BX47: 1
A48: CARGADO_PES | B48: 15402413 | C48: 1 | D48: QUINTANILLA GALLEGUILLOS CARLOS ENRIQUE | H48: Sin accion requerida. | I48: R | J48: R | K48: 15402413 | L48: 15402413 | M48: 1 | N48: 1 | O48: QUINTANILLA | P48: QUINTANILLA | Q48: GALLEGUILLOS | R48: GALLEGUILLOS | S48: CARLOS ENRIQUE | T48: CARLOS ENRIQUE | U48: H | V48: H | W48: 13-12-1982 | X48: 1982-12-13 | Y48: 38 | Z48: 38 | AA48: 3 | AB48: 3 | AC48: INGENIERO EN COMPUTACION EN INFORMATICA | AD48: INGENIERO EN COMPUTACIÓN EN INFORMÁTICA | AE48: INSTITUTO PROFESIONAL LA ARAUCANA | AF48: INSTITUTO PROFESIONAL LA ARAUCANA | AG48: 38 | AH48: 38 | AI48: 01-04-2013 | AJ48: 2013-04-01 | AP48: NO APLICA | AR48: NO APLICA | AV48: NO APLICA | AW48: DOCENTE | AX48: DOCENTE | AY48: 9 | AZ48: 9 | BA48: VICERRECTORIA ACADEMICA | BB48: VICERRECTORIA ACADEMICA | BC48: DIRECCION DE CARRERA | BD48: DIRECCION DE CARRERA | BE48: SANTIAGO | BG48: INGENIERIA EN CIBERSEGURIDAD | BH48: INGENIERIA EN CIBERSEGURIDAD | BI48: 11 | BJ48: 11 | BK48: SANTIAGO | BL48: SANTIAGO | BM48: 0 | BO48: 0 | BQ48: 11 | BR48: 11 | BS48: NO APLICA | BT48: NO APLICA | BU48: 5 | BV48: 5 | BW48: 1 | BX48: 1
A49: CARGADO_PES | B49: 15406848 | C49: 1 | D49: SALVATIERRA GÁLVEZ MARIO ENRIQUE | H49: Sin accion requerida. | I49: R | J49: R | K49: 15406848 | L49: 15406848 | M49: 1 | N49: 1 | O49: SALVATIERRA | P49: SALVATIERRA | Q49: GALVEZ | R49: GÁLVEZ | S49: MARIO ENRIQUE | T49: MARIO ENRIQUE | U49: H | V49: H | W49: 23-01-1982 | X49: 1982-01-23 | Y49: 38 | Z49: 38 | AA49: 3 | AB49: 3 | AC49: PROFESOR DE EDUCACION MEDIA EN MATEMATICA Y ESTADISTICA | AD49: PROFESOR DE EDUCACIÓN MEDIA EN MATEMÁTICA Y ESTADÍSTICA | AE49: UNIVERSIDAD ARCIS | AF49: UNIVERSIDAD ARCIS | AG49: 38 | AH49: 38 | AI49: 11-01-2010 | AJ49: 2010-01-11 | AP49: NO APLICA | AR49: NO APLICA | AV49: NO APLICA | AW49: DOCENTE | AX49: DOCENTE | AY49: 9 | AZ49: 9 | BA49: VICERRECTORIA ACADEMICA | BB49: VICERRECTORIA ACADEMICA | BC49: DIRECCION DE CARRERA | BD49: DIRECCION DE CARRERA | BE49: SANTIAGO | BG49: FORMACION GENERAL | BH49: FORMACIÓN GENERAL | BI49: 20 | BJ49: 20 | BK49: SANTIAGO | BL49: SANTIAGO | BM49: 0 | BO49: 0 | BQ49: 20 | BR49: 20 | BS49: NO APLICA | BT49: NO APLICA | BU49: 5 | BV49: 5 | BW49: 1 | BX49: 1
A50: CARGADO_PES | B50: 15426056 | C50: 0 | D50: MALDONADO YAÑEZ ABRAHAM RAÚL | H50: Sin accion requerida. | I50: R | J50: R | K50: 15426056 | L50: 15426056 | M50: 0 | N50: 0 | O50: MALDONADO | P50: MALDONADO | Q50: YANEZ | R50: YAÑEZ | S50: ABRAHAM RAUL | T50: ABRAHAM RAÚL | U50: H | V50: H | W50: 05-09-1982 | X50: 1982-09-05 | Y50: 38 | Z50: 38 | AA50: 3 | AB50: 3 | AC50: INGENIERO EN PREVENCION DE RIESGOS | AD50: INGENIERO EN PREVENCIÓN DE RIESGOS | AE50: UNIVERSIDAD BOLIVARIANA | AF50: UNIVERSIDAD BOLIVARIANA | AG50: 38 | AH50: 38 | AI50: 09-04-2016 | AJ50: 2016-04-09 | AP50: NO APLICA | AR50: NO APLICA | AV50: NO APLICA | AW50: DOCENTE | AX50: DOCENTE | AY50: 9 | AZ50: 9 | BA50: VICERRECTORIA ACADEMICA | BB50: VICERRECTORIA ACADEMICA | BC50: DIRECCION DE CARRERA | BD50: DIRECCION DE CARRERA | BE50: SANTIAGO | BG50: INGENIERIA EN LOGISTICA | BH50: INGENIERIA EN LOGISTICA | BI50: 10 | BJ50: 10 | BK50: SANTIAGO | BL50: SANTIAGO | BM50: 0 | BO50: 0 | BQ50: 10 | BR50: 10 | BS50: NO APLICA | BT50: NO APLICA | BU50: 5 | BV50: 5 | BW50: 1 | BX50: 1
A51: CARGADO_PES | B51: 15464798 | C51: 8 | D51: MARDONES MUÑOZ FERNANDO MANUEL | H51: Sin accion requerida. | I51: R | J51: R | K51: 15464798 | L51: 15464798 | M51: 8 | N51: 8 | O51: MARDONES | P51: MARDONES | Q51: MUNOZ | R51: MUÑOZ | S51: FERNANDO MANUEL | T51: FERNANDO MANUEL | U51: H | V51: H | W51: 16-12-1981 | X51: 1981-12-16 | Y51: 38 | Z51: 38 | AA51: 3 | AB51: 3 | AC51: ADMINISTRADOR PUBLICO | AD51: ADMINISTRADOR PUBLICO | AE51: UNIVERSIDAD ACADEMIA DE HUMANISMO CRISTIANO | AF51: UNIVERSIDAD ACADEMIA DE HUMANISMO CRISTIANO | AG51: 38 | AH51: 38 | AI51: 02-06-2005 | AJ51: 2005-06-02 | AP51: NO APLICA | AR51: NO APLICA | AV51: NO APLICA | AW51: DOCENTE | AX51: DOCENTE | AY51: 9 | AZ51: 9 | BA51: VICERRECTORIA ACADEMICA | BB51: VICERRECTORIA ACADEMICA | BC51: DIRECCION DE CARRERA | BD51: DIRECCION DE CARRERA | BE51: SANTIAGO | BG51: ADMINISTRACION PUBLICA | BH51: ADMINISTRACION PUBLICA | BI51: 8 | BJ51: 8 | BK51: SANTIAGO | BL51: SANTIAGO | BM51: 0 | BO51: 0 | BQ51: 10.5 | BR51: 10.5 | BS51: NO APLICA | BT51: NO APLICA | BU51: 5 | BV51: 5 | BW51: 1 | BX51: 1
...

Sheet RESUMEN_EJECUTIVO
A1: Resumen ejecutivo Personal Academico 2026
A2: Carga PES/SIES en la Institucion | Generado: 2026-06-12T15:40:57
A5: Base original | E5: Cargados PES/SIES | I5: Pendientes | M5: % carga efectiva
A6: =TABLAS_RESUMEN!B3 -> 0 | E6: =TABLAS_RESUMEN!B4 -> 0 | I6: =TABLAS_RESUMEN!B5 -> 0 | M6: =TABLAS_RESUMEN!B6 -> 0
A8: Horas totales | E8: JCE total | I8: Magister | M8: Doctorado
A9: =TABLAS_RESUMEN!B8 -> 0 | E9: =TABLAS_RESUMEN!B9 -> 0 | I9: =TABLAS_RESUMEN!B16 -> 0 | M9: =TABLAS_RESUMEN!B18 -> 0
A14: Bloque 1: Resultado de carga PES/SIES - pendientes por motivo | G14: Bloque 2: Dedicacion horaria y JCE | L14: Bloque 3: Formacion academica
A15: =TABLAS_RESUMEN!A110 -> 0 | B15: =TABLAS_RESUMEN!B110 -> 0 | C15: =TABLAS_RESUMEN!C110 -> 0 | D15: =TABLAS_RESUMEN!D110 -> 0 | E15: =TABLAS_RESUMEN!E110 -> 0 | G15: =TABLAS_RESUMEN!A27 -> 0 | H15: =TABLAS_RESUMEN!B27 -> 0 | I15: =TABLAS_RESUMEN!C27 -> 0 | L15: =TABLAS_RESUMEN!A34 -> 0 | M15: =TABLAS_RESUMEN!B34 -> 0 | N15: =TABLAS_RESUMEN!C34 -> 0
A16: =TABLAS_RESUMEN!A111 -> 0 | B16: =TABLAS_RESUMEN!B111 -> 0 | C16: =TABLAS_RESUMEN!C111 -> 0 | D16: =TABLAS_RESUMEN!D111 -> 0 | E16: =TABLAS_RESUMEN!E111 -> 0 | G16: =TABLAS_RESUMEN!A28 -> 0 | H16: =TABLAS_RESUMEN!B28 -> 0 | I16: =TABLAS_RESUMEN!C28 -> 0 | L16: =TABLAS_RESUMEN!A35 -> 0 | M16: =TABLAS_RESUMEN!B35 -> 0 | N16: =TABLAS_RESUMEN!C35 -> 0
A17: =TABLAS_RESUMEN!A112 -> 0 | B17: =TABLAS_RESUMEN!B112 -> 0 | C17: =TABLAS_RESUMEN!C112 -> 0 | D17: =TABLAS_RESUMEN!D112 -> 0 | E17: =TABLAS_RESUMEN!E112 -> 0 | G17: =TABLAS_RESUMEN!A29 -> 0 | H17: =TABLAS_RESUMEN!B29 -> 0 | I17: =TABLAS_RESUMEN!C29 -> 0 | L17: =TABLAS_RESUMEN!A36 -> 0 | M17: =TABLAS_RESUMEN!B36 -> 0 | N17: =TABLAS_RESUMEN!C36 -> 0
A18: =TABLAS_RESUMEN!A113 -> 0 | B18: =TABLAS_RESUMEN!B113 -> 0 | C18: =TABLAS_RESUMEN!C113 -> 0 | D18: =TABLAS_RESUMEN!D113 -> 0 | E18: =TABLAS_RESUMEN!E113 -> 0 | G18: =TABLAS_RESUMEN!A30 -> 0 | H18: =TABLAS_RESUMEN!B30 -> 0 | I18: =TABLAS_RESUMEN!C30 -> 0 | L18: =TABLAS_RESUMEN!A37 -> 0 | M18: =TABLAS_RESUMEN!B37 -> 0 | N18: =TABLAS_RESUMEN!C37 -> 0
A19: =TABLAS_RESUMEN!A114 -> 0 | B19: =TABLAS_RESUMEN!B114 -> 0 | C19: =TABLAS_RESUMEN!C114 -> 0 | D19: =TABLAS_RESUMEN!D114 -> 0 | E19: =TABLAS_RESUMEN!E114 -> 0 | L19: =TABLAS_RESUMEN!A38 -> 0 | M19: =TABLAS_RESUMEN!B38 -> 0 | N19: =TABLAS_RESUMEN!C38 -> 0
A20: =TABLAS_RESUMEN!A115 -> 0 | B20: =TABLAS_RESUMEN!B115 -> 0 | C20: =TABLAS_RESUMEN!C115 -> 0 | D20: =TABLAS_RESUMEN!D115 -> 0 | E20: =TABLAS_RESUMEN!E115 -> 0 | L20: =TABLAS_RESUMEN!A39 -> 0 | M20: =TABLAS_RESUMEN!B39 -> 0 | N20: =TABLAS_RESUMEN!C39 -> 0
L21: =TABLAS_RESUMEN!A40 -> 0 | M21: =TABLAS_RESUMEN!B40 -> 0 | N21: =TABLAS_RESUMEN!C40 -> 0
A27: Bloque 4: Composicion academica - cargos | G27: Bloque 4: Programa principal top 10 | M27: Bloque 5: Transformaciones tecnicas
A28: =TABLAS_RESUMEN!A67 -> 0 | B28: =TABLAS_RESUMEN!B67 -> 0 | C28: =TABLAS_RESUMEN!C67 -> 0 | G28: =TABLAS_RESUMEN!A168 -> 0 | H28: =TABLAS_RESUMEN!B168 -> 0 | I28: =TABLAS_RESUMEN!C168 -> 0 | J28: =TABLAS_RESUMEN!D168 -> 0 | M28: =TABLAS_RESUMEN!A126 -> 0 | N28: =TABLAS_RESUMEN!B126 -> 0 | O28: =TABLAS_RESUMEN!C126 -> 0
A29: =TABLAS_RESUMEN!A68 -> 0 | B29: =TABLAS_RESUMEN!B68 -> 0 | C29: =TABLAS_RESUMEN!C68 -> 0 | G29: =TABLAS_RESUMEN!A169 -> 0 | H29: =TABLAS_RESUMEN!B169 -> 0 | I29: =TABLAS_RESUMEN!C169 -> 0 | J29: =TABLAS_RESUMEN!D169 -> 0 | M29: =TABLAS_RESUMEN!A127 -> 0 | N29: =TABLAS_RESUMEN!B127 -> 0 | O29: =TABLAS_RESUMEN!C127 -> 0
A30: =TABLAS_RESUMEN!A69 -> 0 | B30: =TABLAS_RESUMEN!B69 -> 0 | C30: =TABLAS_RESUMEN!C69 -> 0 | G30: =TABLAS_RESUMEN!A170 -> 0 | H30: =TABLAS_RESUMEN!B170 -> 0 | I30: =TABLAS_RESUMEN!C170 -> 0 | J30: =TABLAS_RESUMEN!D170 -> 0 | M30: =TABLAS_RESUMEN!A128 -> 0 | N30: =TABLAS_RESUMEN!B128 -> 0 | O30: =TABLAS_RESUMEN!C128 -> 0
A31: =TABLAS_RESUMEN!A70 -> 0 | B31: =TABLAS_RESUMEN!B70 -> 0 | C31: =TABLAS_RESUMEN!C70 -> 0 | G31: =TABLAS_RESUMEN!A171 -> 0 | H31: =TABLAS_RESUMEN!B171 -> 0 | I31: =TABLAS_RESUMEN!C171 -> 0 | J31: =TABLAS_RESUMEN!D171 -> 0 | M31: =TABLAS_RESUMEN!A129 -> 0 | N31: =TABLAS_RESUMEN!B129 -> 0 | O31: =TABLAS_RESUMEN!C129 -> 0
A32: =TABLAS_RESUMEN!A71 -> 0 | B32: =TABLAS_RESUMEN!B71 -> 0 | C32: =TABLAS_RESUMEN!C71 -> 0 | G32: =TABLAS_RESUMEN!A172 -> 0 | H32: =TABLAS_RESUMEN!B172 -> 0 | I32: =TABLAS_RESUMEN!C172 -> 0 | J32: =TABLAS_RESUMEN!D172 -> 0 | M32: =TABLAS_RESUMEN!A130 -> 0 | N32: =TABLAS_RESUMEN!B130 -> 0 | O32: =TABLAS_RESUMEN!C130 -> 0
A33: =TABLAS_RESUMEN!A72 -> 0 | B33: =TABLAS_RESUMEN!B72 -> 0 | C33: =TABLAS_RESUMEN!C72 -> 0 | G33: =TABLAS_RESUMEN!A173 -> 0 | H33: =TABLAS_RESUMEN!B173 -> 0 | I33: =TABLAS_RESUMEN!C173 -> 0 | J33: =TABLAS_RESUMEN!D173 -> 0 | M33: =TABLAS_RESUMEN!A131 -> 0 | N33: =TABLAS_RESUMEN!B131 -> 0 | O33: =TABLAS_RESUMEN!C131 -> 0
A34: =TABLAS_RESUMEN!A73 -> 0 | B34: =TABLAS_RESUMEN!B73 -> 0 | C34: =TABLAS_RESUMEN!C73 -> 0 | G34: =TABLAS_RESUMEN!A174 -> 0 | H34: =TABLAS_RESUMEN!B174 -> 0 | I34: =TABLAS_RESUMEN!C174 -> 0 | J34: =TABLAS_RESUMEN!D174 -> 0 | M34: =TABLAS_RESUMEN!A132 -> 0 | N34: =TABLAS_RESUMEN!B132 -> 0 | O34: =TABLAS_RESUMEN!C132 -> 0
A35: =TABLAS_RESUMEN!A74 -> 0 | B35: =TABLAS_RESUMEN!B74 -> 0 | C35: =TABLAS_RESUMEN!C74 -> 0 | G35: =TABLAS_RESUMEN!A175 -> 0 | H35: =TABLAS_RESUMEN!B175 -> 0 | I35: =TABLAS_RESUMEN!C175 -> 0 | J35: =TABLAS_RESUMEN!D175 -> 0 | M35: =TABLAS_RESUMEN!A133 -> 0 | N35: =TABLAS_RESUMEN!B133 -> 0 | O35: =TABLAS_RESUMEN!C133 -> 0
G36: =TABLAS_RESUMEN!A176 -> 0 | H36: =TABLAS_RESUMEN!B176 -> 0 | I36: =TABLAS_RESUMEN!C176 -> 0 | J36: =TABLAS_RESUMEN!D176 -> 0
G37: =TABLAS_RESUMEN!A177 -> 0 | H37: =TABLAS_RESUMEN!B177 -> 0 | I37: =TABLAS_RESUMEN!C177 -> 0 | J37: =TABLAS_RESUMEN!D177 -> 0
A44: Bloque 6: Alertas ejecutivas
A45: =TABLAS_RESUMEN!A201 -> 0 | B45: =TABLAS_RESUMEN!B201 -> 0 | C45: =TABLAS_RESUMEN!C201 -> 0 | D45: =TABLAS_RESUMEN!D201 -> 0
A46: =TABLAS_RESUMEN!A202 -> 0 | B46: =TABLAS_RESUMEN!B202 -> 0 | C46: =TABLAS_RESUMEN!C202 -> 0 | D46: =TABLAS_RESUMEN!D202 -> 0
A47: =TABLAS_RESUMEN!A203 -> 0 | B47: =TABLAS_RESUMEN!B203 -> 0 | C47: =TABLAS_RESUMEN!C203 -> 0 | D47: =TABLAS_RESUMEN!D203 -> 0
A48: =TABLAS_RESUMEN!A204 -> 0 | B48: =TABLAS_RESUMEN!B204 -> 0 | C48: =TABLAS_RESUMEN!C204 -> 0 | D48: =TABLAS_RESUMEN!D204 -> 0
A49: =TABLAS_RESUMEN!A205 -> 0 | B49: =TABLAS_RESUMEN!B205 -> 0 | C49: =TABLAS_RESUMEN!C205 -> 0 | D49: =TABLAS_RESUMEN!D205 -> 0
A50: =TABLAS_RESUMEN!A206 -> 0 | B50: =TABLAS_RESUMEN!B206 -> 0 | C50: =TABLAS_RESUMEN!C206 -> 0 | D50: =TABLAS_RESUMEN!D206 -> 0
A52: Nota metodologica: Indicadores calculados desde BASE_KPI y TABLAS_RESUMEN. Archivo generado con XlsxWriter, sin tablas dinamicas nativas. | J52: Doctorado = 0: No se identifican academicos con doctorado segun los datos cargados y criterios de calculo disponibles.
A55: Diferencias ORIGINAL vs SIES: corresponden principalmente a transformaciones tecnicas necesarias para carga PES/SIES: formato de fechas, normalizacion de texto, horas vacias a 0, comuna completada y limpieza de especialidad. No representan necesariamente cambios sustantivos del dato academico.
A58: Continuidad institucional: La serie historica se mantiene por continuidad del Codigo SIES 162. Aunque la institucion aparece historicamente como IP CIISA/CIISA y actualmente corresponde a IP San Sebastian, el analisis compara la misma entidad institucional por codigo SIES, no por coincidencia textual de nombre.

Sheet BASE_KPI
A1: ESTADO_CARGA_PES | B1: NUM_DOCUMENTO | C1: DV | D1: NOMBRE_COMPLETO | E1: MOTIVO_NO_CARGA_LEGIBLE | F1: COLUMNAS_OBSERVADAS | G1: ACCION_REQUERIDA_LEGIBLE | H1: SEXO | I1: SEXO_ETIQUETA | J1: FECHA_NACIMIENTO | K1: EDAD_AL_31_05_2026 | L1: TRAMO_EDAD | M1: NACIONALIDAD | N1: NIVEL_FORMACION_ACADEMICO | O1: NIVEL_FORMACION_ACADEMICO_ETIQUETA | P1: NOMBRE_TITULO_O_GRADO | Q1: PAIS_OBTENCION_TIT_O_GRADO | R1: FECHA_OBT_TIT_O_GRADO | S1: ANIOS_DESDE_TITULO | T1: TRAMO_ANTIGUEDAD_TITULO | U1: ES_MAGISTER | V1: ES_DOCTORADO | W1: ES_PROFESIONAL_CODIGO_3 | X1: ES_TECNICO_CODIGO_5 | Y1: CARGO_NORMALIZADO | Z1: CARGO_NORMALIZADO_ETIQUETA | AA1: NOMBRE_PRINCIPAL_PROGRAMA | AB1: COMUNA_PRINCIPAL_PROGRAMA | AC1: NUM_HORAS_PLANTA_NUM | AD1: NUM_HORAS_CONTRATA_NUM | AE1: NUM_HORAS_HONORARIOS_NUM | AF1: TOTAL_HORAS_ACADEMICO | AG1: JCE_ESTIMADA | AH1: TIPO_DEDICACION | AI1: TIPO_VINCULO_HORARIO
A2: CARGADO_PES | B2: 10063280 | C2: 2 | D2: ESPINOZA CHAPARRO FLORENCIO | G2: Sin accion requerida. | H2: H | I2: Hombre | J2: 1964-10-12 | K2: 61 | L2: 60 o mas | M2: 38 | N2: 5 | O2: 5 - Técnico de Nivel Superior | P2: PROGRAMADOR DE APLICACIONES | Q2: 38 | R2: 1990-10-20 | S2: 35.6 | T2: 15 anios o mas | U2: No | V2: No | W2: No | X2: Si | Y2: 9 | Z2: 9 - Docente | AA2: INGENIERIA EN CIBERSEGURIDAD | AB2: SANTIAGO | AC2: 0 | AD2: 0 | AE2: 18 | AF2: 18 | AG2: 0.41 | AH2: Media dedicacion | AI2: Solo honorarios
A3: CARGADO_PES | B3: 10393519 | C3: 9 | D3: LOPEZ PARRA JOSÉ JOEL | G3: Sin accion requerida. | H3: H | I3: Hombre | J3: 1966-12-18 | K3: 59 | L3: 50 a 59 | M3: 38 | N3: 3 | O3: 3 - Título Profesional | P3: INGENIERO DE EJECUCIÓN EN ADMINISTRACIÓN Y FINANZAS | Q3: 38 | R3: 2012-07-19 | S3: 13.9 | T3: 10 a 14 anios | U3: No | V3: No | W3: Si | X3: No | Y3: 9 | Z3: 9 - Docente | AA3: INGENIERIA EN ADMINISTRACION DE EMPRESAS | AB3: SANTIAGO | AC3: 0 | AD3: 0 | AE3: 25 | AF3: 25 | AG3: 0.57 | AH3: Alta dedicacion | AI3: Solo honorarios
A4: CARGADO_PES | B4: 10536500 | C4: 4 | D4: GARCIA ROMERO MARIO | G4: Sin accion requerida. | H4: H | I4: Hombre | J4: 1967-04-14 | K4: 59 | L4: 50 a 59 | M4: 38 | N4: 2 | O4: 2 - Magíster | P4: MMAGISTER EN DOCENCIA PARA LA EDUCACIÓN SUPERIOR | Q4: 38 | R4: 2011-11-08 | S4: 14.6 | T4: 10 a 14 anios | U4: Si | V4: No | W4: No | X4: No | Y4: 9 | Z4: 9 - Docente | AA4: FORMACIÓN GENERAL | AB4: SANTIAGO | AC4: 0 | AD4: 0 | AE4: 24.5 | AF4: 24.5 | AG4: 0.56 | AH4: Alta dedicacion | AI4: Solo honorarios
A5: CARGADO_PES | B5: 10727793 | C5: 5 | D5: BRAVO FIGUEROA PATRICIO ANDRÉS | G5: Sin accion requerida. | H5: H | I5: Hombre | J5: 1969-06-02 | K5: 56 | L5: 50 a 59 | M5: 38 | N5: 2 | O5: 2 - Magíster | P5: MAGÍSTER EN GESTIÓN PEDAGÓGICA - CURRICULAR Y PROYECTOS EDUCATIVOS | Q5: 38 | R5: 2023-10-06 | S5: 2.7 | T5: 0 a 4 anios | U5: Si | V5: No | W5: No | X5: No | Y5: 9 | Z5: 9 - Docente | AA5: FORMACIÓN GENERAL | AB5: SANTIAGO | AC5: 0 | AD5: 0 | AE5: 24.5 | AF5: 24.5 | AG5: 0.56 | AH5: Alta dedicacion | AI5: Solo honorarios
A6: CARGADO_PES | B6: 11250569 | C6: 5 | D6: CASAS KRAM DINA MAGDALENA | G6: Sin accion requerida. | H6: M | I6: Mujer | J6: 1968-07-06 | K6: 57 | L6: 50 a 59 | M6: 38 | N6: 2 | O6: 2 - Magíster | P6: MAGÍSTER EN DOCENCIA PARA LA EDUCACIÓN SUPERIOR | Q6: 38 | R6: 2023-07-13 | S6: 2.9 | T6: 0 a 4 anios | U6: Si | V6: No | W6: No | X6: No | Y6: 9 | Z6: 9 - Docente | AA6: TECNICO EN ENFERMERIA | AB6: SANTIAGO | AC6: 0 | AD6: 0 | AE6: 20 | AF6: 20 | AG6: 0.45 | AH6: Media dedicacion | AI6: Solo honorarios
A7: CARGADO_PES | B7: 11481000 | C7: 2 | D7: AGUILAR SANTANA CARLOS ALFREDO | G7: Sin accion requerida. | H7: H | I7: Hombre | J7: 1968-08-21 | K7: 57 | L7: 50 a 59 | M7: 38 | N7: 3 | O7: 3 - Título Profesional | P7: PROFESOR DE MATEMÁTICAS | Q7: 38 | R7: 1996-08-08 | S7: 29.8 | T7: 15 anios o mas | U7: No | V7: No | W7: Si | X7: No | Y7: 9 | Z7: 9 - Docente | AA7: FORMACIÓN GENERAL | AB7: SANTIAGO | AC7: 0 | AD7: 0 | AE7: 10 | AF7: 10 | AG7: 0.23 | AH7: Baja dedicacion | AI7: Solo honorarios
A8: CARGADO_PES | B8: 11613889 | C8: 1 | D8: MENA ZUMARÁN NINROD | G8: Sin accion requerida. | H8: M | I8: Mujer | J8: 1970-02-24 | K8: 56 | L8: 50 a 59 | M8: 38 | N8: 3 | O8: 3 - Título Profesional | P8: INGENIERO EN EJECUCIÓN ELECTRÓNICA | Q8: 38 | R8: 2020-02-18 | S8: 6.3 | T8: 5 a 9 anios | U8: No | V8: No | W8: Si | X8: No | Y8: 9 | Z8: 9 - Docente | AA8: INGENIERIA EN CIBERSEGURIDAD | AB8: SANTIAGO | AC8: 0 | AD8: 0 | AE8: 3 | AF8: 3 | AG8: 0.07 | AH8: Baja dedicacion | AI8: Solo honorarios
A9: CARGADO_PES | B9: 11640980 | C9: 1 | D9: LARA ORELLANA PATRICIO ANDRÉS | G9: Sin accion requerida. | H9: H | I9: Hombre | J9: 1970-12-15 | K9: 55 | L9: 50 a 59 | M9: 38 | N9: 3 | O9: 3 - Título Profesional | P9: INGENIERO EN EJECUCIÓN EN ADMINISTRACIÓN PÚBLICA | Q9: 38 | R9: 2005-10-25 | S9: 20.6 | T9: 15 anios o mas | U9: No | V9: No | W9: Si | X9: No | Y9: 9 | Z9: 9 - Docente | AA9: ADMINISTRACION PUBLICA | AB9: SANTIAGO | AC9: 0 | AD9: 0 | AE9: 15 | AF9: 15 | AG9: 0.34 | AH9: Media dedicacion | AI9: Solo honorarios
A10: CARGADO_PES | B10: 11944423 | C10: 3 | D10: SUMA DE VILLA NELSON CARVALLO | G10: Sin accion requerida. | H10: H | I10: Hombre | J10: 1972-05-06 | K10: 54 | L10: 50 a 59 | M10: 38 | N10: 4 | O10: 4 - Licenciatura | P10: LICENCIADO EN MATEMÁTICA Y COMPUTACIÓN | Q10: 38 | R10: 1998-05-19 | S10: 28 | T10: 15 anios o mas | U10: No | V10: No | W10: No | X10: No | Y10: 9 | Z10: 9 - Docente | AA10: INGENIERIA EN INFORMATICA | AB10: SANTIAGO | AC10: 0 | AD10: 0 | AE10: 15 | AF10: 15 | AG10: 0.34 | AH10: Media dedicacion | AI10: Solo honorarios
A11: CARGADO_PES | B11: 12141132 | C11: 6 | D11: SANDOVAL TRONCOSO SEBASTIÁN | G11: Sin accion requerida. | H11: H | I11: Hombre | J11: 1970-11-21 | K11: 55 | L11: 50 a 59 | M11: 38 | N11: 3 | O11: 3 - Título Profesional | P11: INGENIERO EN CONECTIVIDAD Y REDES | Q11: 38 | R11: 2025-04-28 | S11: 1.1 | T11: 0 a 4 anios | U11: No | V11: No | W11: Si | X11: No | Y11: 9 | Z11: 9 - Docente | AA11: INGENIERIA EN INFORMATICA | AB11: SANTIAGO | AC11: 0 | AD11: 0 | AE11: 3 | AF11: 3 | AG11: 0.07 | AH11: Baja dedicacion | AI11: Solo honorarios
A12: CARGADO_PES | B12: 12240733 | C12: 0 | D12: ÁLVAREZ MAULÉN MILTON | G12: Sin accion requerida. | H12: H | I12: Hombre | J12: 1972-07-31 | K12: 53 | L12: 50 a 59 | M12: 38 | N12: 3 | O12: 3 - Título Profesional | P12: PROFESOR DE ESTADO EN FÍSICA Y MATEMÁTICA | Q12: 38 | R12: 2009-06-16 | S12: 17 | T12: 15 anios o mas | U12: No | V12: No | W12: Si | X12: No | Y12: 9 | Z12: 9 - Docente | AA12: FORMACIÓN GENERAL | AB12: SANTIAGO | AC12: 0 | AD12: 0 | AE12: 25 | AF12: 25 | AG12: 0.57 | AH12: Alta dedicacion | AI12: Solo honorarios
A13: CARGADO_PES | B13: 12534768 | C13: 1 | D13: MATUS PEZO RODRIGO | G13: Sin accion requerida. | H13: H | I13: Hombre | J13: 1973-11-08 | K13: 52 | L13: 50 a 59 | M13: 38 | N13: 3 | O13: 3 - Título Profesional | P13: INGENIERO DE EJECUCIÓN EN INFORMÁTICA | Q13: 38 | R13: 2004-04-28 | S13: 22.1 | T13: 15 anios o mas | U13: No | V13: No | W13: Si | X13: No | Y13: 9 | Z13: 9 - Docente | AA13: INGENIERIA EN CIBERSEGURIDAD | AB13: SANTIAGO | AC13: 0 | AD13: 0 | AE13: 6 | AF13: 6 | AG13: 0.14 | AH13: Baja dedicacion | AI13: Solo honorarios
... A19: CARGADO_PES | B19: 13191365 | C19: 6 | D19: ERICES GARCIA CAROLINA MARCELA | G19: Sin accion requerida. | H19: M | I19: Mujer | J19: 1977-10-11 | K19: 48 | L19: 40 a 49 | M19: 38 | N19: 2 | O19: 2 - Magíster | P19: MAGISTER EN GESTIÓIN EMPRESARIAL | Q19: 38 | R19: 2024-12-21 | S19: 1.4 | T19: 0 a 4 anios | U19: Si | V19: No | W19: No | X19: No | Y19: 9 | Z19: 9 - Docente | AA19: INGENIERIA EN MARKETING DIGITAL | AB19: SANTIAGO | AC19: 0 | AD19: 0 | AE19: 18 | AF19: 18 | AG19: 0.41 | AH19: Media dedicacion | AI19: Solo honorarios
A20: NO_CARGADO_PENDIENTE | B20: 13255405 | C20: 6 | D20: SEVERINO DIAZ SINDY ARACELY | E20: La fecha de obtencion del titulo/grado es posterior al corte permitido y requiere confirmacion. | F20: FECHA_OBT_TIT_O_GRADO | G20: Validar respaldo de la fecha y autorizar correccion controlada antes de carga complementaria. | H20: M | I20: Mujer | J20: 1977-04-14 | K20: 49 | L20: 40 a 49 | M20: 38 | N20: 3 | O20: 3 - Título Profesional | P20: PROFESORA DE FÍSICA Y MATEMÁTICAS | Q20: 38 | R20: 2027-11-29 | T20: Sin dato | U20: No | V20: No | W20: Si | X20: No | Y20: 9 | Z20: 9 - Docente | AA20: INGENIERIA INDUSTRIAL | AB20: SANTIAGO | AC20: 0 | AD20: 0 | AE20: 12 | AF20: 12 | AG20: 0.27 | AH20: Media dedicacion | AI20: Solo honorarios
A21: CARGADO_PES | B21: 13297154 | C21: 4 | D21: MONTENEGRO FERNÁNDEZ YASNA SOLEDAD | G21: Sin accion requerida. | H21: M | I21: Mujer | J21: 1977-09-08 | K21: 48 | L21: 40 a 49 | M21: 38 | N21: 4 | O21: 4 - Licenciatura | P21: LICENCIADO EN EDUCACIÓN | Q21: 38 | R21: 2024-06-19 | S21: 1.9 | T21: 0 a 4 anios | U21: No | V21: No | W21: No | X21: No | Y21: 9 | Z21: 9 - Docente | AA21: INGENIERIA EN ADMINISTRACION | AB21: SANTIAGO | AC21: 0 | AD21: 0 | AE21: 15 | AF21: 15 | AG21: 0.34 | AH21: Media dedicacion | AI21: Solo honorarios
