Workbook

Sheet Portada
A1: 🏠 Portada / Índice
B3: Retención de 1er Año — IPSS 2022-2026
B4: Cruce entre la Matrícula Unificada informada a SIES y las cifras oficiales publicadas por SIES
B6: Elaborado por | C6: Dirección de Análisis Institucional (DAI) — Instituto Profesional San Sebastián
B7: Fecha de elaboración | C7: 30-09-2026
B8: Alcance | C8: Cohortes de primer año 2022 a 2025 (candidatos con año siguiente disponible para medir retención)
B9: Fuente técnica base | C9: Análisis gobernado en el proyecto avance_curricular, hito H001-RETENCION-IPSS162
B10: Uso de datos personales | C10: SÍ. Por instrucción explícita del usuario (30-09-2026), este archivo incluye identificadores de estudiante (nombre, RUT, fecha de nacimiento) en las hojas 9 y 11, para uso de gerencia.
B11: Clasificación de uso | C11: USO RESTRINGIDO — contiene datos personales de estudiantes. Distribución exclusiva a gerencia IPSS.
B13: Contenido de este documento
B14: 1. ¿Qué es la retención de 1er año?
B15: 2. ¿De dónde vienen los datos?
B16: 3. ¿Cómo se hace el cruce?
B17: 4. Resultados por sector
B18: 5. Evolución 2022-2026
B19: 6. Limitaciones
B20: 7. Glosario
B22: Hojas de soporte técnico y de detalle granular al final del libro. Las hojas 9 y 11 contienen datos personales de estudiantes; la hoja 12 agrega el desglose por jornada, edad y sexo por carrera; la hoja 13 reconstruye el código único de SIES por carrera+jornada+versión para los 4 años y valida 2025 contra el dato real enviado por SIES; la hoja 14 consolida las vistas ejecutivas (institucional, sector, sede, modalidad, carrera) con mejor/peor % y conclusiones — uso restringido, no redistribuir.

Sheet 1_Que_es_Retencion
A1: 🏠 Portada / Índice
A2: 1. ¿Qué es la retención de 1er año?
B4: Definición oficial
B5: "Es el porcentaje de estudiantes que, estando matriculados como estudiantes de primer año en una institución de educación superior en un año de referencia dado, se mantiene matriculado en la misma institución y en la misma generación o cohorte de origen al año siguiente, respecto del total de estudiantes de primer año que ingresó en el año de referencia."
B10: Fuente: correo de Rodrigo Rolando Meneses (SIES/MINEDUC) a Karla Muñoz Gajardo (IPSS), 09-09-2026, asunto "RV: Matrícula de 1er año". Clasificación A — definición oficial. Transcripción gobernada en CARACTERIZACIÓN/gobernanza/sies/RETENCION/REGLA_RETENCION_1ER_ANIO_CORREO_20260909.txt
B12: Reglas de aplicación (del mismo correo, clasificación A)
B13: • Se consideran solo programas regulares: 4 semestres mínimo para carreras técnicas, 6 para profesionales sin licenciatura, 8 para profesionales con licenciatura y licenciaturas no conducentes a título.
B14: • Quedan excluidos los programas especiales (planes no regulares).
B15: • Se eliminan casos puntuales de estudiantes con inconsistencias de cohorte de origen de un año a otro.
B16: • Solo se publican cifras cuando la categoría tiene 10 o más casos en la cohorte de origen.
B17: • La fecha de referencia de la matrícula de cada año es el 30 de abril de ese año.
B19: Nota: el umbral de 10 casos aplica a lo que SIES publica de forma agregada. En este documento, cuando un sector o carrera tiene menos de 10 casos, igual se muestra el resultado interno (porque es un análisis propio, no una publicación oficial de SIES), pero se advierte en la hoja de resultados.

Sheet 2_Origen_Datos
A1: 🏠 Portada / Índice
A2: 2. ¿De dónde vienen los datos?
B4: ¿Qué es la Matrícula Unificada?
B5: Cada año, IPSS informa a SIES (Servicio de Información de Educación Superior, MINEDUC) un registro por cada estudiante matriculado: en qué carrera está, en qué año y semestre ingresó a esa carrera, y si su matrícula sigue vigente. Ese envío se llama Matrícula Unificada y es la misma información que después SIES usa para publicar sus propias cifras oficiales, incluida la retención de 1er año.
B7: La base que usamos en este análisis
B8: Se trabajó con la Matrícula Unificada de IPSS de los años 2022 a 2026: 10.200 registros en total. Esta base fue construida y verificada en el proyecto avance_curricular (verificación por huella digital SHA-256 el 01-09-2026), y es la misma base ya usada en el análisis técnico completo de retención.
B10: Lo que NO contiene este archivo
B11: Por instrucción explícita del usuario (30-09-2026), este documento SÍ incluye identificadores de estudiante (nombre, RUT, fecha de nacimiento) en las hojas 9 y 11, porque está destinado a gerencia y se requiere poder revisar el detalle individual. Es uso restringido: no debe redistribuirse fuera de gerencia sin autorización.
B13: La cifra de comparación: SIES publicada
B14: Para contrastar, se usa la cifra de retención que SIES publica oficialmente para IPSS (informe agregado institucional 2022-2025), y además la tabla granular por carrera que SIES envió por correo para el año 2025 (36 códigos de carrera). No existe una tabla granular por carrera publicada por SIES para 2022, 2023 ni 2024; para esos años solo se compara la cifra institucional total.
B16: Fuentes: Base Matrícula Unificada IPSS 2022-2026 (B, avance_curricular); Informe de Retención SIES agregado institucional 2022-2025 (B, gobernanza/sies/RETENCION); correo granular SIES 2025 de Rodrigo Rolando Meneses, 09-09-2026 (A/B).

Sheet 3_Como_se_Cruza
A1: 🏠 Portada / Índice
A2: 3. ¿Cómo se hace el cruce?
B4: Paso 1 — ¿Quién es candidato de primer año?
B5: Un estudiante entra al cálculo de un año X cuando su año de ingreso a la carrera de origen es igual a X, está en un plan regular (no especial), y su carrera cumple la duración mínima exigida (4, 6 u 8 semestres según el tipo). Esto sigue exactamente la definición A del correo SIES.
B7: Paso 2 — ¿Qué significa "vigente"?
B8: La Matrícula Unificada informa un código de vigencia (VIG) por estudiante: 0 = sin matrícula, 1 = con matrícula vigente, 2 = egresado con matrícula vigente (Manual de Procesos: Matrícula Unificada 2026, clasificación A). Un estudiante "retenido" es aquel candidato que, al año siguiente, aparece con VIG 1 o 2 en la misma institución y en la misma cohorte de origen.
B10: Paso 3 — Exclusiones
B11: Se excluyen del cálculo los casos donde la cohorte de origen del estudiante cambia de forma inconsistente de un año a otro (mismo criterio que aplica SIES, implementado como regla propia — clasificación C, documentada y auditada en el archivo técnico).
B13: Paso 4 — El resultado
B14: Con esas reglas aplicadas fila por fila sobre los 10.200 registros, cada candidato queda marcado como "incluido" o no, y como "retenido" o no. Ese cálculo fila por fila —con fórmulas verificadas de forma independiente— es el que ya está gobernado y auditado en el archivo técnico. Este documento ejecutivo toma esos resultados ya calculados y los agrupa por sector para presentarlos.
B16: Fuente técnica completa: RETENCION_PRIMER_ANIO_IPSS_162_DIAGNOSTICO_BRECHAS_20260930.xlsx (SHA-256 5f0f7c7f...c77b3), hito H001-RETENCION-IPSS162, proyecto avance_curricular. Clasificación C — implementación técnica, verificada de forma independiente fila por fila.

Sheet 4_Resultados_Sector
A1: 🏠 Portada / Índice
A2: 4. Resultados por sector
B3: C · Foto de valores históricos preservados; detalle individual excluido. No recalcula con filtros en esta copia agregada.
B5: A. Retención interna por sector y cohorte | H5: B. Comparación 2025 — interna vs. SIES granular oficial, por sector
B6: Sector | C6: Cohorte | D6: Estudiantes | E6: Retenidos | F6: Tasa de retención | H6: Sector | I6: Estudiantes IPSS 2025 | J6: Retenidos internos 2025 | K6: Tasa interna 2025 | L6: Estudiantes SIES 2025 | M6: Retenidos SIES 2025 | N6: Tasa SIES 2025 | O6: Brecha (pp)
B7: Tecnologías | C7: 2022 | D7: 305 | E7: 224 | F7: 0.73442623 | H7: Tecnologías | I7: 598 | J7: 381 | K7: 0.63712375 | L7: 607 | M7: 386 | N7: 0.63591433 | O7: 0.1209413
B8: Tecnologías | C8: 2023 | D8: 366 | E8: 258 | F8: 0.70491803 | H8: Administración y Comercio | I8: 477 | J8: 252 | K8: 0.52830189 | L8: 481 | M8: 256 | N8: 0.53222453 | O8: -0.39226454
B9: Tecnologías | C9: 2024 | D9: 497 | E9: 299 | F9: 0.60160966 | H9: Salud | I9: 75 | J9: 35 | K9: 0.46666667 | L9: 75 | M9: 35 | N9: 0.46666667 | O9: 0
B10: Tecnologías | C10: 2025 | D10: 598 | E10: 381 | F10: 0.63712375
B11: Administración y Comercio | C11: 2022 | D11: 0 | E11: 0 | H11: La comparación granular por carrera solo existe para el año 2025 (tabla enviada por correo). Para 2022-2024, SIES no publicó esa tabla por carrera — esos años solo se comparan a nivel institucional total en la hoja 5.
B12: Administración y Comercio | C12: 2023 | D12: 0 | E12: 0
B13: Administración y Comercio | C13: 2024 | D13: 61 | E13: 27 | F13: 0.44262295
B14: Administración y Comercio | C14: 2025 | D14: 477 | E14: 252 | F14: 0.52830189
B15: Salud | C15: 2022 | D15: 0 | E15: 0
B16: Salud | C16: 2023 | D16: 0 | E16: 0
B17: Salud | C17: 2024 | D17: 0 | E17: 0
B18: Salud | C18: 2025 | D18: 75 | E18: 35 | F18: 0.46666667
B20: Administración y Comercio muestra candidatos recién desde 2024, y Salud recién desde 2025 (dato observado: apertura progresiva de esos sectores en la oferta de IPSS).
B22: Tabla auxiliar para el gráfico (técnica, no editar)
B23: Cohorte | C23: Tecnologías | D23: Administración y Comercio | E23: Salud
B24: 2022 | C24: 0.73442623
B25: 2023 | C25: 0.70491803
B26: 2024 | C26: 0.60160966 | D26: 0.44262295
B27: 2025 | C27: 0.63712375 | D27: 0.52830189 | E27: 0.46666667
H35: Conclusión: La tasa interna 2025 coincide casi exactamente con lo publicado por SIES en los tres sectores (brechas menores a 0,4 puntos porcentuales) — confirma que el cálculo interno está bien alineado con la fuente oficial para el año en que existe tabla granular de comparación.
B47: Conclusión: Tecnologías se mantiene sobre 60% en todas las cohortes y es el único sector con serie completa 2022-2025. Administración y Comercio (desde 2024) y Salud (desde 2025) recién tienen uno o dos años de datos — su tendencia todavía no es comparable con Tecnologías.

Sheet 5_Evolucion
A1: 🏠 Portada / Índice
A2: 5. Evolución 2022-2026 (nivel institucional)
B3: Tasa interna: fórmula en vivo sobre la base anonimizada (hoja 9), todos los sectores. Tasa SIES publicada: cifra oficial institucional, gobernada en el informe SIES agregado 2022-2025 (clasificación B). 2026 no tiene retención medible todavía: recién se sabrá en 2027, cuando exista el año siguiente para esa cohorte.
B5: Evolución institucional 2022-2025 — interna vs. SIES publicada
B6: Cohorte | C6: Estudiantes IPSS | D6: Retenidos internos | E6: Tasa interna | F6: Tasa SIES publicada | G6: Brecha (pp)
B7: 2022 | C7: 305 | D7: 224 | E7: 0.73442623 | F7: 0.68951613 | G7: 4.49101
B8: 2023 | C8: 366 | D8: 258 | E8: 0.70491803 | F8: 0.70572207 | G8: -0.080403806
B9: 2024 | C9: 558 | D9: 326 | E9: 0.58422939 | F9: 0.675 | G9: -9.0770609
B10: 2025 | C10: 1150 | D10: 668 | E10: 0.58086957 | F10: 0.58211522 | G10: -0.1245654
B12: 2026 no tiene retención medible todavía: recién se sabrá en 2027, cuando exista el año siguiente para esa cohorte. Tasa SIES publicada: cifra oficial institucional gobernada en el informe SIES agregado 2022-2025 (clasificación B).
B34: Lectura de los resultados (B/C/E): las tasas internas y las publicadas por SIES son cercanas en 2023 y 2025. En 2022 la tasa interna supera a SIES en 4,49 puntos porcentuales y en 2024 queda 9,08 puntos por debajo. Estas dos brechas siguen sin una causa completamente verificada; el gráfico conserva ambas series para mostrar la diferencia.

Sheet 6_Limitaciones
A1: 🏠 Portada / Índice
A2: 6. Limitaciones
B4: • Umbral de 10 casos: SIES solo publica cifras oficiales cuando una categoría tiene 10 o más casos. Este documento sí muestra resultados internos por sector aunque tengan menos de 10 casos, porque es un cálculo propio, no una cifra oficial publicada — se indica cuando corresponde.
B5: • Fecha de corte 30 de abril: no aplica como pendiente — los documentos revisados en este análisis corresponden a lo ya informado a SIES, por lo que la vigencia de corte queda resuelta por ese hecho (decisión del usuario, 2026-09-30). Nota de precisión: el campo FECHA_MATRICULA sí existe en la base RAW BASE_RETENCION_MU (columna AE, 8.017 de 10.200 filas con valor), aunque no fue propagado al cruce ya gobernado — dato observado directamente, no cambia el resultado.
B6: • Brechas 2022 y 2024 sin causa establecida: al comparar la tasa interna con la tasa SIES publicada, 2022 muestra una diferencia de +4,5 puntos porcentuales aproximados y 2024 de -9,1 puntos porcentuales aproximados. Se revisaron las reglas del manual de matrícula unificada y la cobertura de los datos de esos años sin encontrar una causa que explique la diferencia por completo. Se deja registrada como diferencia sin causa establecida (clasificación E), nunca forzada ni inventada.
B7: • Comparación granular por sector (actualizado 2026-09-30): para 2025, SIES envió la tabla oficial desglosada por carrera (hoja 10) — se validó código por código contra el cálculo interno (hoja 13, Sección A). Para 2022-2024 no existe ese envío externo, pero sí se construyó el mismo desglose de forma interna (hoja 13, Sección B), reconstruyendo el código único de SIES a partir de columnas ya gobernadas de BASE_RETENCION_MU (COD_SED, COD_CAR, JOR, VERSION) — sin validación externa por código para esos 3 años, solo con el porcentaje agregado publicado por SIES como referencia de nivel superior.
B8: • 2026 sin retención medible aún: los estudiantes de primer año de 2026 recién podrán evaluarse en 2027, cuando exista el año siguiente de matrícula.
B9: • Datos personales: este documento SÍ incluye identificadores de estudiante (nombre, RUT, fecha de nacimiento) en las hojas 9 y 11, por instrucción explícita del usuario (2026-09-30), porque su audiencia es gerencia y requiere poder revisar el detalle individual. USO RESTRINGIDO — no redistribuir fuera de gerencia sin autorización. El detalle completo, con las reglas de elegibilidad aplicadas a cada candidato, permanece además gobernado en el archivo técnico completo, hito H001-RETENCION-IPSS162.
B10: C · Foto de valores históricos preservados; detalle individual excluido. No recalcula con filtros en esta copia agregada.
B11: • Reconciliación granular 2025 (2026-09-30): al comparar código por código el cálculo interno contra el envío real de SIES (hoja 13, Sección A), 27 de 36 códigos coinciden exactamente. En 9 códigos — 7 de ellos en jornada Virtual — el cálculo interno cuenta 1 o 2 casos menos que SIES, sumando 13 casos y 9 retenidos de diferencia en total. La suma de los 36 códigos de SIES (1.163 casos / 677 retenidos / 58,2115%) coincide exactamente con el "Total general" que Rodrigo Rolando Meneses envió y con la tasa oficial publicada — confirmando que esos 13 casos son la explicación completa y ya cuantificada de la diferencia entre la tasa interna 2025 (58,09%) y la oficial (58,21%). Carreras afectadas: Ingeniería en Conectividad y Redes, Ingeniería en Ciberseguridad, Técnico en Programación y Análisis de Sistemas, Ingeniería en Administración de Empresas, Ingeniería en Logística, Auditoría, Ingeniería en Ciencia de Datos.
B12: • Vistas ejecutivas (2026-09-30): se agregó la hoja 14 con el desglose institucional → sector → sede → modalidad → carrera, mejor/peor % por dimensión y conclusiones. El hallazgo inicial sugerido de "a mayor edad, mejor retención" no se sostiene en el dato combinado 2022-2025: la mejor tasa está en 20-24 años (70,4%) y baja con la edad hasta 40+ (56,2%, la peor) — ver hoja 14 para el detalle y la comparación por año, que muestra que el patrón se invirtió entre 2022 y 2024-2025.

Sheet 7_Glosario
A1: 🏠 Portada / Índice
A2: 7. Glosario
B4: Término | C4: Definición en lenguaje simple
B5: Retención de 1er año | C5: Porcentaje de estudiantes de primer año que sigue matriculado en la misma institución y cohorte al año siguiente, sobre el total que ingresó ese año.
B6: Cohorte | C6: Grupo de estudiantes que ingresó a una carrera en el mismo año y semestre.
B7: VIG (vigencia) | C7: Código que indica si la matrícula de un estudiante sigue activa: 0 = sin matrícula, 1 = con matrícula vigente, 2 = egresado con matrícula vigente.
B8: Matrícula Unificada | C8: Información que IPSS envía cada año a SIES con los datos de todos sus estudiantes matriculados.
B9: SIES | C9: Servicio de Información de Educación Superior, del Ministerio de Educación de Chile.
B10: Sector IPSS | C10: Agrupación de carreras tal como IPSS las organiza en su propio sitio web (ipss.cl): Tecnologías, Administración y Comercio, Salud (más el sector Ingeniería, que no aplica a las carreras de este análisis).
B11: Área SIES/CINE-F | C11: Clasificación académica que usa SIES para agrupar carreras (por ejemplo, "Tecnología" o "Ciencias Básicas"). No es la misma agrupación que usa IPSS internamente.
B12: Brecha (pp) | C12: Diferencia, en puntos porcentuales, entre la tasa calculada internamente y la tasa publicada por SIES.
B13: Candidato incluido | C13: Estudiante de primer año que cumple todas las condiciones para entrar al cálculo de retención (carrera regular, duración suficiente, sin inconsistencias de cohorte).

Sheet 8_Mapeo_Sector_IPSS
A1: 🏠 Portada / Índice
A2: 8. Mapeo de carrera a sector IPSS (hoja de soporte técnico)
B3: Sector según la taxonomía propia de IPSS publicada en ipss.cl ("Sectores de Estudio"), consultada el 30-09-2026 por instrucción del usuario. No es la clasificación SIES/CINE-F (que se conserva en la columna C solo como referencia). Clasificación B-externo: dato observado en fuente institucional pública, verificado carrera por carrera con su URL.
B5: Carrera | C5: Sector IPSS | D5: Código Carrera (COD_CAR) | E5: Fuente (ipss.cl)
B6: Administracion Publica | C6: Administración y Comercio | D6: 83 | E6: https://ipss.cl/administracion-y-comercio/administracion-publica/
B7: Auditoria | C7: Administración y Comercio | D7: 86 | E7: https://ipss.cl/administracion-y-comercio/auditoria/
B8: Contabilidad General | C8: Administración y Comercio | D8: 85 | E8: https://ipss.cl/administracion-y-comercio/contabilidad-general/
B9: Ingenieria En Administracion De Empresas | C9: Administración y Comercio | D9: 76 | E9: https://ipss.cl/administracion-y-comercio/ingenieria-en-administracion-de-empresas/
B10: Ingenieria En Ciberseguridad | C10: Tecnologías | D10: 46 | E10: https://ipss.cl/tecnologias/ingenieria-en-ciberseguridad/
B11: Ingenieria En Ciencia De Datos | C11: Tecnologías | D11: 88 | E11: https://ipss.cl/tecnologias/ingenieria-en-ciencia-de-datos/
B12: Ingenieria En Conectividad Y Redes | C12: Tecnologías | D12: 3 | E12: https://ipss.cl/tecnologias/ingenieria-en-conectividad-y-redes/
B13: Ingenieria En Informatica | C13: Tecnologías | D13: 1 | E13: https://ipss.cl/tecnologias/ingenieria-en-informatica/
B14: Ingenieria En Logistica | C14: Administración y Comercio | D14: 77 | E14: https://ipss.cl/administracion-y-comercio/ingenieria-en-logistica/
B15: Tecnico En Administracion De Empresas | C15: Administración y Comercio | D15: 78 | E15: https://ipss.cl/administracion-y-comercio/tecnico-en-administracion-de-empresas/
B16: Tecnico En Administracion Publica | C16: Administración y Comercio | D16: 84 | E16: https://ipss.cl/administracion-y-comercio/tecnico-en-administracion-publica/
... B22: Tecnico En Programacion Y Analisis De Sistemas | C22: Tecnologías | D22: 57 | E22: https://ipss.cl/tecnologias/tecnico-en-programacion-y-analisis-de-sistemas/
B24: Código Carrera (columna D) verificado 2026-09-30 (dato B): para cada carrera, se tomaron las filas de BASE_RETENCION_MU con clave (Año, N° Documento, DV) única (2.305 de 2.379 casos) y se confirmó que el código COD_CAR observado es el mismo en el 100% de esas filas para cada nombre de carrera — mapeo 1 a 1, sin ambigüedad. Se usa para desambiguar los 74 casos en que un mismo estudiante tiene más de una matrícula el mismo año (distinta carrera): sin este código, 13 de esos 74 casos habrían tomado el primer registro que encuentra la fórmula en vez del que corresponde a la carrera de este análisis.

Sheet 9_Base_Analitica_Detalle
A1: 9_Base_Analitica_Detalle · agregado provisional
A2: 2026-10-22 · detalle individual excluido; original preservado
A3: C · Cantidad de registros de la fuente; no se interpreta como personas únicas
A4: Cohorte de ingreso | B4: Carrera | C4: Sector IPSS (fórmula) | D4: Retenido (1/0) | E4: Registros
A5: 2022 | B5: Ingenieria En Ciberseguridad | C5: Tecnologías | D5: 0 | E5: 6
A6: 2022 | B6: Ingenieria En Ciberseguridad | C6: Tecnologías | D6: 1 | E6: 38
A7: 2022 | B7: Ingenieria En Conectividad Y Redes | C7: Tecnologías | D7: 0 | E7: 14
A8: 2022 | B8: Ingenieria En Conectividad Y Redes | C8: Tecnologías | D8: 1 | E8: 56
A9: 2022 | B9: Ingenieria En Informatica | C9: Tecnologías | D9: 0 | E9: 14
A10: 2022 | B10: Ingenieria En Informatica | C10: Tecnologías | D10: 1 | E10: 30
A11: 2022 | B11: Tecnico En Ciberseguridad | C11: Tecnologías | D11: 0 | E11: 8
A12: 2022 | B12: Tecnico En Ciberseguridad | C12: Tecnologías | D12: 1 | E12: 24
A13: 2022 | B13: Tecnico En Conectividad Y Redes | C13: Tecnologías | D13: 0 | E13: 12
A14: 2022 | B14: Tecnico En Conectividad Y Redes | C14: Tecnologías | D14: 1 | E14: 21
A15: 2022 | B15: Tecnico En Programacion Y Analisis De Sistemas | C15: Tecnologías | D15: 0 | E15: 27
A16: 2022 | B16: Tecnico En Programacion Y Analisis De Sistemas | C16: Tecnologías | D16: 1 | E16: 55
... A82: 2025 | B82: Tecnico En Programacion Y Analisis De Sistemas | C82: Tecnologías | D82: 1 | E82: 80

Sheet 10_SIES_2025_Granular
A1: 🏠 Portada / Índice
A2: 10. SIES 2025 granular por carrera (hoja de soporte técnico)
B3: Tabla oficial enviada por Rodrigo Rolando Meneses (SIES/MINEDUC) a Karla Muñoz Gajardo, 09-09-2026, 36 códigos únicos. Clasificación A/B, gobernada en CARACTERIZACIÓN/gobernanza/sies/RETENCION/RETENCION_SIES_IPSS_162_GRANULAR_2025_CORREO_20260909.tsv. No existe tabla equivalente para 2022-2024 (por eso la comparación granular por sector solo puede hacerse para 2025).
B6: Código único | C6: Carrera | D6: Sector IPSS (fórmula) | E6: Estudiantes SIES 2025 | F6: Retenidos SIES 2025
B7: I162S2C1J1V1 | C7: Ingenieria En Informatica | D7: =IFERROR(VLOOKUP(C7,'8_Mapeo_Sector_IPSS'!$B$6:$C$22,2,FALSE()),"SIN MAPEO") -> Tecnologías | E7: 3 | F7: 3
B8: I162S2C1J1V2 | C8: Ingenieria En Informatica | D8: =IFERROR(VLOOKUP(C8,'8_Mapeo_Sector_IPSS'!$B$6:$C$22,2,FALSE()),"SIN MAPEO") -> Tecnologías | E8: 11 | F8: 7
B9: I162S2C1J2V1 | C9: Ingenieria En Informatica | D9: =IFERROR(VLOOKUP(C9,'8_Mapeo_Sector_IPSS'!$B$6:$C$22,2,FALSE()),"SIN MAPEO") -> Tecnologías | E9: 4 | F9: 2
B10: I162S2C1J2V4 | C10: Ingenieria En Informatica | D10: =IFERROR(VLOOKUP(C10,'8_Mapeo_Sector_IPSS'!$B$6:$C$22,2,FALSE()),"SIN MAPEO") -> Tecnologías | E10: 9 | F10: 5
B11: I162S2C1J4V2 | C11: Ingenieria En Informatica | D11: =IFERROR(VLOOKUP(C11,'8_Mapeo_Sector_IPSS'!$B$6:$C$22,2,FALSE()),"SIN MAPEO") -> Tecnologías | E11: 91 | F11: 64
B12: I162S2C3J2V1 | C12: Ingenieria En Conectividad Y Redes | D12: =IFERROR(VLOOKUP(C12,'8_Mapeo_Sector_IPSS'!$B$6:$C$22,2,FALSE()),"SIN MAPEO") -> Tecnologías | E12: 3 | F12: 1
B13: I162S2C3J2V4 | C13: Ingenieria En Conectividad Y Redes | D13: =IFERROR(VLOOKUP(C13,'8_Mapeo_Sector_IPSS'!$B$6:$C$22,2,FALSE()),"SIN MAPEO") -> Tecnologías | E13: 7 | F13: 5
B14: I162S2C3J4V2 | C14: Ingenieria En Conectividad Y Redes | D14: =IFERROR(VLOOKUP(C14,'8_Mapeo_Sector_IPSS'!$B$6:$C$22,2,FALSE()),"SIN MAPEO") -> Tecnologías | E14: 55 | F14: 38
B15: I162S2C46J1V1 | C15: Ingenieria En Ciberseguridad | D15: =IFERROR(VLOOKUP(C15,'8_Mapeo_Sector_IPSS'!$B$6:$C$22,2,FALSE()),"SIN MAPEO") -> Tecnologías | E15: 18 | F15: 16
B16: I162S2C46J2V1 | C16: Ingenieria En Ciberseguridad | D16: =IFERROR(VLOOKUP(C16,'8_Mapeo_Sector_IPSS'!$B$6:$C$22,2,FALSE()),"SIN MAPEO") -> Tecnologías | E16: 11 | F16: 8
B17: I162S2C46J4V3 | C17: Ingenieria En Ciberseguridad | D17: =IFERROR(VLOOKUP(C17,'8_Mapeo_Sector_IPSS'!$B$6:$C$22,2,FALSE()),"SIN MAPEO") -> Tecnologías | E17: 75 | F17: 42
B18: I162S2C47J1V1 | C18: Tecnico En Ciberseguridad | D18: =IFERROR(VLOOKUP(C18,'8_Mapeo_Sector_IPSS'!$B$6:$C$22,2,FALSE()),"SIN MAPEO") -> Tecnologías | E18: 8 | F18: 7
... B42: I162S2C91J2V1 | C42: Tecnico En Enfermeria | D42: =IFERROR(VLOOKUP(C42,'8_Mapeo_Sector_IPSS'!$B$6:$C$22,2,FALSE()),"SIN MAPEO") -> Salud | E42: 41 | F42: 16

Sheet 11_BASE_RETENCION_MU_RAW
A1: 11_BASE_RETENCION_MU_RAW · agregado provisional
A2: 2026-10-22 · detalle individual excluido; original preservado
A3: C · Cantidad de registros de la fuente; no se interpreta como personas únicas
A4: ANIO_INFORMADO | B4: COD_SED | C4: COD_CAR | D4: JOR | E4: VERSION | F4: VIG | G4: Registros
A5: 2022 | B5: 2 | C5: 1 | D5: 1 | E5: 2 | F5: 1 | G5: 19
A6: 2022 | B6: 2 | C6: 1 | D6: 2 | E6: 4 | F6: 1 | G6: 29
A7: 2022 | B7: 2 | C7: 1 | D7: 4 | E7: 1 | F7: 1 | G7: 1
A8: 2022 | B8: 2 | C8: 1 | D8: 4 | E8: 2 | F8: 1 | G8: 130
A9: 2022 | B9: 2 | C9: 11 | D9: 2 | E9: 1 | F9: 0 | G9: 1
A10: 2022 | B10: 2 | C10: 11 | D10: 2 | E10: 1 | F10: 1 | G10: 8
A11: 2022 | B11: 2 | C11: 2 | D11: 1 | E11: 2 | F11: 1 | G11: 3
A12: 2022 | B12: 2 | C12: 2 | D12: 4 | E12: 2 | F12: 1 | G12: 1
A13: 2022 | B13: 2 | C13: 22 | D13: 2 | E13: 1 | F13: 1 | G13: 16
A14: 2022 | B14: 2 | C14: 3 | D14: 2 | E14: 1 | F14: 0 | G14: 2
A15: 2022 | B15: 2 | C15: 3 | D15: 2 | E15: 4 | F15: 1 | G15: 48
A16: 2022 | B16: 2 | C16: 3 | D16: 4 | E16: 1 | F16: 1 | G16: 3
... A284: 2026 | B284: 3 | C284: 91 | D284: 2 | E284: 1 | F284: 1 | G284: 14

Sheet 12_Desglose_Jornada_Edad_Sexo
A1: 12. Desglose por jornada, edad y sexo (soporte técnico)
A3: 🏠 Portada / Índice | B3: C · Foto de valores históricos preservados; detalle individual excluido. No recalcula con filtros en esta copia agregada.
B4: Cohortes elegidas | C4: Sector | D4: Carrera | E4: Estudiantes | F4: Retenidos | G4: Tasa ponderada
B5: Acumulado 2022-2025 | C5: Todos | D5: Todas | E5: 2379 | F5: 1476 | G5: 0.62042875
B6: A. Retención por carrera y jornada (2022-2025 combinado)
B7: Sector | C7: Carrera | D7: Jornada | E7: Estudiantes | F7: Retenidos | G7: Tasa de retención
B8: Administración y Comercio | C8: Administracion Publica | D8: Presencial-Diurno | E8: 0 | F8: 0
B9: Administración y Comercio | C9: Administracion Publica | D9: Presencial-Vespertino | E9: 0 | F9: 0
B10: Administración y Comercio | C10: Administracion Publica | D10: Virtual | E10: 70 | F10: 33 | G10: 0.47142857
B11: Administración y Comercio | C11: Auditoria | D11: Presencial-Diurno | E11: 0 | F11: 0
B12: Administración y Comercio | C12: Auditoria | D12: Presencial-Vespertino | E12: 0 | F12: 0
B13: Administración y Comercio | C13: Auditoria | D13: Virtual | E13: 40 | F13: 27 | G13: 0.675
B14: Administración y Comercio | C14: Contabilidad General | D14: Presencial-Diurno | E14: 0 | F14: 0
B15: Administración y Comercio | C15: Contabilidad General | D15: Presencial-Vespertino | E15: 0 | F15: 0
B16: Administración y Comercio | C16: Contabilidad General | D16: Virtual | E16: 38 | F16: 19 | G16: 0.5
B17: Administración y Comercio | C17: Ingenieria En Administracion De Empresas | D17: Presencial-Diurno | E17: 0 | F17: 0
B18: Administración y Comercio | C18: Ingenieria En Administracion De Empresas | D18: Presencial-Vespertino | E18: 20 | F18: 7 | G18: 0.35
B19: Administración y Comercio | C19: Ingenieria En Administracion De Empresas | D19: Virtual | E19: 79 | F19: 42 | G19: 0.53164557
B20: Tecnologías | C20: Ingenieria En Ciberseguridad | D20: Presencial-Diurno | E20: 44 | F20: 35 | G20: 0.79545455
B21: Tecnologías | C21: Ingenieria En Ciberseguridad | D21: Presencial-Vespertino | E21: 48 | F21: 33 | G21: 0.6875
B22: Tecnologías | C22: Ingenieria En Ciberseguridad | D22: Virtual | E22: 211 | F22: 130 | G22: 0.61611374
B23: Tecnologías | C23: Ingenieria En Ciencia De Datos | D23: Presencial-Diurno | E23: 0 | F23: 0
B24: Tecnologías | C24: Ingenieria En Ciencia De Datos | D24: Presencial-Vespertino | E24: 0 | F24: 0
B25: Tecnologías | C25: Ingenieria En Ciencia De Datos | D25: Virtual | E25: 40 | F25: 21 | G25: 0.525
B26: Tecnologías | C26: Ingenieria En Conectividad Y Redes | D26: Presencial-Diurno | E26: 0 | F26: 0
B27: Tecnologías | C27: Ingenieria En Conectividad Y Redes | D27: Presencial-Vespertino | E27: 25 | F27: 19 | G27: 0.76
B28: Tecnologías | C28: Ingenieria En Conectividad Y Redes | D28: Virtual | E28: 212 | F28: 150 | G28: 0.70754717
B29: Tecnologías | C29: Ingenieria En Informatica | D29: Presencial-Diurno | E29: 34 | F29: 25 | G29: 0.73529412
B30: Tecnologías | C30: Ingenieria En Informatica | D30: Presencial-Vespertino | E30: 44 | F30: 26 | G30: 0.59090909
B31: Tecnologías | C31: Ingenieria En Informatica | D31: Virtual | E31: 256 | F31: 172 | G31: 0.671875
B32: Administración y Comercio | C32: Ingenieria En Logistica | D32: Presencial-Diurno | E32: 0 | F32: 0
B33: Administración y Comercio | C33: Ingenieria En Logistica | D33: Presencial-Vespertino | E33: 15 | F33: 7 | G33: 0.46666667
B34: Administración y Comercio | C34: Ingenieria En Logistica | D34: Virtual | E34: 61 | F34: 37 | G34: 0.60655738
B35: Administración y Comercio | C35: Tecnico En Administracion De Empresas | D35: Presencial-Diurno | E35: 0 | F35: 0
B36: Administración y Comercio | C36: Tecnico En Administracion De Empresas | D36: Presencial-Vespertino | E36: 16 | F36: 5 | G36: 0.3125
B37: Administración y Comercio | C37: Tecnico En Administracion De Empresas | D37: Virtual | E37: 72 | F37: 34 | G37: 0.47222222
B38: Administración y Comercio | C38: Tecnico En Administracion Publica | D38: Presencial-Diurno | E38: 0 | F38: 0
B39: Administración y Comercio | C39: Tecnico En Administracion Publica | D39: Presencial-Vespertino | E39: 0 | F39: 0
B40: Administración y Comercio | C40: Tecnico En Administracion Publica | D40: Virtual | E40: 22 | F40: 11 | G40: 0.5
B41: Tecnologías | C41: Tecnico En Ciberseguridad | D41: Presencial-Diurno | E41: 21 | F41: 16 | G41: 0.76190476
...

Sheet 13_Granular_Codigo_Unico
A1: 13. Retención granular por código único — interno vs SIES (soporte técnico)
A3: 🏠 Portada / Índice | B3: C · Foto de valores históricos preservados; detalle individual excluido. No recalcula con filtros en esta copia agregada.
B4: Cohortes elegidas | C4: Sector | D4: Carrera | H4: Estudiantes | I4: Retenidos | J4: Tasa ponderada
B5: Acumulado 2022-2025 | C5: Todos | D5: Todas | H5: 2379 | I5: 1476 | J5: 0.62042875
B6: A. Validación 2025 — retención interna vs dato real enviado por SIES (hoja 10)
B7: Código único | C7: Carrera | D7: Sector | E7: Jornada | F7: Modalidad | G7: Estudiantes | H7: Retenidos | I7: Estudiantes SIES 2025 (hoja 10) | J7: Retenidos SIES (hoja 10) | K7: Diferencia estudiantes (SIES − IPSS) | L7: Diferencia retenidos (SIES − interno)
B8: I162S2C1J1V1 | C8: Ingenieria En Informatica | D8: Tecnologías | E8: Diurno | F8: Presencial | G8: 3 | H8: 3 | I8: 3 | J8: 3 | K8: 0 | L8: 0
B9: I162S2C1J1V2 | C9: Ingenieria En Informatica | D9: Tecnologías | E9: Diurno | F9: Presencial | G9: 11 | H9: 7 | I9: 11 | J9: 7 | K9: 0 | L9: 0
B10: I162S2C1J2V1 | C10: Ingenieria En Informatica | D10: Tecnologías | E10: Vespertino | F10: Presencial | G10: 4 | H10: 2 | I10: 4 | J10: 2 | K10: 0 | L10: 0
B11: I162S2C1J2V4 | C11: Ingenieria En Informatica | D11: Tecnologías | E11: Vespertino | F11: Presencial | G11: 9 | H11: 5 | I11: 9 | J11: 5 | K11: 0 | L11: 0
B12: I162S2C1J4V2 | C12: Ingenieria En Informatica | D12: Tecnologías | E12: Virtual | F12: A distancia | G12: 91 | H12: 64 | I12: 91 | J12: 64 | K12: 0 | L12: 0
B13: I162S2C3J2V1 | C13: Ingenieria En Conectividad Y Redes | D13: Tecnologías | E13: Vespertino | F13: Presencial | G13: 3 | H13: 1 | I13: 3 | J13: 1 | K13: 0 | L13: 0
B14: I162S2C3J2V4 | C14: Ingenieria En Conectividad Y Redes | D14: Tecnologías | E14: Vespertino | F14: Presencial | G14: 6 | H14: 5 | I14: 7 | J14: 5 | K14: 1 | L14: 0
B15: I162S2C3J4V2 | C15: Ingenieria En Conectividad Y Redes | D15: Tecnologías | E15: Virtual | F15: A distancia | G15: 54 | H15: 37 | I15: 55 | J15: 38 | K15: 1 | L15: 1
B16: I162S2C46J1V1 | C16: Ingenieria En Ciberseguridad | D16: Tecnologías | E16: Diurno | F16: Presencial | G16: 18 | H16: 16 | I16: 18 | J16: 16 | K16: 0 | L16: 0
B17: I162S2C46J2V1 | C17: Ingenieria En Ciberseguridad | D17: Tecnologías | E17: Vespertino | F17: Presencial | G17: 11 | H17: 8 | I17: 11 | J17: 8 | K17: 0 | L17: 0
B18: I162S2C46J4V3 | C18: Ingenieria En Ciberseguridad | D18: Tecnologías | E18: Virtual | F18: A distancia | G18: 73 | H18: 41 | I18: 75 | J18: 42 | K18: 2 | L18: 1
B19: I162S2C47J1V1 | C19: Tecnico En Ciberseguridad | D19: Tecnologías | E19: Diurno | F19: Presencial | G19: 8 | H19: 7 | I19: 8 | J19: 7 | K19: 0 | L19: 0
... B43: I162S2C91J2V1 | C43: Tecnico En Enfermeria | D43: Salud | E43: Vespertino | F43: Presencial | G43: 41 | H43: 16 | I43: 41 | J43: 16 | K43: 0 | L43: 0
D45: TOTAL 2025 (suma de los 36 códigos) | G45: 1150 | H45: 668 | I45: 1163 | J45: 677 | K45: 13 | L45: 9
D46: Tasa de retención resultante | G46: 0.58086957 | I46: 0.58211522
B49: B. Retención interna por código único — todas las cohortes (2022-2025)
B50: Cohorte | C50: Código único | D50: Carrera | E50: Sector | F50: Jornada | G50: Modalidad | H50: Estudiantes | I50: Retenidos | J50: Tasa retención
B51: 2022 | C51: I162S2C46J1V1 | D51: Ingenieria En Ciberseguridad | E51: Tecnologías | F51: Diurno | G51: Presencial | H51: 5 | I51: 5 | J51: 1
B52: 2022 | C52: I162S2C46J2V1 | D52: Ingenieria En Ciberseguridad | E52: Tecnologías | F52: Vespertino | G52: Presencial | H52: 10 | I52: 9 | J52: 0.9
B53: 2022 | C53: I162S2C46J4V3 | D53: Ingenieria En Ciberseguridad | E53: Tecnologías | F53: Virtual | G53: A distancia | H53: 29 | I53: 24 | J53: 0.82758621
B54: 2022 | C54: I162S2C3J2V4 | D54: Ingenieria En Conectividad Y Redes | E54: Tecnologías | F54: Vespertino | G54: Presencial | H54: 10 | I54: 9 | J54: 0.9
B55: 2022 | C55: I162S2C3J4V2 | D55: Ingenieria En Conectividad Y Redes | E55: Tecnologías | F55: Virtual | G55: A distancia | H55: 60 | I55: 47 | J55: 0.78333333
B56: 2022 | C56: I162S2C1J1V2 | D56: Ingenieria En Informatica | E56: Tecnologías | F56: Diurno | G56: Presencial | H56: 5 | I56: 3 | J56: 0.6
B57: 2022 | C57: I162S2C1J2V4 | D57: Ingenieria En Informatica | E57: Tecnologías | F57: Vespertino | G57: Presencial | H57: 8 | I57: 4 | J57: 0.5
B58: 2022 | C58: I162S2C1J4V2 | D58: Ingenieria En Informatica | E58: Tecnologías | F58: Virtual | G58: A distancia | H58: 31 | I58: 23 | J58: 0.74193548
B59: 2022 | C59: I162S2C47J1V1 | D59: Tecnico En Ciberseguridad | E59: Tecnologías | F59: Diurno | G59: Presencial | H59: 8 | I59: 7 | J59: 0.875
B60: 2022 | C60: I162S2C47J2V1 | D60: Tecnico En Ciberseguridad | E60: Tecnologías | F60: Vespertino | G60: Presencial | H60: 8 | I60: 6 | J60: 0.75
B61: 2022 | C61: I162S2C47J4V1 | D61: Tecnico En Ciberseguridad | E61: Tecnologías | F61: Virtual | G61: A distancia | H61: 16 | I61: 11 | J61: 0.6875
B62: 2022 | C62: I162S2C6J1V1 | D62: Tecnico En Conectividad Y Redes | E62: Tecnologías | F62: Diurno | G62: Presencial | H62: 2 | I62: 2 | J62: 1
... B135: 2025 | C135: I162S2C57J4V1 | D135: Tecnico En Programacion Y Analisis De Sistemas | E135: Tecnologías | F135: Virtual | G135: A distancia | H135: 106 | I135: 66 | J135: 0.62264151
B136: TOTAL VISIBLE (filtro) | H136: 2379 | I136: 1476 | J136: 0.62042875
B137: Hallazgo (dato B, observado): de los 36 códigos de SIES 2025, 27 coinciden exactamente con el cálculo interno; en 9 códigos (7 de ellos en jornada Virtual) el interno cuenta 1-2 estudiantes menos, sumando 13 estudiantes y 9 retenidos de diferencia. La suma de los 36 códigos SIES (1.163/677/58,2115%) coincide con el "Total general" de Meneses y con la tasa oficial — esos 13 estudiantes explican por completo la brecha 2025. Ver README del hito, Adenda 3, y hoja 14 para las vistas ejecutivas derivadas de esta hoja.
B140: C. Comparación por carrera, cohorte 2025 — IPSS frente a SIES
C141: Carrera | D141: Estudiantes IPSS 2025 | E141: Retenidos IPSS 2025 | F141: Tasa IPSS 2025 | G141: Estudiantes SIES 2025 | H141: Retenidos SIES 2025 | I141: Tasa SIES 2025 | J141: Brecha (pp)
...

Sheet 14_Vistas_Ejecutivas
A1: 14. Vistas ejecutivas — de lo institucional a lo granular
BL2: Acumulado 2022-2025 | BM2: Todos | BN2: Todas
A3: 🏠 Portada / Índice | B3: Elija cohortes, sector y, si desea, carrera. La tasa de un mismo grupo debe coincidir entre niveles; cada modalidad o carrera puede tener una tasa diferente. Para reunir grupos, sume retenidos y estudiantes y divida los totales. «Promedio» en Excel solo promedia porcentajes y no considera cuántos estudiantes tiene cada grupo. Los gráficos muestran las cohortes elegidas. La referencia oficial de matrícula es el 30 de abril. | BL3: Cohorte 2022 | BM3: Tecnologías | BN3: Administracion Publica
B4: COHORTE(S) | C4: Acumulado 2022-2025 | G4: SECTOR | H4: Todos | R4: CARRERA | S4: Todas | BL4: Cohorte 2023 | BM4: Administración y Comercio | BN4: Auditoria
B5: Nivel 1 — Grupo seleccionado | G5: Nivel 2 — Por sector (cohorte elegida) | L5: Nivel 4 — Por Modalidad | R5: Nivel 5 — Por carrera (cohorte elegida) | X5: Nivel 6 — Por carrera y modalidad (cohorte elegida) | AD5: Nivel 7 — Por Jornada | AI5: Nivel 7 — Por Sexo | AN5: Nivel 7 — Por Tramo de edad | AS5: Vista — Mejores y menores tasas en la cohorte elegida | AY5: Datos auxiliares de gráficos — orden ascendente por tasa (se actualizan solos) | BL5: Cohorte 2024 | BM5: Salud | BN5: Contabilidad General
B6: Cohorte | C6: Estudiantes | D6: Retenidos | E6: Tasa de retención | G6: Sector | H6: Estudiantes | I6: Retenidos | J6: Tasa de retención | L6: Modalidad | M6: Cohorte | N6: Estudiantes | O6: Retenidos | P6: Tasa de retención | R6: Carrera | S6: Sector | T6: Estudiantes | U6: Retenidos | V6: Tasa de retención | X6: Carrera | Y6: Modalidad | Z6: Estudiantes | AA6: Retenidos | AB6: Tasa de retención | AD6: Jornada | AE6: Estudiantes | AF6: Retenidos | AG6: Tasa de retención | AI6: Sexo | AJ6: Estudiantes | AK6: Retenidos | AL6: Tasa de retención | AN6: Tramo Edad | AO6: Estudiantes | AP6: Retenidos | AQ6: Tasa de retención | AS6: Dimensión | AT6: Mejor | AU6: Tasa (mejor) | AV6: Peor | AW6: Tasa (peor) | AY6: Carrera — Modalidad | AZ6: Tasa de retención | BB6: Jornada | BC6: Tasa de retención | BE6: Sexo | BF6: Tasa de retención | BH6: Tramo Edad | BI6: Tasa de retención | BL6: Cohorte 2025 | BN6: Ingenieria En Administracion De Empresas
B7: Acumulado 2022-2025 | C7: 2379 | D7: 1476 | E7: 0.62042875 | G7: Tecnologías | H7: 1766 | I7: 1162 | J7: 0.65798414 | L7: Presencial | M7: 2022-25 | N7: 483 | O7: 291 | P7: 0.60248447 | R7: Ingenieria En Conectividad Y Redes | S7: Tecnologías | T7: 237 | U7: 169 | V7: 0.71308017 | X7: Administracion Publica | Y7: A distancia | Z7: 70 | AA7: 33 | AB7: 0.47142857 | AC7: Administracion Publica — A distancia | AD7: Presencial-Diurno | AE7: 177 | AF7: 126 | AG7: 0.71186441 | AI7: Hombre | AJ7: 1768 | AK7: 1094 | AL7: 0.61877828 | AN7: Menos de 20 | AO7: 91 | AP7: 61 | AQ7: 0.67032967 | AS7: Sector | AT7: Tecnologías | AU7: 0.65798414 | AV7: Salud | AW7: 0.46666667 | AY7: Tecnico En Administracion De Empresas — Presencial | AZ7: 0.3125 | BB7: Presencial-Vespertino | BC7: 0.53921569 | BE7: No binario | BF7: 0 | BH7: 40+ | BI7: 0.56231003 | BL7: Cohortes 2022 + 2023 | BN7: Ingenieria En Ciberseguridad | BR7: Ingenieria En Conectividad Y Redes | BS7: 237 | BT7: 169 | BU7: 1 | BV7: Administracion Publica | BW7: A distancia | BX7: 70 | BY7: 33 | BZ7: 1 | CA7: 0.62042875 | CB7: 0.65798414 | CE7: 0.71308017 | CF7: Presencial | CG7: Presencial-Diurno | CH7: Hombre | CI7: Menos de 20 | CJ7: 6 | CK7: 3 | CL7: 2 | CM7: 4 | CN7: 2022 | CO7: 0.73442623 | CP7: 1 | CQ7: Tecnologías | CR7: 0.65798414 | CS7: 1 | CT7: 2022 | CU7: 0.75903614 | CV7: 0.72522523 | CW7: 1
G8: Administración y Comercio | H8: 538 | I8: 279 | J8: 0.51858736 | L8: A distancia | M8: 2022-25 | N8: 1896 | O8: 1185 | P8: 0.625 | R8: Auditoria | S8: Administración y Comercio | T8: 40 | U8: 27 | V8: 0.675 | X8: Auditoria | Y8: A distancia | Z8: 40 | AA8: 27 | AB8: 0.675 | AC8: Auditoria — A distancia | AD8: Presencial-Vespertino | AE8: 306 | AF8: 165 | AG8: 0.53921569 | AI8: Mujer | AJ8: 610 | AK8: 382 | AL8: 0.62622951 | AN8: 20-24 | AO8: 382 | AP8: 269 | AQ8: 0.70418848 | AS8: Modalidad | AT8: Presencial | AU8: 0.60248447 | AV8: Presencial | AW8: 0.60248447 | AY8: Ingenieria En Administracion De Empresas — Presencial | AZ8: 0.35 | BB8: Virtual | BC8: 0.625 | BE8: Hombre | BF8: 0.61877828 | BH8: 30-39 | BI8: 0.59713701 | BL8: Cohortes 2022 + 2024 | BN8: Ingenieria En Ciencia De Datos | BR8: Auditoria | BS8: 40 | BT8: 27 | BU8: 2 | BV8: Auditoria | BW8: A distancia | BX8: 40 | BY8: 27 | BZ8: 2 | CB8: 0.51858736 | CC8: 0.625 | CE8: 0.675 | CF8: Presencial | CG8: Presencial-Vespertino | CH8: Mujer | CI8: 20-24 | CJ8: 22 | CK8: 1 | CL8: 3 | CM8: 5 | CN8: 2023 | CO8: 0.70491803 | CQ8: Administración y Comercio | CR8: 0.51858736 | CS8: 2 | CT8: 2023 | CU8: 0.58333333 | CV8: 0.71345029
G9: Salud | H9: 75 | I9: 35 | J9: 0.46666667 | R9: Tecnico En Programacion Y Analisis De Sistemas | S9: Tecnologías | T9: 466 | U9: 313 | V9: 0.67167382 | X9: Contabilidad General | Y9: A distancia | Z9: 38 | AA9: 19 | AB9: 0.5 | AC9: Contabilidad General — A distancia | AD9: Virtual | AE9: 1896 | AF9: 1185 | AG9: 0.625 | AI9: No binario | AJ9: 1 | AK9: 0 | AL9: 0 | AN9: 25-29 | AO9: 599 | AP9: 377 | AQ9: 0.6293823 | AS9: Carrera | AT9: Ingenieria En Conectividad Y Redes | AU9: 0.71308017 | AV9: Tecnico En Administracion De Empresas | AW9: 0.44318182 | AY9: Tecnico En Logistica — Presencial | AZ9: 0.36 | BB9: Presencial-Diurno | BC9: 0.71186441 | BE9: Mujer | BF9: 0.62622951 | BH9: 25-29 | BI9: 0.6293823 | BL9: Cohortes 2022 + 2025 | BN9: Ingenieria En Conectividad Y Redes | BR9: Tecnico En Programacion Y Analisis De Sistemas | BS9: 466 | BT9: 313 | BU9: 3 | BV9: Contabilidad General | BW9: A distancia | BX9: 38 | BY9: 19 | BZ9: 3 | CB9: 0.46666667 | CE9: 0.67167382 | CF9: Presencial | CG9: Virtual | CH9: No binario | CI9: 25-29 | CJ9: 8 | CK9: 2 | CL9: 1 | CM9: 3 | CN9: 2024 | CO9: 0.58422939 | CQ9: Salud | CR9: 0.46666667 | CS9: 3 | CT9: 2024 | CU9: 0.58088235 | CV9: 0.58530806
R10: Ingenieria En Informatica | S10: Tecnologías | T10: 334 | U10: 223 | V10: 0.66766467 | X10: Ingenieria En Administracion De Empresas | Y10: A distancia | Z10: 79 | AA10: 42 | AB10: 0.53164557 | AC10: Ingenieria En Administracion De Empresas — A distancia | AN10: 30-39 | AO10: 978 | AP10: 584 | AQ10: 0.59713701 | AS10: Carrera × Modalidad | AT10: Ingenieria En Conectividad Y Redes — Presencial | AU10: 0.76 | AV10: Tecnico En Administracion De Empresas — Presencial | AW10: 0.3125 | AY10: Ingenieria En Logistica — Presencial | AZ10: 0.46666667 | BH10: Menos de 20 | BI10: 0.67032967 | BL10: Cohortes 2023 + 2024 | BN10: Ingenieria En Informatica | BO10: 2022 | BR10: Ingenieria En Informatica | BS10: 334 | BT10: 223 | BU10: 4 | BV10: Ingenieria En Administracion De Empresas | BW10: A distancia | BX10: 79 | BY10: 42 | BZ10: 4 | CE10: 0.66766467 | CF10: Presencial | CI10: 30-39 | CJ10: 11 | CM10: 2 | CN10: 2025 | CO10: 0.58086957 | CT10: 2025 | CU10: 0.5625 | CV10: 0.58571429
R11: Ingenieria En Ciberseguridad | S11: Tecnologías | T11: 303 | U11: 198 | V11: 0.65346535 | X11: Ingenieria En Administracion De Empresas | Y11: Presencial | Z11: 20 | AA11: 7 | AB11: 0.35 | AC11: Ingenieria En Administracion De Empresas — Presencial | AN11: 40+ | AO11: 329 | AP11: 185 | AQ11: 0.56231003 | AS11: Jornada | AT11: Presencial-Diurno | AU11: 0.71186441 | AV11: Presencial-Vespertino | AW11: 0.53921569 | AY11: Tecnico En Enfermeria — Presencial | AZ11: 0.46666667 | BH11: 20-24 | BI11: 0.70418848 | BL11: Cohortes 2023 + 2025 | BN11: Ingenieria En Logistica | BO11: 2025 | BR11: Ingenieria En Ciberseguridad | BS11: 303 | BT11: 198 | BU11: 5 | BV11: Ingenieria En Administracion De Empresas | BW11: Presencial | BX11: 20 | BY11: 7 | BZ11: 5 | CE11: 0.65346535 | CF11: Presencial | CI11: 40+ | CJ11: 2 | CM11: 1
R12: Tecnico En Ciberseguridad | S12: Tecnologías | T12: 239 | U12: 155 | V12: 0.64853556 | X12: Ingenieria En Ciberseguridad | Y12: A distancia | Z12: 211 | AA12: 130 | AB12: 0.61611374 | AC12: Ingenieria En Ciberseguridad — A distancia | AS12: Sexo (H/M; NB se muestra aparte por tamaño muestral) | AT12: Mujer | AU12: 0.62622951 | AV12: Hombre | AW12: 0.61877828 | AY12: Administracion Publica — A distancia | AZ12: 0.47142857 | BL12: Cohortes 2024 + 2025 | BN12: Tecnico En Administracion De Empresas | BO12: * | BR12: Tecnico En Ciberseguridad | BS12: 239 | BT12: 155 | BU12: 6 | BV12: Ingenieria En Ciberseguridad | BW12: A distancia | BX12: 211 | BY12: 130 | BZ12: 6 | CE12: 0.64853556 | CF12: A distancia | CJ12: 16
R13: Ingenieria En Logistica | S13: Administración y Comercio | T13: 76 | U13: 44 | V13: 0.57894737 | X13: Ingenieria En Ciberseguridad | Y13: Presencial | Z13: 92 | AA13: 68 | AB13: 0.73913043 | AC13: Ingenieria En Ciberseguridad — Presencial | AS13: Tramo de Edad | AT13: 20-24 | AU13: 0.70418848 | AV13: 40+ | AW13: 0.56231003 | AY13: Tecnico En Administracion De Empresas — A distancia | AZ13: 0.47222222 | BL13: Cohortes 2022 + 2023 + 2024 | BN13: Tecnico En Administracion Publica | BO13: * | BR13: Ingenieria En Logistica | BS13: 76 | BT13: 44 | BU13: 7 | BV13: Ingenieria En Ciberseguridad | BW13: Presencial | BX13: 92 | BY13: 68 | BZ13: 7 | CE13: 0.57894737 | CF13: A distancia | CJ13: 26
R14: Tecnico En Ciencia De Datos | S14: Tecnologías | T14: 23 | U14: 13 | V14: 0.56521739 | X14: Ingenieria En Ciencia De Datos | Y14: A distancia | Z14: 40 | AA14: 21 | AB14: 0.525 | AC14: Ingenieria En Ciencia De Datos — A distancia | AY14: Contabilidad General — A distancia | AZ14: 0.5 | BL14: Cohortes 2022 + 2023 + 2025 | BN14: Tecnico En Ciberseguridad | BP14: 2022 | BQ14: 1 | BR14: Tecnico En Ciencia De Datos | BS14: 23 | BT14: 13 | BU14: 8 | BV14: Ingenieria En Ciencia De Datos | BW14: A distancia | BX14: 40 | BY14: 21 | BZ14: 8 | CE14: 0.56521739 | CF14: A distancia | CJ14: 10
R15: Tecnico En Conectividad Y Redes | S15: Tecnologías | T15: 124 | U15: 70 | V15: 0.56451613 | X15: Ingenieria En Conectividad Y Redes | Y15: A distancia | Z15: 212 | AA15: 150 | AB15: 0.70754717 | AC15: Ingenieria En Conectividad Y Redes — A distancia | AS15: Antes de comparar los extremos, mire cuántos estudiantes hay detrás de cada porcentaje. En grupos pequeños, unas pocas personas pueden cambiar mucho la tasa. | AY15: Tecnico En Administracion Publica — A distancia | AZ15: 0.5 | BL15: Cohortes 2022 + 2024 + 2025 | BN15: Tecnico En Ciencia De Datos | BP15: 2023 | BQ15: 1 | BR15: Tecnico En Conectividad Y Redes | BS15: 124 | BT15: 70 | BU15: 9 | BV15: Ingenieria En Conectividad Y Redes | BW15: A distancia | BX15: 212 | BY15: 150 | BZ15: 9 | CE15: 0.56451613 | CF15: A distancia | CJ15: 25
R16: Tecnico En Logistica | S16: Administración y Comercio | T16: 105 | U16: 57 | V16: 0.54285714 | X16: Ingenieria En Conectividad Y Redes | Y16: Presencial | Z16: 25 | AA16: 19 | AB16: 0.76 | AC16: Ingenieria En Conectividad Y Redes — Presencial | AY16: Ingenieria En Ciencia De Datos — A distancia | AZ16: 0.525 | BL16: Cohortes 2023 + 2024 + 2025 | BN16: Tecnico En Conectividad Y Redes | BP16: 2024 | BQ16: 1 | BR16: Tecnico En Logistica | BS16: 105 | BT16: 57 | BU16: 10 | BV16: Ingenieria En Conectividad Y Redes | BW16: Presencial | BX16: 25 | BY16: 19 | BZ16: 10 | CE16: 0.54285714 | CF16: A distancia | CJ16: 27
R17: Ingenieria En Ciencia De Datos | S17: Tecnologías | T17: 40 | U17: 21 | V17: 0.525 | X17: Ingenieria En Informatica | Y17: A distancia | Z17: 256 | AA17: 172 | AB17: 0.671875 | AC17: Ingenieria En Informatica — A distancia | AY17: Ingenieria En Administracion De Empresas — A distancia | AZ17: 0.53164557 | BN17: Tecnico En Enfermeria | BP17: 2025 | BQ17: 1 | BR17: Ingenieria En Ciencia De Datos | BS17: 40 | BT17: 21 | BU17: 11 | BV17: Ingenieria En Informatica | BW17: A distancia | BX17: 256 | BY17: 172 | BZ17: 11 | CE17: 0.525 | CJ17: 21
R18: Tecnico En Administracion Publica | S18: Administración y Comercio | T18: 22 | U18: 11 | V18: 0.5 | X18: Ingenieria En Informatica | Y18: Presencial | Z18: 78 | AA18: 51 | AB18: 0.65384615 | AC18: Ingenieria En Informatica — Presencial | AY18: Tecnico En Conectividad Y Redes — A distancia | AZ18: 0.55454545 | BN18: Tecnico En Logistica | BR18: Tecnico En Administracion Publica | BS18: 22 | BT18: 11 | BU18: 12 | BV18: Ingenieria En Informatica | BW18: Presencial | BX18: 78 | BY18: 51 | BZ18: 12 | CE18: 0.5 | CJ18: 20
R19: Contabilidad General | S19: Administración y Comercio | T19: 38 | U19: 19 | V19: 0.5 | X19: Ingenieria En Logistica | Y19: A distancia | Z19: 61 | AA19: 37 | AB19: 0.60655738 | AC19: Ingenieria En Logistica — A distancia | AY19: Tecnico En Ciencia De Datos — A distancia | AZ19: 0.56521739 | BN19: Tecnico En Programacion Y Analisis De Sistemas | BR19: Contabilidad General | BS19: 38 | BT19: 19 | BU19: 13 | BV19: Ingenieria En Logistica | BW19: A distancia | BX19: 61 | BY19: 37 | BZ19: 13 | CE19: 0.5 | CJ19: 15
R20: Ingenieria En Administracion De Empresas | S20: Administración y Comercio | T20: 99 | U20: 49 | V20: 0.49494949 | X20: Ingenieria En Logistica | Y20: Presencial | Z20: 15 | AA20: 7 | AB20: 0.46666667 | AC20: Ingenieria En Logistica — Presencial | AS20: Claves para leer la cohorte elegida | AY20: Tecnico En Logistica — A distancia | AZ20: 0.6 | BN20: Todas | BR20: Ingenieria En Administracion De Empresas | BS20: 99 | BT20: 49 | BU20: 14 | BV20: Ingenieria En Logistica | BW20: Presencial | BX20: 15 | BY20: 7 | BZ20: 14 | CE20: 0.49494949 | CJ20: 4
R21: Administracion Publica | S21: Administración y Comercio | T21: 70 | U21: 33 | V21: 0.47142857 | X21: Tecnico En Administracion De Empresas | Y21: A distancia | Z21: 72 | AA21: 34 | AB21: 0.47222222 | AC21: Tecnico En Administracion De Empresas — A distancia | AS21: Cambie la cohorte o combinación, el sector o la carrera. Todas las tablas de esta vista usan la misma selección. Para comparar tasas entre hojas, sume primero estudiantes y retenidos del mismo grupo y divida; el promedio que muestra la barra de Excel al seleccionar porcentajes no es la tasa total. | AY21: Ingenieria En Logistica — A distancia | AZ21: 0.60655738 | BN21: Ingenieria En Ciberseguridad | BR21: Administracion Publica | BS21: 70 | BT21: 33 | BU21: 15 | BV21: Tecnico En Administracion De Empresas | BW21: A distancia | BX21: 72 | BY21: 34 | BZ21: 15 | CE21: 0.47142857 | CJ21: 7
R22: Tecnico En Enfermeria | S22: Salud | T22: 75 | U22: 35 | V22: 0.46666667 | X22: Tecnico En Administracion De Empresas | Y22: Presencial | Z22: 16 | AA22: 5 | AB22: 0.3125 | AC22: Tecnico En Administracion De Empresas — Presencial | AY22: Ingenieria En Ciberseguridad — A distancia | AZ22: 0.61611374 | BN22: Ingenieria En Ciencia De Datos | BR22: Tecnico En Enfermeria | BS22: 75 | BT22: 35 | BU22: 16 | BV22: Tecnico En Administracion De Empresas | BW22: Presencial | BX22: 16 | BY22: 5 | BZ22: 16 | CE22: 0.46666667 | CJ22: 1
R23: Tecnico En Administracion De Empresas | S23: Administración y Comercio | T23: 88 | U23: 39 | V23: 0.44318182 | X23: Tecnico En Administracion Publica | Y23: A distancia | Z23: 22 | AA23: 11 | AB23: 0.5 | AC23: Tecnico En Administracion Publica — A distancia | AS23: • Grupo seleccionado: la tasa es retenidos divididos por estudiantes. Sin filtros de sector ni carrera, representa a la institución; el acumulado no es un promedio de porcentajes. | AY23: Tecnico En Programacion Y Analisis De Sistemas — Presencial | AZ23: 0.63157895 | BN23: Ingenieria En Conectividad Y Redes | BR23: Tecnico En Administracion De Empresas | BS23: 88 | BT23: 39 | BU23: 17 | BV23: Tecnico En Administracion Publica | BW23: A distancia | BX23: 22 | BY23: 11 | BZ23: 17 | CE23: 0.44318182 | CJ23: 9
X24: Tecnico En Ciberseguridad | Y24: A distancia | Z24: 192 | AA24: 122 | AB24: 0.63541667 | AC24: Tecnico En Ciberseguridad — A distancia | AY24: Tecnico En Ciberseguridad — A distancia | AZ24: 0.63541667 | BN24: Ingenieria En Informatica | BV24: Tecnico En Ciberseguridad | BW24: A distancia | BX24: 192 | BY24: 122 | BZ24: 18 | CJ24: 18
X25: Tecnico En Ciberseguridad | Y25: Presencial | Z25: 47 | AA25: 33 | AB25: 0.70212766 | AC25: Tecnico En Ciberseguridad — Presencial | AY25: Tecnico En Conectividad Y Redes — Presencial | AZ25: 0.64285714 | BN25: Tecnico En Ciberseguridad | BV25: Tecnico En Ciberseguridad | BW25: Presencial | BX25: 47 | BY25: 33 | BZ25: 19 | CJ25: 24
X26: Tecnico En Ciencia De Datos | Y26: A distancia | Z26: 23 | AA26: 13 | AB26: 0.56521739 | AC26: Tecnico En Ciencia De Datos — A distancia | AS26: • Sector: compare la continuidad junto con el número de estudiantes. Si un sector no tiene estudiantes en este cohorte, su tasa queda sin calcular. | AY26: Ingenieria En Informatica — Presencial | AZ26: 0.65384615 | BN26: Tecnico En Ciencia De Datos | BV26: Tecnico En Ciencia De Datos | BW26: A distancia | BX26: 23 | BY26: 13 | BZ26: 20 | CJ26: 13
X27: Tecnico En Conectividad Y Redes | Y27: A distancia | Z27: 110 | AA27: 61 | AB27: 0.55454545 | AC27: Tecnico En Conectividad Y Redes — A distancia | AY27: Ingenieria En Informatica — A distancia | AZ27: 0.671875 | BN27: Tecnico En Conectividad Y Redes | BV27: Tecnico En Conectividad Y Redes | BW27: A distancia | BX27: 110 | BY27: 61 | BZ27: 21 | CJ27: 12
X28: Tecnico En Conectividad Y Redes | Y28: Presencial | Z28: 14 | AA28: 9 | AB28: 0.64285714 | AC28: Tecnico En Conectividad Y Redes — Presencial | AY28: Auditoria — A distancia | AZ28: 0.675 | BN28: Tecnico En Programacion Y Analisis De Sistemas | BV28: Tecnico En Conectividad Y Redes | BW28: Presencial | BX28: 14 | BY28: 9 | BZ28: 22 | CJ28: 19
X29: Tecnico En Enfermeria | Y29: Presencial | Z29: 75 | AA29: 35 | AB29: 0.46666667 | AC29: Tecnico En Enfermeria — Presencial | AS29: • Sede: esta base analítica contiene estudiantes de Casa Central. Aquí no es posible comparar sedes. | AY29: Tecnico En Programacion Y Analisis De Sistemas — A distancia | AZ29: 0.67948718 | BN29: Todas | BV29: Tecnico En Enfermeria | BW29: Presencial | BX29: 75 | BY29: 35 | BZ29: 23 | CJ29: 5
X30: Tecnico En Logistica | Y30: A distancia | Z30: 80 | AA30: 48 | AB30: 0.6 | AC30: Tecnico En Logistica — A distancia | AY30: Tecnico En Ciberseguridad — Presencial | AZ30: 0.70212766 | BN30: Administracion Publica | BV30: Tecnico En Logistica | BW30: A distancia | BX30: 80 | BY30: 48 | BZ30: 24 | CJ30: 14
G31: Lectura por sector: compare las tasas junto con sus denominadores. Un sector con pocos estudiantes puede variar mucho de una cohorte a otro. | X31: Tecnico En Logistica | Y31: Presencial | Z31: 25 | AA31: 9 | AB31: 0.36 | AC31: Tecnico En Logistica — Presencial | AD31: Lectura por jornada: una diferencia en porcentaje merece revisar el tamaño de cada jornada y la carrera que la compone. | AI31: Lectura por sexo: compare grupos del mismo cohorte y trate con cautela los que tienen muy pocos estudiantes. | AY31: Ingenieria En Conectividad Y Redes — A distancia | AZ31: 0.70754717 | BN31: Auditoria | BV31: Tecnico En Logistica | BW31: Presencial | BX31: 25 | BY31: 9 | BZ31: 25 | CJ31: 3
X32: Tecnico En Programacion Y Analisis De Sistemas | Y32: A distancia | Z32: 390 | AA32: 265 | AB32: 0.67948718 | AC32: Tecnico En Programacion Y Analisis De Sistemas — A distancia | AS32: • Modalidad: presencial y a distancia pueden tener tamaños diferentes. Lea el porcentaje junto con el total de estudiantes. | AY32: Ingenieria En Ciberseguridad — Presencial | AZ32: 0.73913043 | BN32: Contabilidad General | BV32: Tecnico En Programacion Y Analisis De Sistemas | BW32: A distancia | BX32: 390 | BY32: 265 | BZ32: 26 | CJ32: 23
X33: Tecnico En Programacion Y Analisis De Sistemas | Y33: Presencial | Z33: 76 | AA33: 48 | AB33: 0.63157895 | AC33: Tecnico En Programacion Y Analisis De Sistemas — Presencial | AY33: Ingenieria En Conectividad Y Redes — Presencial | AZ33: 0.76 | BN33: Ingenieria En Administracion De Empresas | BV33: Tecnico En Programacion Y Analisis De Sistemas | BW33: Presencial | BX33: 76 | BY33: 48 | BZ33: 27 | CJ33: 17
B34: Ejemplo fijo: Tecnologías, acumulado 2022–2025. Presencial: 228/332 = 68,7%. A distancia: 934/1.434 = 65,1%. Excel «Promedio»: 66,9%. Tasa de todo el sector: (228+934)/(332+1.434) = 65,8%. Cada estudiante cuenta una vez. | AN34: Lectura por edad: la cohorte elegida permite observar cómo cambia la continuidad entre tramos, sin suponer que la edad sea la causa. | BN34: Ingenieria En Logistica
AS35: • Carrera: elija primero un sector y después una carrera. Si cambia de sector, seleccione de nuevo la carrera para evitar comparar grupos distintos. | BN35: Tecnico En Administracion De Empresas
BN36: Tecnico En Administracion Publica
BN37: Tecnico En Logistica
AS38: • Carrera y modalidad: esta vista permite mirar ambas dimensiones juntas. Una diferencia de tasa, por sí sola, no demuestra su causa. | BN38: Todas
BN39: Tecnico En Enfermeria
L40: Lectura por modalidad: la comparación es más útil dentro de una misma carrera y un mismo cohorte; los tamaños de grupo pueden ser distintos. | BP40: 2022 | BQ40: 1 | BR40: 305 | BS40: 224 | BT40: 83 | BU40: 63 | BV40: 222 | BW40: 161 | BX40: 1
...

Sheet 15_Tablas_Ejecutivas
A1: 🏠 Portada / Índice | B1: C · Foto de valores históricos preservados; detalle individual excluido. No recalcula con filtros en esta copia agregada.
B2: Los bloques derivados de la hoja 14 responden a su selección de cohortes, sector y carrera. Las tablas históricas de apoyo conservan todas las cohortes indicadas en sus títulos. Para comparar grupos, use retenidos ÷ estudiantes; el promedio simple de porcentajes que muestra Excel no pondera por tamaño de cohorte.
B5: 4A. Retención interna por sector y cohorte | H5: 4B. Comparación 2025 — interna vs. SIES granular, por sector | Q5: 5. Evolución institucional 2022-2025 (interna vs. SIES publicada) | X5: 12A. Retención por carrera y jornada (2022-2025 combinado) | AE5: 12B. Retención por jornada y cohorte | AL5: 12C. Retención por sexo y cohorte | AR5: 12D. Retención por tramo de edad y cohorte | AX5: 14·N1. Institucional (por cohorte) | BC5: 14·N2. Por sector (cohorte elegida) | BH5: 14·N4. Por Modalidad | BN5: 14·N5. Por carrera (cohorte elegida) | BT5: 14·N6. Por Carrera × Modalidad | BZ5: 14·N7. Por Jornada | CE5: 14·N7. Por Sexo | CJ5: 14·N7. Por Tramo de edad | CO5: 14·Vista. Mejores y menores tasas (cohorte elegida)
B6: Sector | C6: Cohorte | D6: Estudiantes | E6: Retenidos | F6: Tasa de retención | H6: Sector | I6: Estudiantes IPSS 2025 | J6: Retenidos internos 2025 | K6: Tasa interna 2025 | L6: Estudiantes SIES 2025 | M6: Retenidos SIES 2025 | N6: Tasa SIES 2025 | O6: Brecha (pp) | Q6: Cohorte | R6: Estudiantes IPSS | S6: Retenidos internos | T6: Tasa interna | U6: Tasa SIES publicada | V6: Brecha (pp) | X6: Sector | Y6: Carrera | Z6: Jornada | AA6: Estudiantes | AB6: Retenidos | AC6: Tasa de retención | AE6: Cohorte | AF6: Jornada | AG6: Estudiantes | AH6: % de la cohorte | AI6: Retenidos | AJ6: Tasa de retención | AL6: Cohorte | AM6: Sexo | AN6: Estudiantes | AO6: Retenidos | AP6: Tasa de retención | AR6: Cohorte | AS6: Tramo Edad | AT6: Estudiantes | AU6: Retenidos | AV6: Tasa de retención | AX6: Cohorte | AY6: Estudiantes | AZ6: Retenidos | BA6: Tasa de retención | BC6: Sector | BD6: Estudiantes | BE6: Retenidos | BF6: Tasa de retención | BH6: Modalidad | BI6: Cohorte | BJ6: Estudiantes | BK6: Retenidos | BL6: Tasa de retención | BN6: Carrera | BO6: Sector | BP6: Estudiantes | BQ6: Retenidos | BR6: Tasa de retención | BT6: Carrera | BU6: Modalidad | BV6: Estudiantes | BW6: Retenidos | BX6: Tasa de retención | BZ6: Jornada | CA6: Estudiantes | CB6: Retenidos | CC6: Tasa de retención | CE6: Sexo | CF6: Estudiantes | CG6: Retenidos | CH6: Tasa de retención | CJ6: Tramo Edad | CK6: Estudiantes | CL6: Retenidos | CM6: Tasa de retención | CO6: Dimensión | CP6: Mejor | CQ6: Tasa (mejor) | CR6: Peor | CS6: Tasa (peor)
