Workbook
Name CarrerasRevisionIntermedia: 'Fuentes_y_alcance'!$H$7:$H$25

Sheet Resumen
A2: Retención intermedia: revisión de cohortes 2024 y 2025
A4: C: seleccione una carrera en H4 para revisar los cuatro cierres. | H4: Todas
A5: E: cobertura al cierre no acreditada. Se muestran presencias comprobadas; las tasas intermedias siguen pendientes.
A7: Cohorte | B7: Cierre observado | C7: Estudiantes de referencia anual | D7: Localizados en el listado | E7: Con estado VIGENTE | F7: Sin llave comparable | G7: Sin localizar con llave | H7: Tasa intermedia | I7: Qué falta (E)
A8: 2024 | B8: 2025-T2 | C8: =IF($H$4="Todas",SUMIFS('Por_carrera'!$D$7:$D$34,'Por_carrera'!$A$7:$A$34,A8),SUMIFS('Por_carrera'!$D$7:$D$34,'Por_carrera'!$A$7:$A$34,A8,'Por_carrera'!$B$7:$B$34,$H$4)) -> 558 | D8: =IF($H$4="Todas",SUMIFS('Por_carrera'!$F$7:$F$34,'Por_carrera'!$A$7:$A$34,A8),SUMIFS('Por_carrera'!$F$7:$F$34,'Por_carrera'!$A$7:$A$34,A8,'Por_carrera'!$B$7:$B$34,$H$4)) -> 1 | E8: =IF($H$4="Todas",SUMIFS('Por_carrera'!$G$7:$G$34,'Por_carrera'!$A$7:$A$34,A8),SUMIFS('Por_carrera'!$G$7:$G$34,'Por_carrera'!$A$7:$A$34,A8,'Por_carrera'!$B$7:$B$34,$H$4)) -> 1 | F8: =IF($H$4="Todas",SUMIFS('Por_carrera'!$E$7:$E$34,'Por_carrera'!$A$7:$A$34,A8),SUMIFS('Por_carrera'!$E$7:$E$34,'Por_carrera'!$A$7:$A$34,A8,'Por_carrera'!$B$7:$B$34,$H$4)) -> 0 | G8: =C8-D8-F8 -> 557 | H8: Pendiente | I8: E: falta una base completa de 2025-T2 que incluya la cohorte 2024. La entrega solo contiene ingresos 2025-T2.
A9: 2024 | B9: 2025-T3 | C9: =IF($H$4="Todas",SUMIFS('Por_carrera'!$D$7:$D$34,'Por_carrera'!$A$7:$A$34,A9),SUMIFS('Por_carrera'!$D$7:$D$34,'Por_carrera'!$A$7:$A$34,A9,'Por_carrera'!$B$7:$B$34,$H$4)) -> 558 | D9: =IF($H$4="Todas",SUMIFS('Por_carrera'!$H$7:$H$34,'Por_carrera'!$A$7:$A$34,A9),SUMIFS('Por_carrera'!$H$7:$H$34,'Por_carrera'!$A$7:$A$34,A9,'Por_carrera'!$B$7:$B$34,$H$4)) -> 325 | E9: =IF($H$4="Todas",SUMIFS('Por_carrera'!$I$7:$I$34,'Por_carrera'!$A$7:$A$34,A9),SUMIFS('Por_carrera'!$I$7:$I$34,'Por_carrera'!$A$7:$A$34,A9,'Por_carrera'!$B$7:$B$34,$H$4)) -> 317 | F9: =IF($H$4="Todas",SUMIFS('Por_carrera'!$E$7:$E$34,'Por_carrera'!$A$7:$A$34,A9),SUMIFS('Por_carrera'!$E$7:$E$34,'Por_carrera'!$A$7:$A$34,A9,'Por_carrera'!$B$7:$B$34,$H$4)) -> 0 | G9: =C9-D9-F9 -> 233 | H9: Pendiente | I9: E: T3_2025 incluye varias cohortes. Falta acreditar completitud y fecha efectiva del estado. No se exige otro archivo si este se confirma.
A10: 2025 | B10: 2026-T2 | C10: =IF($H$4="Todas",SUMIFS('Por_carrera'!$D$7:$D$34,'Por_carrera'!$A$7:$A$34,A10),SUMIFS('Por_carrera'!$D$7:$D$34,'Por_carrera'!$A$7:$A$34,A10,'Por_carrera'!$B$7:$B$34,$H$4)) -> 1150 | D10: =IF($H$4="Todas",SUMIFS('Por_carrera'!$F$7:$F$34,'Por_carrera'!$A$7:$A$34,A10),SUMIFS('Por_carrera'!$F$7:$F$34,'Por_carrera'!$A$7:$A$34,A10,'Por_carrera'!$B$7:$B$34,$H$4)) -> 2 | E10: ="Sin estado" -> Sin estado | F10: =IF($H$4="Todas",SUMIFS('Por_carrera'!$E$7:$E$34,'Por_carrera'!$A$7:$A$34,A10),SUMIFS('Por_carrera'!$E$7:$E$34,'Por_carrera'!$A$7:$A$34,A10,'Por_carrera'!$B$7:$B$34,$H$4)) -> 20 | G10: =C10-D10-F10 -> 1128 | H10: Pendiente | I10: E: DatosAlumnos_10246 está congelado para Caracterización P2. Falta acreditar que representa todo el cierre 2026-T2 y sus estados.
A11: 2025 | B11: 2026-T3 | C11: =IF($H$4="Todas",SUMIFS('Por_carrera'!$D$7:$D$34,'Por_carrera'!$A$7:$A$34,A11),SUMIFS('Por_carrera'!$D$7:$D$34,'Por_carrera'!$A$7:$A$34,A11,'Por_carrera'!$B$7:$B$34,$H$4)) -> 1150 | D11: =IF($H$4="Todas",SUMIFS('Por_carrera'!$H$7:$H$34,'Por_carrera'!$A$7:$A$34,A11),SUMIFS('Por_carrera'!$H$7:$H$34,'Por_carrera'!$A$7:$A$34,A11,'Por_carrera'!$B$7:$B$34,$H$4)) -> 0 | E11: =IF($H$4="Todas",SUMIFS('Por_carrera'!$I$7:$I$34,'Por_carrera'!$A$7:$A$34,A11),SUMIFS('Por_carrera'!$I$7:$I$34,'Por_carrera'!$A$7:$A$34,A11,'Por_carrera'!$B$7:$B$34,$H$4)) -> 0 | F11: =IF($H$4="Todas",SUMIFS('Por_carrera'!$E$7:$E$34,'Por_carrera'!$A$7:$A$34,A11),SUMIFS('Por_carrera'!$E$7:$E$34,'Por_carrera'!$A$7:$A$34,A11,'Por_carrera'!$B$7:$B$34,$H$4)) -> 20 | G11: =C11-D11-F11 -> 1130 | H11: Pendiente | I11: E: DatosAlumnos_11998 es una fuente común de P1/P2/P3. Falta acreditar fecha y cobertura del cierre 2026-T3.
A13: D/C: se conservan 558 y 1.150 estudiantes de referencia. No se cambian elegibilidad ni denominadores.
A14: B/E: presencia y estado describen el archivo recibido; no certifican vigencia al cierre sin evidencia temporal.
A15: E: sin localizar no equivale a desertor. T2-2026 carece de estado académico; no se rellena como 0 ni como 1.
A17: Seguimiento distinto ya solicitado: ingresos 2025 T2/T3 buscados en MU2026
A18: D/C: conserva 222 y 124 estudiantes, incluidos ELIMINADO. Esta sección no cambia con el selector de carrera.
A20: Ingreso | B20: Estudiantes (D) | C20: Localizados (C) | D20: Con VIG 1 (C) | E20: Solo VIG 0 (C) | F20: Ausentes (C) | G20: Continuidad (C) | H20: Clase | I20: Observación
A21: 2025-T2 | B21: ='Fuentes_y_alcance'!B30 -> 222 | C21: ='Fuentes_y_alcance'!C30 -> 80 | D21: ='Fuentes_y_alcance'!D30 -> 74 | E21: ='Fuentes_y_alcance'!E30 -> 6 | F21: ='Fuentes_y_alcance'!F30 -> 142 | G21: =IF(B21=0,"Sin denominador",D21/B21) -> 0.33333333 | H21: C / D / E | I21: Continuidad institucional, no tasa SIES oficial. No explica las ausencias.
A22: 2025-T3 | B22: ='Fuentes_y_alcance'!B31 -> 124 | C22: ='Fuentes_y_alcance'!C31 -> 50 | D22: ='Fuentes_y_alcance'!D31 -> 48 | E22: ='Fuentes_y_alcance'!E31 -> 2 | F22: ='Fuentes_y_alcance'!F31 -> 74 | G22: =IF(B22=0,"Sin denominador",D22/B22) -> 0.38709677 | H22: C / D / E | I22: Continuidad institucional, no tasa SIES oficial. No explica las ausencias.
A24: D: las decisiones VIG para MU2027 no se aplican retroactivamente a estas bases ni a estos denominadores.
A25: B/E: el estudio 2026 documentó cambios por nómina; su fundamento académico individual sigue pendiente.
A27: Próximo paso: revisar Bases_por_confirmar. Usar fuentes existentes si se acredita fecha, cobertura y estados del cierre.
A29: C: MU2024 identifica la cohorte 2024; MU2025 permite observar su continuidad y definir la cohorte 2025.
A30: C: MU2026 permite observar continuidad de la cohorte 2025. Ninguna MU anual sustituye por sí sola un cierre T2/T3.
A31: E: que la MU siguiente incluya todos los ingresos T1/T2/T3 previos es una hipótesis a comprobar, no una cobertura demostrada.

Sheet Por_carrera
A2: Detalle por carrera de origen y cohorte
A4: B/C: se conservan los conteos del cruce verificado. E: tasas pendientes hasta acreditar fecha y cobertura de los cierres.
A6: Cohorte | B6: Carrera de origen | C6: Candidatos MU | D6: Referencia anual | E6: Sin llave comparable | F6: Localizados T2 | G6: VIGENTE T2 | H6: Localizados T3 | I6: VIGENTE T3 | J6: Tasa T2 (E) | K6: Tasa T3 (E)
A7: 2024 | B7: INGENIERIA EN ADMINISTRACION DE EMPRESAS | C7: 16 | D7: 8 | E7: 0 | F7: 0 | G7: 0 | H7: 3 | I7: 3 | J7: Pendiente | K7: Pendiente
A8: 2024 | B8: INGENIERIA EN CIBERSEGURIDAD | C8: 99 | D8: 89 | E8: 0 | F8: 0 | G8: 0 | H8: 49 | I8: 48 | J8: Pendiente | K8: Pendiente
A9: 2024 | B9: INGENIERIA EN CONECTIVIDAD Y REDES | C9: 76 | D9: 68 | E9: 0 | F9: 0 | G9: 0 | H9: 46 | I9: 45 | J9: Pendiente | K9: Pendiente
A10: 2024 | B10: INGENIERIA EN INFORMATICA | C10: 114 | D10: 107 | E10: 0 | F10: 0 | G10: 0 | H10: 72 | I10: 68 | J10: Pendiente | K10: Pendiente
A11: 2024 | B11: INGENIERIA EN LOGISTICA | C11: 18 | D11: 15 | E11: 0 | F11: 0 | G11: 0 | H11: 7 | I11: 6 | J11: Pendiente | K11: Pendiente
A12: 2024 | B12: TECNICO EN ADMINISTRACION DE EMPRESAS | C12: 24 | D12: 15 | E12: 0 | F12: 0 | G12: 0 | H12: 7 | I12: 7 | J12: Pendiente | K12: Pendiente
A13: 2024 | B13: TECNICO EN AUTOMATIZACION Y CONTROL INDUSTRIAL | C13: 1 | D13: 0 | E13: 0 | F13: 0 | G13: 0 | H13: 0 | I13: 0 | J13: Pendiente | K13: Pendiente
A14: 2024 | B14: TECNICO EN CIBERSEGURIDAD | C14: 79 | D14: 71 | E14: 0 | F14: 0 | G14: 0 | H14: 37 | I14: 36 | J14: Pendiente | K14: Pendiente
A15: 2024 | B15: TECNICO EN CONECTIVIDAD Y REDES | C15: 30 | D15: 25 | E15: 0 | F15: 0 | G15: 0 | H15: 6 | I15: 6 | J15: Pendiente | K15: Pendiente
A16: 2024 | B16: TECNICO EN LOGISTICA | C16: 32 | D16: 23 | E16: 0 | F16: 0 | G16: 0 | H16: 10 | I16: 10 | J16: Pendiente | K16: Pendiente
A17: 2024 | B17: TECNICO EN PROGRAMACION Y ANALISIS DE SISTEMAS | C17: 147 | D17: 137 | E17: 0 | F17: 1 | G17: 1 | H17: 88 | I17: 88 | J17: Pendiente | K17: Pendiente
A18: 2025 | B18: ADMINISTRACION PUBLICA | C18: 70 | D18: 70 | E18: 0 | F18: 0 | G18: n.d. | H18: 0 | I18: 0 | J18: Pendiente | K18: Pendiente
A19: 2025 | B19: AUDITORIA | C19: 41 | D19: 40 | E19: 0 | F19: 0 | G19: n.d. | H19: 0 | I19: 0 | J19: Pendiente | K19: Pendiente
A20: 2025 | B20: CONTABILIDAD GENERAL | C20: 38 | D20: 38 | E20: 0 | F20: 1 | G20: n.d. | H20: 0 | I20: 0 | J20: Pendiente | K20: Pendiente
A21: 2025 | B21: INGENIERIA EN ADMINISTRACION DE EMPRESAS | C21: 100 | D21: 91 | E21: 1 | F21: 0 | G21: n.d. | H21: 0 | I21: 0 | J21: Pendiente | K21: Pendiente
A22: 2025 | B22: INGENIERIA EN CIBERSEGURIDAD | C22: 122 | D22: 102 | E22: 0 | F22: 0 | G22: n.d. | H22: 0 | I22: 0 | J22: Pendiente | K22: Pendiente
A23: 2025 | B23: INGENIERIA EN CIENCIA DE DATOS | C23: 42 | D23: 40 | E23: 0 | F23: 0 | G23: n.d. | H23: 0 | I23: 0 | J23: Pendiente | K23: Pendiente
A24: 2025 | B24: INGENIERIA EN CONECTIVIDAD Y REDES | C24: 67 | D24: 63 | E24: 0 | F24: 0 | G24: n.d. | H24: 0 | I24: 0 | J24: Pendiente | K24: Pendiente
A25: 2025 | B25: INGENIERIA EN INFORMATICA | C25: 131 | D25: 118 | E25: 4 | F25: 0 | G25: n.d. | H25: 0 | I25: 0 | J25: Pendiente | K25: Pendiente
A26: 2025 | B26: INGENIERIA EN LOGISTICA | C26: 66 | D26: 61 | E26: 0 | F26: 0 | G26: n.d. | H26: 0 | I26: 0 | J26: Pendiente | K26: Pendiente
A27: 2025 | B27: TECNICO EN ADMINISTRACION DE EMPRESAS | C27: 76 | D27: 73 | E27: 2 | F27: 0 | G27: n.d. | H27: 0 | I27: 0 | J27: Pendiente | K27: Pendiente
A28: 2025 | B28: TECNICO EN ADMINISTRACION PUBLICA | C28: 22 | D28: 22 | E28: 0 | F28: 0 | G28: n.d. | H28: 0 | I28: 0 | J28: Pendiente | K28: Pendiente
A29: 2025 | B29: TECNICO EN CIBERSEGURIDAD | C29: 85 | D29: 80 | E29: 0 | F29: 0 | G29: n.d. | H29: 0 | I29: 0 | J29: Pendiente | K29: Pendiente
... A34: 2025 | B34: TECNICO EN PROGRAMACION Y ANALISIS DE SISTEMAS | C34: 163 | D34: 130 | E34: 3 | F34: 1 | G34: n.d. | H34: 0 | I34: 0 | J34: Pendiente | K34: Pendiente
A37: C: procedencia única: libro de revisión 20-10-2026, Por_carrera!A7:I34. Ruta y SHA-256 en Fuentes_y_alcance.
A38: E: los 20 documentos sin llave comparable de la cohorte 2025 no se cuentan como ausencia.
A39: E: cobertura no acreditada no significa pérdida de datos demostrada. Los ceros indican ausencia en el archivo consultado.

Sheet Fuentes_y_alcance
A2: Fuentes y alcance de los resultados
A6: Clase | B6: Fuente / hoja | C6: Uso | D6: SHA-256 | E6: Ruta | F6: Estado de fuente | H6: Carreras disponibles
A7: B | B7: Matrícula T2_2025 2.xlsx / T2_2025 | C7: Cierre parcial recibido | D7: ed5de007202df0780bb3396ad88307f4096d7c8b729005486a20d1123096d5b3 | E7: /Users/alexi/Downloads/cierre/Matrícula T2_2025 2.xlsx | F7: Íntegra por SHA-256 | H7: Todas
A8: B | B8: Matrícula T3_2025 2.xlsx / T3_2025 | C8: Cierre parcial recibido | D8: 68a1cd54ee48c1e6a679c1dbb3999e12d491543e9425e81f3d0508fefdc8d6cc | E8: /Users/alexi/Downloads/cierre/Matrícula T3_2025 2.xlsx | F8: Íntegra por SHA-256 | H8: INGENIERIA EN ADMINISTRACION DE EMPRESAS
A9: B | B9: Matrícula T_2_13_07_2026.xlsx / Hoja1 | C9: Cierre parcial recibido | D9: 7926a9cabcc67ed19abb50459132fd74ebb323bff9f5cb53e9116378c21a6769 | E9: /Users/alexi/Downloads/cierre/Matrícula T_2_13_07_2026.xlsx | F9: Íntegra por SHA-256 | H9: INGENIERIA EN CIBERSEGURIDAD
A10: B | B10: Matrícula_T3_02_10_2026.xlsx / Base | C10: Cierre parcial recibido | D10: de4e73ee7d27779cdc531c6816f745d412e1021cbd61e4fceb8ab0459cbda4ae | E10: /Users/alexi/Downloads/cierre/Matrícula_T3_02_10_2026.xlsx | F10: Íntegra por SHA-256 | H10: INGENIERIA EN CONECTIVIDAD Y REDES
A11: B | B11: BASE_RETENCION_MATRICULA_UNIFICADA_INFORMADA_SIES_2022_2026_20260901_142342.xlsx / BASE_RETENCION_MU | C11: MU informada; origen | D11: 19cf33ae4925a7c13ec4745394141a297f4f64be4052a240cb0d2c42ffeb53bd | E11: /Users/alexi/Documents/GitHub/avance_curricular/outputs/base_retencion_matricula_unificada_2022_2026/20260901_142342/BASE_RETENCION_MATRICULA_UNIFICADA_INFORMADA_SIES_2022_2026_20260901_142342.xlsx | F11: Íntegra por SHA-256 | H11: INGENIERIA EN INFORMATICA
A12: C | B12: RETENCION_PRIMER_ANIO_IPSS_162_DIAGNOSTICO_BRECHAS_20260930.xlsx / 02_COHORTE_ELEGIBILIDAD | C12: Motor anual de referencia | D12: 5f0f7c7f0f238556de374d287bf2931ccc8a93a5489f4c2f2b543befd38c77b3 | E12: /Users/alexi/Documents/GitHub/avance_curricular/outputs/retencion_primer_anio_ipss_162/20260930_000000/RETENCION_PRIMER_ANIO_IPSS_162_DIAGNOSTICO_BRECHAS_20260930.xlsx | F12: Íntegra por SHA-256 | H12: INGENIERIA EN LOGISTICA
A13: A | B13: REGLA_RETENCION_1ER_ANIO_CORREO_20260909.txt / Texto | C13: Regla anual; no define T2/T3 | D13: 92716565c2ace72a1b3ea1a73fb257cab70b247e0c3eb49d7845ef72b14945a8 | E13: /Users/alexi/Documents/GitHub/CARACTERIZACIÓN/gobernanza/sies/RETENCION/REGLA_RETENCION_1ER_ANIO_CORREO_20260909.txt | F13: Íntegra por SHA-256 | H13: TECNICO EN ADMINISTRACION DE EMPRESAS
A14: C | B14: Revisión previa / Por_carrera!A7:I34 | C14: Conteos usados en este resumen | D14: 699ca7b18aa3b5892ef7ef5b0dfbeb766d2632f0e4319a7c83995aa818092f12 | E14: /Users/alexi/Documents/GitHub/avance_curricular/outputs/retencion_intermedia_t2_t3/20261020_215248/REVISION_RETENCION_INTERMEDIA_IPSS_2024_2025_T2_T3_20261020.xlsx | F14: Cachés y controles verificados | H14: TECNICO EN AUTOMATIZACION Y CONTROL INDUSTRIAL
A15: C | B15: Continuidad previa / manifiesto resultados_C | C15: Insumos del seguimiento separado | D15: 202072b117e61c53d4895d72f1dee7f92c2557a013ea3262d055de4bc28379a5 | E15: /Users/alexi/Documents/GitHub/avance_curricular/outputs/retencion_intermedia_t2_t3/20261020_221157/CONTINUIDAD_IPSS_INGRESOS_2025_T2_T3_EN_MU2026_20261020_221157.xlsx | F15: 222 / 124 conservados | H15: TECNICO EN CIBERSEGURIDAD
H16: TECNICO EN CONECTIVIDAD Y REDES
H17: TECNICO EN LOGISTICA
A18: A: regla SIES anual. B: dato observado. C: cálculo o implementación. D: decisión interna. E: pendiente. | H18: TECNICO EN PROGRAMACION Y ANALISIS DE SISTEMAS
H19: ADMINISTRACION PUBLICA
A20: D/B: el usuario describió las entregas como parciales. Se revisaron respaldos existentes antes de solicitar más bases. | H20: AUDITORIA
A21: C: la carrera corresponde al origen de la cohorte, aunque la presencia posterior ocurra en otro programa. | H21: CONTABILIDAD GENERAL
A22: E: verificar período de ingreso UMAS frente a semestre de origen SIES. No asumir equivalencia T1/T2/T3 = semestre 1/2. | H22: INGENIERIA EN CIENCIA DE DATOS
A23: D: revisión MU2027 por versión 20261021_v1. No cambia esta revisión ni constituye norma SIES. | H23: TECNICO EN ADMINISTRACION PUBLICA
A24: C: este resumen contiene solo agregados. El cruce detallado anterior se conserva localmente y no se replica aquí. | H24: TECNICO EN CIENCIA DE DATOS
A25: C: actualización de alcance y fuentes. Conteos originales y fórmulas de seguimiento conservados. | H25: TECNICO EN ENFERMERIA
A27: Insumos de la continuidad ya calculada (fuente: MANIFEST_CONTINUIDAD.json, resultados_C)
A29: Ingreso (D) | B29: Estudiantes (D) | C29: Localizados (C) | D29: VIG 1 (C) | E29: Solo VIG 0 (C) | F29: Ausentes (C)
A30: 2025-T2 | B30: 222 | C30: 80 | D30: 74 | E30: 6 | F30: 142
A31: 2025-T3 | B31: 124 | C31: 50 | D31: 48 | E31: 2 | F31: 74
A34: Clase | B34: Fuente / hoja | C34: Uso | D34: SHA-256 | E34: Ruta | F34: Estado de fuente
A35: B | B35: DatosAlumnos_10246 / Hoja1 | C35: 14.204 registros; respaldo P2 | D35: b175d63bd9e3280c5757fb0d7292e45fb594d8f076e277f2e06bad2b15e9d869 | E35: /Users/alexi/Documents/GitHub/CARACTERIZACIÓN/.local/fuentes_congeladas/2026/P2/2026_P2_20260721_161905/DATOSDEALUMNOS_10246.xlsx | F35: Congelado 22-07-2026; no acredita cierre
A36: B | B36: Fuentes congeladas 2026-P2 | C36: Corrida 21-07; congelamiento 22-07 | D36: bda8a15c0f0689bf013f94882a20cdb6fac25107888641af69c9210bc663f588 | E36: /Users/alexi/Documents/GitHub/CARACTERIZACIÓN/docs/gobernanza/FUENTES_CONGELADAS_2026_P2.json | F36: Metadatos de gobernanza
A37: B | B37: DatosAlumnos_11998 / Hoja1 | C37: 15.045 registros; mismo archivo P1/P2/P3 | D37: 5d2df5e7998a4ec903e12d51b25114e8f1ff36da57cecaf623e90398b0828f35 | E37: /Users/alexi/Documents/GitHub/CARACTERIZACIÓN/.local/analisis_anual/2026/20261016_002933_892820/entrega/03_RESPALDOS/P3/01_ENTRADAS/DATOSDEALUMNOS_11998.xlsx | F37: Usado 15-10-2026; extracción no acreditada
A38: B | B38: Inventario histórico SIES/UMAS | C38: Documenta ausencia de fecha de extracción | D38: 8c0b9f02c013f94b98dc72be1eae9912dadd991ba0e5a3fa7a64da3ef3904ae2 | E38: /Users/alexi/Documents/GitHub/avance_curricular/data/versiones_historicas_sies_umas/fase_1_20261015/inventario.json | F38: No convertir años observados en cierres
A39: B | B39: Manifest ejecución P3 | C39: Fecha de ejecución y fuente utilizada | D39: c0f23e85071dd0c319d1bd1bff05f22a49d898a7ba6d67bc4882595113690c8a | E39: /Users/alexi/Documents/GitHub/CARACTERIZACIÓN/.local/analisis_anual/2026/20261016_002933_892820/entrega/03_RESPALDOS/P3/04_AUDITORIA/manifest_ejecucion.json | F39: 15-10-2026; no certifica estado histórico
A40: B | B40: Manifest BASE_RETENCION_MU | C40: Fuentes anuales 2024, 2025 y 2026 disponibles | D40: 746539ed62a3a3a051da14fd7f32b90fc6fd30a426304386d54e19c203d74145 | E40: /Users/alexi/Documents/GitHub/avance_curricular/outputs/base_retencion_matricula_unificada_2022_2026/20260901_142342/MANIFEST_BASE_RETENCION_MU_2022_2026.json | F40: No falta la base anual 2024
A41: C | B41: Libro de revisión previo | C41: Presencias conservadas y procedencia | D41: 1fed8a17c0b6977c579b14a86c012b7160170648b46e638f9009f33b0c0c85a0 | E41: /Users/alexi/Documents/GitHub/avance_curricular/outputs/retencion_intermedia_t2_t3/20261021_013430/REVISION_RETENCION_INTERMEDIA_IPSS_2024_2025_20261021.xlsx | F41: No se recalcula el cruce individual

Sheet Bases_por_confirmar
A2: Bases de cierre: disponible y pendiente
A4: B: fuentes revisadas. E: falta acreditar cobertura o fecha; esto no demuestra que falten estudiantes.
A6: Cierre | B6: Cohorte | C6: Base disponible (B) | D6: Fecha acreditada (B) | E6: Qué confirmar (E) | F6: Qué falta resolver
A7: 2025-T2 | B7: 2024 | C7: Archivo recibido: 225 registros, todos ingresos 2025-T2. | D7: No acredita fecha efectiva del cierre. | E7: Matrícula de todas las cohortes y estados al cierre, incluida cohorte 2024. | F7: Falta base completa acreditada.
A8: 2025-T3 | B8: 2024 | C8: T3_2025: 3.081 registros de varias cohortes; 500 con ingreso 2024. | D8: Propiedades: creado 13-10-2025; modificado 20-10-2026. No son prueba del corte. | E8: Completitud de la hoja y fecha efectiva de sus estados académicos. | F8: Puede bastar confirmar el archivo existente.
A9: 2026-T2 | B9: 2025 | C9: DatosAlumnos_10246: 14.204 registros. Fuente congelada de Caracterización P2. | D9: Corrida 21-07-2026; congelado 22-07-2026. Sin fecha de extracción acreditada. | E9: Si incluye toda la matrícula del cierre y si el estado corresponde a ese cierre. | F9: Candidato localizado; cobertura temporal pendiente.
A10: 2026-T3 | B10: 2025 | C10: DatosAlumnos_11998: 15.045 registros. Mismo archivo usado en P1, P2 y P3. | D10: Ejecución 15-10-2026; fecha de extracción no acreditada. | E10: Cobertura completa al cierre T3, incluidos ingresos de períodos 1 y 2. | F10: Candidato localizado; no son tres cierres históricos.
A12: C: no reemplazar la cohorte 2024 por quienes aparecen en MU2025; eso cambiaría el denominador.
A13: B: la base consolidada ya contiene matrícula informada de 2024, 2025 y 2026.
A14: E: MU2027 es una comprobación futura. No dar por confirmada su cobertura de ingresos 2026.
A15: C: las bases candidatas no se han usado para sumar presencias nuevas ni para sustituir cierres.
A16: D: denominadores conservados: 558 / 1.150 y, en el ejercicio separado, 222 / 124.
A18: Referencias, rutas y hashes: Fuentes_y_alcance, filas 35 a 41.

Sheet Escenario_80
A2: Escenario de los 80 ingresos reclasificados
A3: Institucional completo, cohortes 2024 y 2025. C/D: no responde al selector de carrera de Resumen. Resultados actuales conservados. Fecha: 21-10-2026.
A4: E: hipótesis aislada: cambiar solo ANIO_ING_ACT y ANIO_ING_ORI de 2025 a 2024 en las 80 filas MU2025. Se conservan los semestres informados, VIG, programas, MU2024 y MU2026. No es una corrección aprobada.
A6: Comparación anual: cálculo actual (C) y simulación separada (C/E)
A7: Cohorte | B7: Estudiantes actuales (C) | C7: Retenidos actuales (C) | D7: Tasa actual (C) | E7: Estudiantes simulados (C/E) | F7: Retenidos simulados (C/E) | G7: Tasa simulada (C/E) | H7: Cambio (pp, C/E)
A8: 2024 | B8: =SUMIFS('Por_carrera'!$D$7:$D$34,'Por_carrera'!$A$7:$A$34,A8) -> 558 | C8: =E40 -> 326 | D8: =IF(B8=0,"Pendiente",C8/B8) -> 0.58422939 | E8: =B8+E38 -> 560 | F8: =C8+E39 -> 328 | G8: =IF(E8=0,"Pendiente",F8/E8) -> 0.58571429 | H8: =(G8-D8)*100 -> 0.1484895
A9: 2025 | B9: =SUMIFS('Por_carrera'!$D$7:$D$34,'Por_carrera'!$A$7:$A$34,A9) -> 1150 | C9: =E41 -> 668 | D9: =IF(B9=0,"Pendiente",C9/B9) -> 0.58086957 | E9: =B9-E33 -> 1123 | F9: =C9-E34 -> 668 | G9: =IF(E9=0,"Pendiente",F9/E9) -> 0.59483526 | H9: =(G9-D9)*100 -> 1.3965697
A11: D/E: 560 y 1.123 son universos hipotéticos de esta hoja. No sustituyen los denominadores actuales 558 y 1.150, ni los denominadores separados de ingresos T2=222 y T3=124.
A12: Comparación con SIES: brecha = tasa propia menos tasa publicada
A13: Cohorte | B13: Tasa SIES observada (B) | C13: Brecha actual (pp, C) | D13: Brecha simulada (pp, C/E) | E13: Lectura
A14: 2024 | B14: 0.675 | C14: =(D8-B14)*100 -> -9.0770609 | D14: =(G8-B14)*100 -> -8.9285714 | E14: C/E: mejora solo una parte pequeña de la brecha. La causa restante sigue pendiente.
A15: 2025 | B15: 0.58211522 | C15: =(D9-B15)*100 -> -0.1245654 | D15: =(G9-B15)*100 -> 1.2720043 | E15: C/E: la simulación queda por encima de SIES. Acercarse al dato no valida la hipótesis.
A17: Control: seguimiento de la misma población actual, sin cambiar denominadores
A18: Cohorte | B18: Estudiantes actuales (C) | C18: Retenidos actuales (C) | D18: Tasa actual (C) | E18: Tasa misma población (C/E) | F18: Cambio (pp, C/E) | G18: Estado (D)
A19: 2024 | B19: =B8 -> 558 | C19: =C8 -> 326 | D19: =D8 -> 0.58422939 | E19: =C19/B19 -> 0.58422939 | F19: =(E19-D19)*100 -> 0 | G19: Sin cambio de población
A20: 2025 | B20: =B9 -> 1150 | C20: =C9 -> 668 | D20: =D9 -> 0.58086957 | E20: =C20/B20 -> 0.58086957 | F20: =(E20-D20)*100 -> 0 | G20: Sin cambio de población
A22: C/E: el escenario evalúa retención anual MU2024→MU2025 y MU2025→MU2026. Las tasas de los cierres T2/T3 siguen pendientes de acreditar fecha, cobertura y estados. Los 53 VIG=1 no se añaden automáticamente al numerador.
A24: Cómo se construye: entradas agregadas del cruce ya verificado
A26: Marca 2+3 INGRESO | E26: 50 | F26: B · respaldo de preparación MU2025
A27: Marca CORRECCIÓN | E27: 30 | F27: B · respaldo de preparación MU2025
A28: Población del escenario | E28: =SUM(E26:E27) -> 80 | F28: C · suma de las dos marcas
A29: Con al menos una fila VIG=1 en MU2026 | E29: 53 | F29: B · cruce exacto de persona
A30: En MU2026 solo con VIG=0 | E30: 11 | F30: B · sin fila VIG=1
A31: Sin fila en MU2026 | E31: 16 | F31: B · ausencia en esta extracción
A32: Total clasificado en MU2026 | E32: =SUM(E29:E31) -> 80 | F32: C · suma de las tres situaciones
A33: De los 80, incluidos actualmente en cohorte 2025 | E33: 27 | F33: C · no se descuentan los 80
A34: Retenidos actuales aportados por esos incluidos | E34: 0 | F34: C · cálculo actual
A35: Ya excluidos por COHORTE_INCONSISTENTE en 2025 | E35: 53 | F35: C · proxy de exclusión D/E
A36: Con fila MU2024; pasarían a incluidos y retenidos | E36: 2 | F36: B: 2 filas · C/E: efecto simulado
A37: Sin fila en MU2024 | E37: 78 | F37: B · no se crean filas faltantes
A38: Estudiantes que se sumarían a cohorte 2024 | E38: =E36 -> 2 | F38: C/E · solo las dos filas existentes
A39: Retenidos que se sumarían a cohorte 2024 | E39: =E36 -> 2 | F39: C/E · transición simulada ya evaluada
A40: Retenidos actuales de la cohorte 2024 | E40: 326 | F40: C · motor anual conservado
A41: Retenidos actuales de la cohorte 2025 | E41: 668 | F41: C · motor anual conservado
A43: Los 80 estudiantes por programa de MU2025 (B: observaciones agregadas)
A44: Código único | B44: Carrera | E44: Estudiantes (B) | F44: VIG 1 MU2026 (B) | G44: Solo VIG 0 (B) | H44: Ausentes MU2026 (B)
A45: I162S2C1J4V2 | B45: INGENIERIA EN INFORMATICA | E45: 9 | F45: 4 | G45: 2 | H45: 3
A46: I162S2C3J4V2 | B46: INGENIERIA EN CONECTIVIDAD Y REDES | E46: 5 | F46: 2 | G46: 2 | H46: 1
A47: I162S2C46J4V3 | B47: INGENIERIA EN CIBERSEGURIDAD | E47: 22 | F47: 13 | G47: 3 | H47: 6
A48: I162S2C47J4V1 | B48: TECNICO EN CIBERSEGURIDAD | E48: 5 | F48: 2 | G48: 1 | H48: 2
...
